Workbook

Sheet Sheet1
A1: Citation (APA 7th-Annotated) | B1: sequence | C1: DOI if different from article or doi Alt | D1: Item number | E1: end | F1: Publication name | G1: 1st Author | H1: other author(s) | I1: year | J1: DOI (or Alt) | K1: Item name | L1: Item encoded | M1: Public TSV match from AUTO_Public_TSV_FileList (generated by _tools/__file_list.R; do not edit manually) | N1: Item full original title | O1: Note about item | P1: Progress stage | Q1: Online Database | R1: Snapshot | S1: Adjustment made | T1: Data readable file, can use this | U1: Source Type | V1: Source format | W1: Source URL direct access | X1: Source URL link | Y1: Team | Z1: Collection | AA1: Possible Traits | AB1: Note | AC1: Flags pre-addressed | AD1: Flags possible | AE1: Flags active (skips) | AF1: Sample type | AG1: Method | AH1: Subcategory | AI1: Main Trait(s) | AJ1: Taxon group | AK1: Source type | AL1: Data role (primary/secondary/both) | AM1: Measure type
A2: Andelin, A. K., Olavarria, J. F., Fine, I., Taber, E. N., Schwartz, D., Kroenke, C. D., & Stevens, A. A. (2019). The Effect of Onset Age of Visual Deprivation on Visual Cortex Surface Area Across-Species. Cereb Cortex, 29(10), 4321-4333. https://doi.org/10.1093/cercor/bhy315 | D2: Table 4 | E2: =RIGHT(A2,1) -> 5 | F2: =G2 & IF(H2<>"", "_" & H2, "_") & IF(I2<>"", "_" & I2, "_") & IF(B2<>"", "_" & B2, "") -> Andelin_etal_2019 | G2: =SUBSTITUTE(SUBSTITUTE(_xlfn.TEXTBEFORE(A2,","), "-", ""), " ", "") -> Andelin | H2: =_xlfn.LET( _xlpm.authors,_xlfn.TEXTBEFORE(A2," ("&I2&")"), _xlpm.hasAmp,ISNUMBER(SEARCH("&",_xlpm.authors)), _xlpm.commasBeforeAmp,IF(_xlpm.hasAmp,LEN(_xlfn.TEXTBEFORE(_xlpm.authors,"&"))-LEN(SUBSTITUTE(_xlfn.TEXTBEFORE(_xlpm.authors,"&"),",","")),0), IF(NOT(_xlpm.hasAmp),"",IF(_xlpm.commasBeforeAmp>2,"etal",TRIM(_xlfn.TEXTBEFORE(_xlfn.TEXTAFTER(_xlpm.authors,"& "),",")))) ) -> etal | I2: =_xlfn.TEXTBEFORE(_xlfn.TEXTAFTER(A2, "("), ")") -> 2019 | J2: =_xlfn.LET( _xlpm.doi,IF(C2<>"",C2,_xlfn.TEXTAFTER(A2,"https://doi.org/")), SUBSTITUTE( SUBSTITUTE( SUBSTITUTE( SUBSTITUTE( _xlpm.doi, "/","%2F"), ":","%3A"), "<","%3C"), ">","%3E") ) -> 10.1093%2Fcercor%2Fbhy315 | K2: =TRIM(_xlfn.TEXTJOIN("_",FALSE(),F2,(SUBSTITUTE(SUBSTITUTE(D2," ",""), "_", "")))) -> Andelin_etal_2019_Table4 | L2: =J2 & "_" & SUBSTITUTE(SUBSTITUTE(SUBSTITUTE(D2,CHAR(160),"")," ",""),"_","") -> 10.1093%2Fcercor%2Fbhy315_Table4 | M2: {=IFERROR(INDEX(AUTO_Public_TSV_FileList!$A$1:$A$1000,MATCH(TRUE(),EXACT(L2,IFERROR(_xlfn.TEXTBEFORE(AUTO_Public_TSV_FileList!$A$1:$A$1000,".tsv"),"")),0)),"notfound")} -> 10.1093%2Fcercor%2Fbhy315_Table4.tsv | P2: FINISHED | V2: table | AJ2: review | AL2: review | AM2: review
A3: Ashwell, K. W. S. (2020). Quantitative analysis of cerebellar morphology in monotreme, metatherian and eutherian mammals. Zoology (Jena), 139, 125753. https://doi.org/10.1016/j.zool.2020.125753 | D3: Supplementary Table | E3: =RIGHT(A3,1) -> 3 | F3: =G3 & IF(H3<>"", "_" & H3, "_") & IF(I3<>"", "_" & I3, "_") & IF(B3<>"", "_" & B3, "") -> Ashwell__2020 | G3: =SUBSTITUTE(SUBSTITUTE(_xlfn.TEXTBEFORE(A3,","), "-", ""), " ", "") -> Ashwell | H3: =_xlfn.LET( _xlpm.authors,_xlfn.TEXTBEFORE(A3," ("&I3&")"), _xlpm.hasAmp,ISNUMBER(SEARCH("&",_xlpm.authors)), _xlpm.commasBeforeAmp,IF(_xlpm.hasAmp,LEN(_xlfn.TEXTBEFORE(_xlpm.authors,"&"))-LEN(SUBSTITUTE(_xlfn.TEXTBEFORE(_xlpm.authors,"&"),",","")),0), IF(NOT(_xlpm.hasAmp),"",IF(_xlpm.commasBeforeAmp>2,"etal",TRIM(_xlfn.TEXTBEFORE(_xlfn.TEXTAFTER(_xlpm.authors,"& "),",")))) ) | I3: =_xlfn.TEXTBEFORE(_xlfn.TEXTAFTER(A3, "("), ")") -> 2020 | J3: =_xlfn.LET( _xlpm.doi,IF(C3<>"",C3,_xlfn.TEXTAFTER(A3,"https://doi.org/")), SUBSTITUTE( SUBSTITUTE( SUBSTITUTE( SUBSTITUTE( _xlpm.doi, "/","%2F"), ":","%3A"), "<","%3C"), ">","%3E") ) -> 10.1016%2Fj.zool.2020.125753 | K3: =TRIM(_xlfn.TEXTJOIN("_",FALSE(),F3,(SUBSTITUTE(SUBSTITUTE(D3," ",""), "_", "")))) -> Ashwell__2020_SupplementaryTable | L3: =J3 & "_" & SUBSTITUTE(SUBSTITUTE(SUBSTITUTE(D3,CHAR(160),"")," ",""),"_","") -> 10.1016%2Fj.zool.2020.125753_SupplementaryTable | M3: {=IFERROR(INDEX(AUTO_Public_TSV_FileList!$A$1:$A$1000,MATCH(TRUE(),EXACT(L3,IFERROR(_xlfn.TEXTBEFORE(AUTO_Public_TSV_FileList!$A$1:$A$1000,".tsv"),"")),0)),"notfound")} -> 10.1016%2Fj.zool.2020.125753_SupplementaryTable.tsv | N3: Supplementary Table. Cerebellar Morphology Data | P3: FINISHED | Y3: Ashwell
A4: Avelino-de-Souza, K., Patzke, N., Karlsson, K. A. E., Manger, P. R., & Herculano-Houzel, S. (2025). Cellular Composition of the Brain of a Northern Minke Whale. J Comp Neurol, 533(9), e70089. https://doi.org/10.1002/cne.70089 | D4: TABLE 1 | E4: =RIGHT(A4,1) -> 9 | F4: =G4 & IF(H4<>"", "_" & H4, "_") & IF(I4<>"", "_" & I4, "_") & IF(B4<>"", "_" & B4, "") -> AvelinodeSouza_etal_2025 | G4: =SUBSTITUTE(SUBSTITUTE(_xlfn.TEXTBEFORE(A4,","), "-", ""), " ", "") -> AvelinodeSouza | H4: =_xlfn.LET( _xlpm.authors,_xlfn.TEXTBEFORE(A4," ("&I4&")"), _xlpm.hasAmp,ISNUMBER(SEARCH("&",_xlpm.authors)), _xlpm.commasBeforeAmp,IF(_xlpm.hasAmp,LEN(_xlfn.TEXTBEFORE(_xlpm.authors,"&"))-LEN(SUBSTITUTE(_xlfn.TEXTBEFORE(_xlpm.authors,"&"),",","")),0), IF(NOT(_xlpm.hasAmp),"",IF(_xlpm.commasBeforeAmp>2,"etal",TRIM(_xlfn.TEXTBEFORE(_xlfn.TEXTAFTER(_xlpm.authors,"& "),",")))) ) -> etal | I4: =_xlfn.TEXTBEFORE(_xlfn.TEXTAFTER(A4, "("), ")") -> 2025 | J4: =_xlfn.LET( _xlpm.doi,IF(C4<>"",C4,_xlfn.TEXTAFTER(A4,"https://doi.org/")), SUBSTITUTE( SUBSTITUTE( SUBSTITUTE( SUBSTITUTE( _xlpm.doi, "/","%2F"), ":","%3A"), "<","%3C"), ">","%3E") ) -> 10.1002%2Fcne.70089 | K4: =TRIM(_xlfn.TEXTJOIN("_",FALSE(),F4,(SUBSTITUTE(SUBSTITUTE(D4," ",""), "_", "")))) -> AvelinodeSouza_etal_2025_TABLE1 | L4: =J4 & "_" & SUBSTITUTE(SUBSTITUTE(SUBSTITUTE(D4,CHAR(160),"")," ",""),"_","") -> 10.1002%2Fcne.70089_TABLE1 | M4: {=IFERROR(INDEX(AUTO_Public_TSV_FileList!$A$1:$A$1000,MATCH(TRUE(),EXACT(L4,IFERROR(_xlfn.TEXTBEFORE(AUTO_Public_TSV_FileList!$A$1:$A$1000,".tsv"),"")),0)),"notfound")} -> 10.1002%2Fcne.70089_TABLE1.tsv | N4: Table 1. Cellular composition of the brain of a Northern minke whale (Balaenoptera acutorostrata) | P4: FINISHED | Q4: added | R4: AvelinodeSouza_etal_2025_TABLE1_snapshot.csv | S4: Y | T4: AvelinodeSouza_etal_2025_TABLE1.csv | U4: pdf | V4: table | W4: https://onlinelibrary.wiley.com/doi/10.1002/cne.70089 | X4: https://doi.org/10.1002/cne.70089 | Y4: HH | AG4: isotropic fractionator | AH4: placental mammals | AI4: neuron number | AJ4: Cetaceans & other placental mammals | AK4: primary | AL4: primary | AM4: cell count (isotropic fractionator)
A5: Baker, J., Barton, R. A., & Venditti, C. (2025). Human dexterity and brains evolved hand in hand. Communications Biology, 8(1). https://doi.org/10.1038/s42003-025-08686-5 | D5: Supplementary Data 1 | E5: =RIGHT(A5,1) -> 5 | F5: =G5 & IF(H5<>"", "_" & H5, "_") & IF(I5<>"", "_" & I5, "_") & IF(B5<>"", "_" & B5, "") -> Baker_etal_2025 | G5: =SUBSTITUTE(SUBSTITUTE(_xlfn.TEXTBEFORE(A5,","), "-", ""), " ", "") -> Baker | H5: =_xlfn.LET( _xlpm.authors,_xlfn.TEXTBEFORE(A5," ("&I5&")"), _xlpm.hasAmp,ISNUMBER(SEARCH("&",_xlpm.authors)), _xlpm.commasBeforeAmp,IF(_xlpm.hasAmp,LEN(_xlfn.TEXTBEFORE(_xlpm.authors,"&"))-LEN(SUBSTITUTE(_xlfn.TEXTBEFORE(_xlpm.authors,"&"),",","")),0), IF(NOT(_xlpm.hasAmp),"",IF(_xlpm.commasBeforeAmp>2,"etal",TRIM(_xlfn.TEXTBEFORE(_xlfn.TEXTAFTER(_xlpm.authors,"& "),",")))) ) -> etal | I5: =_xlfn.TEXTBEFORE(_xlfn.TEXTAFTER(A5, "("), ")") -> 2025 | J5: =_xlfn.LET( _xlpm.doi,IF(C5<>"",C5,_xlfn.TEXTAFTER(A5,"https://doi.org/")), SUBSTITUTE( SUBSTITUTE( SUBSTITUTE( SUBSTITUTE( _xlpm.doi, "/","%2F"), ":","%3A"), "<","%3C"), ">","%3E") ) -> 10.1038%2Fs42003-025-08686-5 | K5: =TRIM(_xlfn.TEXTJOIN("_",FALSE(),F5,(SUBSTITUTE(SUBSTITUTE(D5," ",""), "_", "")))) -> Baker_etal_2025_SupplementaryData1 | L5: =J5 & "_" & SUBSTITUTE(SUBSTITUTE(SUBSTITUTE(D5,CHAR(160),"")," ",""),"_","") -> 10.1038%2Fs42003-025-08686-5_SupplementaryData1 | M5: {=IFERROR(INDEX(AUTO_Public_TSV_FileList!$A$1:$A$1000,MATCH(TRUE(),EXACT(L5,IFERROR(_xlfn.TEXTBEFORE(AUTO_Public_TSV_FileList!$A$1:$A$1000,".tsv"),"")),0)),"notfound")} -> 10.1038%2Fs42003-025-08686-5_SupplementaryData1.tsv
A6: Balzeau, A., Holloway, R. L., & Grimaud-Herve, D. (2012). Variations and asymmetries in regional brain surface in the genus Homo. J Hum Evol, 62(6), 696-706. https://doi.org/10.1016/j.jhevol.2012.03.007 | D6: Table 2 | E6: =RIGHT(A6,1) -> 7 | F6: =G6 & IF(H6<>"", "_" & H6, "_") & IF(I6<>"", "_" & I6, "_") & IF(B6<>"", "_" & B6, "") -> Balzeau_etal_2012 | G6: =SUBSTITUTE(SUBSTITUTE(_xlfn.TEXTBEFORE(A6,","), "-", ""), " ", "") -> Balzeau | H6: =_xlfn.LET( _xlpm.authors,_xlfn.TEXTBEFORE(A6," ("&I6&")"), _xlpm.hasAmp,ISNUMBER(SEARCH("&",_xlpm.authors)), _xlpm.commasBeforeAmp,IF(_xlpm.hasAmp,LEN(_xlfn.TEXTBEFORE(_xlpm.authors,"&"))-LEN(SUBSTITUTE(_xlfn.TEXTBEFORE(_xlpm.authors,"&"),",","")),0), IF(NOT(_xlpm.hasAmp),"",IF(_xlpm.commasBeforeAmp>2,"etal",TRIM(_xlfn.TEXTBEFORE(_xlfn.TEXTAFTER(_xlpm.authors,"& "),",")))) ) -> etal | I6: =_xlfn.TEXTBEFORE(_xlfn.TEXTAFTER(A6, "("), ")") -> 2012 | J6: =_xlfn.LET( _xlpm.doi,IF(C6<>"",C6,_xlfn.TEXTAFTER(A6,"https://doi.org/")), SUBSTITUTE( SUBSTITUTE( SUBSTITUTE( SUBSTITUTE( _xlpm.doi, "/","%2F"), ":","%3A"), "<","%3C"), ">","%3E") ) -> 10.1016%2Fj.jhevol.2012.03.007 | K6: =TRIM(_xlfn.TEXTJOIN("_",FALSE(),F6,(SUBSTITUTE(SUBSTITUTE(D6," ",""), "_", "")))) -> Balzeau_etal_2012_Table2 | L6: =J6 & "_" & SUBSTITUTE(SUBSTITUTE(SUBSTITUTE(D6,CHAR(160),"")," ",""),"_","") -> 10.1016%2Fj.jhevol.2012.03.007_Table2 | M6: {=IFERROR(INDEX(AUTO_Public_TSV_FileList!$A$1:$A$1000,MATCH(TRUE(),EXACT(L6,IFERROR(_xlfn.TEXTBEFORE(AUTO_Public_TSV_FileList!$A$1:$A$1000,".tsv"),"")),0)),"notfound")} -> 10.1016%2Fj.jhevol.2012.03.007_Table2.tsv | N6: Table 2. Regression results for the relationship between endocranial volume and the surface of the frontal, parieto-temporal and occipital lobes.
A7: Balzeau, A., Holloway, R. L., & Grimaud-Herve, D. (2012). Variations and asymmetries in regional brain surface in the genus Homo. J Hum Evol, 62(6), 696-706. https://doi.org/10.1016/j.jhevol.2012.03.007 | D7: Table 3 | E7: =RIGHT(A7,1) -> 7 | F7: =G7 & IF(H7<>"", "_" & H7, "_") & IF(I7<>"", "_" & I7, "_") & IF(B7<>"", "_" & B7, "") -> Balzeau_etal_2012 | G7: =SUBSTITUTE(SUBSTITUTE(_xlfn.TEXTBEFORE(A7,","), "-", ""), " ", "") -> Balzeau | H7: =_xlfn.LET( _xlpm.authors,_xlfn.TEXTBEFORE(A7," ("&I7&")"), _xlpm.hasAmp,ISNUMBER(SEARCH("&",_xlpm.authors)), _xlpm.commasBeforeAmp,IF(_xlpm.hasAmp,LEN(_xlfn.TEXTBEFORE(_xlpm.authors,"&"))-LEN(SUBSTITUTE(_xlfn.TEXTBEFORE(_xlpm.authors,"&"),",","")),0), IF(NOT(_xlpm.hasAmp),"",IF(_xlpm.commasBeforeAmp>2,"etal",TRIM(_xlfn.TEXTBEFORE(_xlfn.TEXTAFTER(_xlpm.authors,"& "),",")))) ) -> etal | I7: =_xlfn.TEXTBEFORE(_xlfn.TEXTAFTER(A7, "("), ")") -> 2012 | J7: =_xlfn.LET( _xlpm.doi,IF(C7<>"",C7,_xlfn.TEXTAFTER(A7,"https://doi.org/")), SUBSTITUTE( SUBSTITUTE( SUBSTITUTE( SUBSTITUTE( _xlpm.doi, "/","%2F"), ":","%3A"), "<","%3C"), ">","%3E") ) -> 10.1016%2Fj.jhevol.2012.03.007 | K7: =TRIM(_xlfn.TEXTJOIN("_",FALSE(),F7,(SUBSTITUTE(SUBSTITUTE(D7," ",""), "_", "")))) -> Balzeau_etal_2012_Table3 | L7: =J7 & "_" & SUBSTITUTE(SUBSTITUTE(SUBSTITUTE(D7,CHAR(160),"")," ",""),"_","") -> 10.1016%2Fj.jhevol.2012.03.007_Table3 | M7: {=IFERROR(INDEX(AUTO_Public_TSV_FileList!$A$1:$A$1000,MATCH(TRUE(),EXACT(L7,IFERROR(_xlfn.TEXTBEFORE(AUTO_Public_TSV_FileList!$A$1:$A$1000,".tsv"),"")),0)),"notfound")} -> 10.1016%2Fj.jhevol.2012.03.007_Table3.tsv | N7: Table 3 Size-corrected dimensions for the surface of the frontal, parieto-temporal and occipital lobes in the different analysed samples.
A8: Balzeau, A., Holloway, R. L., & Grimaud-Herve, D. (2012). Variations and asymmetries in regional brain surface in the genus Homo. J Hum Evol, 62(6), 696-706. https://doi.org/10.1016/j.jhevol.2012.03.007 | D8: Table 5 | E8: =RIGHT(A8,1) -> 7 | F8: =G8 & IF(H8<>"", "_" & H8, "_") & IF(I8<>"", "_" & I8, "_") & IF(B8<>"", "_" & B8, "") -> Balzeau_etal_2012 | G8: =SUBSTITUTE(SUBSTITUTE(_xlfn.TEXTBEFORE(A8,","), "-", ""), " ", "") -> Balzeau | H8: =_xlfn.LET( _xlpm.authors,_xlfn.TEXTBEFORE(A8," ("&I8&")"), _xlpm.hasAmp,ISNUMBER(SEARCH("&",_xlpm.authors)), _xlpm.commasBeforeAmp,IF(_xlpm.hasAmp,LEN(_xlfn.TEXTBEFORE(_xlpm.authors,"&"))-LEN(SUBSTITUTE(_xlfn.TEXTBEFORE(_xlpm.authors,"&"),",","")),0), IF(NOT(_xlpm.hasAmp),"",IF(_xlpm.commasBeforeAmp>2,"etal",TRIM(_xlfn.TEXTBEFORE(_xlfn.TEXTAFTER(_xlpm.authors,"& "),",")))) ) -> etal | I8: =_xlfn.TEXTBEFORE(_xlfn.TEXTAFTER(A8, "("), ")") -> 2012 | J8: =_xlfn.LET( _xlpm.doi,IF(C8<>"",C8,_xlfn.TEXTAFTER(A8,"https://doi.org/")), SUBSTITUTE( SUBSTITUTE( SUBSTITUTE( SUBSTITUTE( _xlpm.doi, "/","%2F"), ":","%3A"), "<","%3C"), ">","%3E") ) -> 10.1016%2Fj.jhevol.2012.03.007 | K8: =TRIM(_xlfn.TEXTJOIN("_",FALSE(),F8,(SUBSTITUTE(SUBSTITUTE(D8," ",""), "_", "")))) -> Balzeau_etal_2012_Table5 | L8: =J8 & "_" & SUBSTITUTE(SUBSTITUTE(SUBSTITUTE(D8,CHAR(160),"")," ",""),"_","") -> 10.1016%2Fj.jhevol.2012.03.007_Table5 | M8: {=IFERROR(INDEX(AUTO_Public_TSV_FileList!$A$1:$A$1000,MATCH(TRUE(),EXACT(L8,IFERROR(_xlfn.TEXTBEFORE(AUTO_Public_TSV_FileList!$A$1:$A$1000,".tsv"),"")),0)),"notfound")} -> 10.1016%2Fj.jhevol.2012.03.007_Table5.tsv | N8: Table 5 Percentage contribution of frontal, parieto-temporal and occipital lobes to the hemispheres.
A9: Barbeito-Andres, J., Castro-Fonseca, E., Qiu, L. R., Bernal, V., Lent, R., Henkelman, M., Lukowiak, K., Gleiser, P. M., Hallgrimsson, B., & Gonzalez, P. N. (2019). Region-specific changes in Mus musculus brain size and cell composition under chronic nutrient restriction. J Exp Biol, 222(Pt 17). https://doi.org/10.1242/jeb.204651 | D9: cell density | E9: =RIGHT(A9,1) -> 1 | F9: =G9 & IF(H9<>"", "_" & H9, "_") & IF(I9<>"", "_" & I9, "_") & IF(B9<>"", "_" & B9, "") -> BarbeitoAndres_etal_2019 | G9: =SUBSTITUTE(SUBSTITUTE(_xlfn.TEXTBEFORE(A9,","), "-", ""), " ", "") -> BarbeitoAndres | H9: =_xlfn.LET( _xlpm.authors,_xlfn.TEXTBEFORE(A9," ("&I9&")"), _xlpm.hasAmp,ISNUMBER(SEARCH("&",_xlpm.authors)), _xlpm.commasBeforeAmp,IF(_xlpm.hasAmp,LEN(_xlfn.TEXTBEFORE(_xlpm.authors,"&"))-LEN(SUBSTITUTE(_xlfn.TEXTBEFORE(_xlpm.authors,"&"),",","")),0), IF(NOT(_xlpm.hasAmp),"",IF(_xlpm.commasBeforeAmp>2,"etal",TRIM(_xlfn.TEXTBEFORE(_xlfn.TEXTAFTER(_xlpm.authors,"& "),",")))) ) -> etal | I9: =_xlfn.TEXTBEFORE(_xlfn.TEXTAFTER(A9, "("), ")") -> 2019 | J9: =_xlfn.LET( _xlpm.doi,IF(C9<>"",C9,_xlfn.TEXTAFTER(A9,"https://doi.org/")), SUBSTITUTE( SUBSTITUTE( SUBSTITUTE( SUBSTITUTE( _xlpm.doi, "/","%2F"), ":","%3A"), "<","%3C"), ">","%3E") ) -> 10.1242%2Fjeb.204651 | K9: =TRIM(_xlfn.TEXTJOIN("_",FALSE(),F9,(SUBSTITUTE(SUBSTITUTE(D9," ",""), "_", "")))) -> BarbeitoAndres_etal_2019_celldensity | L9: =J9 & "_" & SUBSTITUTE(SUBSTITUTE(SUBSTITUTE(D9,CHAR(160),"")," ",""),"_","") -> 10.1242%2Fjeb.204651_celldensity | M9: {=IFERROR(INDEX(AUTO_Public_TSV_FileList!$A$1:$A$1000,MATCH(TRUE(),EXACT(L9,IFERROR(_xlfn.TEXTBEFORE(AUTO_Public_TSV_FileList!$A$1:$A$1000,".tsv"),"")),0)),"notfound")} -> 10.1242%2Fjeb.204651_celldensity.tsv | AG9: isotropic fractionator | AJ9: review | AL9: review | AM9: review
A10: Barbeito-Andres, J., Castro-Fonseca, E., Qiu, L. R., Bernal, V., Lent, R., Henkelman, M., Lukowiak, K., Gleiser, P. M., Hallgrimsson, B., & Gonzalez, P. N. (2019). Region-specific changes in Mus musculus brain size and cell composition under chronic nutrient restriction. J Exp Biol, 222(Pt 17). https://doi.org/10.1242/jeb.204651 | D10: cell number | E10: =RIGHT(A10,1) -> 1 | F10: =G10 & IF(H10<>"", "_" & H10, "_") & IF(I10<>"", "_" & I10, "_") & IF(B10<>"", "_" & B10, "") -> BarbeitoAndres_etal_2019 | G10: =SUBSTITUTE(SUBSTITUTE(_xlfn.TEXTBEFORE(A10,","), "-", ""), " ", "") -> BarbeitoAndres | H10: =_xlfn.LET( _xlpm.authors,_xlfn.TEXTBEFORE(A10," ("&I10&")"), _xlpm.hasAmp,ISNUMBER(SEARCH("&",_xlpm.authors)), _xlpm.commasBeforeAmp,IF(_xlpm.hasAmp,LEN(_xlfn.TEXTBEFORE(_xlpm.authors,"&"))-LEN(SUBSTITUTE(_xlfn.TEXTBEFORE(_xlpm.authors,"&"),",","")),0), IF(NOT(_xlpm.hasAmp),"",IF(_xlpm.commasBeforeAmp>2,"etal",TRIM(_xlfn.TEXTBEFORE(_xlfn.TEXTAFTER(_xlpm.authors,"& "),",")))) ) -> etal | I10: =_xlfn.TEXTBEFORE(_xlfn.TEXTAFTER(A10, "("), ")") -> 2019 | J10: =_xlfn.LET( _xlpm.doi,IF(C10<>"",C10,_xlfn.TEXTAFTER(A10,"https://doi.org/")), SUBSTITUTE( SUBSTITUTE( SUBSTITUTE( SUBSTITUTE( _xlpm.doi, "/","%2F"), ":","%3A"), "<","%3C"), ">","%3E") ) -> 10.1242%2Fjeb.204651 | K10: =TRIM(_xlfn.TEXTJOIN("_",FALSE(),F10,(SUBSTITUTE(SUBSTITUTE(D10," ",""), "_", "")))) -> BarbeitoAndres_etal_2019_cellnumber | L10: =J10 & "_" & SUBSTITUTE(SUBSTITUTE(SUBSTITUTE(D10,CHAR(160),"")," ",""),"_","") -> 10.1242%2Fjeb.204651_cellnumber | M10: {=IFERROR(INDEX(AUTO_Public_TSV_FileList!$A$1:$A$1000,MATCH(TRUE(),EXACT(L10,IFERROR(_xlfn.TEXTBEFORE(AUTO_Public_TSV_FileList!$A$1:$A$1000,".tsv"),"")),0)),"notfound")} -> 10.1242%2Fjeb.204651_cellnumber.tsv | AG10: isotropic fractionator | AJ10: review | AL10: review | AM10: review
A11: Barbeito-Andres, J., Castro-Fonseca, E., Qiu, L. R., Bernal, V., Lent, R., Henkelman, M., Lukowiak, K., Gleiser, P. M., Hallgrimsson, B., & Gonzalez, P. N. (2019). Region-specific changes in Mus musculus brain size and cell composition under chronic nutrient restriction. J Exp Biol, 222(Pt 17). https://doi.org/10.1242/jeb.204651 | D11: volumes | E11: =RIGHT(A11,1) -> 1 | F11: =G11 & IF(H11<>"", "_" & H11, "_") & IF(I11<>"", "_" & I11, "_") & IF(B11<>"", "_" & B11, "") -> BarbeitoAndres_etal_2019 | G11: =SUBSTITUTE(SUBSTITUTE(_xlfn.TEXTBEFORE(A11,","), "-", ""), " ", "") -> BarbeitoAndres | H11: =_xlfn.LET( _xlpm.authors,_xlfn.TEXTBEFORE(A11," ("&I11&")"), _xlpm.hasAmp,ISNUMBER(SEARCH("&",_xlpm.authors)), _xlpm.commasBeforeAmp,IF(_xlpm.hasAmp,LEN(_xlfn.TEXTBEFORE(_xlpm.authors,"&"))-LEN(SUBSTITUTE(_xlfn.TEXTBEFORE(_xlpm.authors,"&"),",","")),0), IF(NOT(_xlpm.hasAmp),"",IF(_xlpm.commasBeforeAmp>2,"etal",TRIM(_xlfn.TEXTBEFORE(_xlfn.TEXTAFTER(_xlpm.authors,"& "),",")))) ) -> etal | I11: =_xlfn.TEXTBEFORE(_xlfn.TEXTAFTER(A11, "("), ")") -> 2019 | J11: =_xlfn.LET( _xlpm.doi,IF(C11<>"",C11,_xlfn.TEXTAFTER(A11,"https://doi.org/")), SUBSTITUTE( SUBSTITUTE( SUBSTITUTE( SUBSTITUTE( _xlpm.doi, "/","%2F"), ":","%3A"), "<","%3C"), ">","%3E") ) -> 10.1242%2Fjeb.204651 | K11: =TRIM(_xlfn.TEXTJOIN("_",FALSE(),F11,(SUBSTITUTE(SUBSTITUTE(D11," ",""), "_", "")))) -> BarbeitoAndres_etal_2019_volumes | L11: =J11 & "_" & SUBSTITUTE(SUBSTITUTE(SUBSTITUTE(D11,CHAR(160),"")," ",""),"_","") -> 10.1242%2Fjeb.204651_volumes | M11: {=IFERROR(INDEX(AUTO_Public_TSV_FileList!$A$1:$A$1000,MATCH(TRUE(),EXACT(L11,IFERROR(_xlfn.TEXTBEFORE(AUTO_Public_TSV_FileList!$A$1:$A$1000,".tsv"),"")),0)),"notfound")} -> 10.1242%2Fjeb.204651_volumes.tsv | AG11: isotropic fractionator | AJ11: review | AL11: review | AM11: review
A12: Barger, N., Hanson, K. L., Teffer, K., Schenker-Ahmed, N. M., & Semendeferi, K. (2014). Evidence for evolutionary specialization in human limbic structures. Front Hum Neurosci, 8, 277. https://doi.org/10.3389/fnhum.2014.00277 | D12: Table 1 | E12: =RIGHT(A12,1) -> 7 | F12: =G12 & IF(H12<>"", "_" & H12, "_") & IF(I12<>"", "_" & I12, "_") & IF(B12<>"", "_" & B12, "") -> Barger_etal_2014 | G12: =SUBSTITUTE(SUBSTITUTE(_xlfn.TEXTBEFORE(A12,","), "-", ""), " ", "") -> Barger | H12: =_xlfn.LET( _xlpm.authors,_xlfn.TEXTBEFORE(A12," ("&I12&")"), _xlpm.hasAmp,ISNUMBER(SEARCH("&",_xlpm.authors)), _xlpm.commasBeforeAmp,IF(_xlpm.hasAmp,LEN(_xlfn.TEXTBEFORE(_xlpm.authors,"&"))-LEN(SUBSTITUTE(_xlfn.TEXTBEFORE(_xlpm.authors,"&"),",","")),0), IF(NOT(_xlpm.hasAmp),"",IF(_xlpm.commasBeforeAmp>2,"etal",TRIM(_xlfn.TEXTBEFORE(_xlfn.TEXTAFTER(_xlpm.authors,"& "),",")))) ) -> etal | I12: =_xlfn.TEXTBEFORE(_xlfn.TEXTAFTER(A12, "("), ")") -> 2014 | J12: =_xlfn.LET( _xlpm.doi,IF(C12<>"",C12,_xlfn.TEXTAFTER(A12,"https://doi.org/")), SUBSTITUTE( SUBSTITUTE( SUBSTITUTE( SUBSTITUTE( _xlpm.doi, "/","%2F"), ":","%3A"), "<","%3C"), ">","%3E") ) -> 10.3389%2Ffnhum.2014.00277 | K12: =TRIM(_xlfn.TEXTJOIN("_",FALSE(),F12,(SUBSTITUTE(SUBSTITUTE(D12," ",""), "_", "")))) -> Barger_etal_2014_Table1 | L12: =J12 & "_" & SUBSTITUTE(SUBSTITUTE(SUBSTITUTE(D12,CHAR(160),"")," ",""),"_","") -> 10.3389%2Ffnhum.2014.00277_Table1 | M12: {=IFERROR(INDEX(AUTO_Public_TSV_FileList!$A$1:$A$1000,MATCH(TRUE(),EXACT(L12,IFERROR(_xlfn.TEXTBEFORE(AUTO_Public_TSV_FileList!$A$1:$A$1000,".tsv"),"")),0)),"notfound")} -> 10.3389%2Ffnhum.2014.00277_Table1.tsv | N12: Table 1 | Volume of amygdala, hippocampus, and striatum in hominoid species collected with stereological methods. | Z12: Zilles | AF12: histological sections | AG12: Zilles
A13: Barger, N., Stefanacci, L., & Semendeferi, K. (2007). A comparative volumetric analysis of the amygdaloid complex and basolateral division in the human and ape brain. Am J Phys Anthropol, 134(3), 392-403. https://doi.org/10.1002/ajpa.20684 | D13: TABLE 1 | E13: =RIGHT(A13,1) -> 4 | F13: =G13 & IF(H13<>"", "_" & H13, "_") & IF(I13<>"", "_" & I13, "_") & IF(B13<>"", "_" & B13, "") -> Barger_etal_2007 | G13: =SUBSTITUTE(SUBSTITUTE(_xlfn.TEXTBEFORE(A13,","), "-", ""), " ", "") -> Barger | H13: =_xlfn.LET( _xlpm.authors,_xlfn.TEXTBEFORE(A13," ("&I13&")"), _xlpm.hasAmp,ISNUMBER(SEARCH("&",_xlpm.authors)), _xlpm.commasBeforeAmp,IF(_xlpm.hasAmp,LEN(_xlfn.TEXTBEFORE(_xlpm.authors,"&"))-LEN(SUBSTITUTE(_xlfn.TEXTBEFORE(_xlpm.authors,"&"),",","")),0), IF(NOT(_xlpm.hasAmp),"",IF(_xlpm.commasBeforeAmp>2,"etal",TRIM(_xlfn.TEXTBEFORE(_xlfn.TEXTAFTER(_xlpm.authors,"& "),",")))) ) -> etal | I13: =_xlfn.TEXTBEFORE(_xlfn.TEXTAFTER(A13, "("), ")") -> 2007 | J13: =_xlfn.LET( _xlpm.doi,IF(C13<>"",C13,_xlfn.TEXTAFTER(A13,"https://doi.org/")), SUBSTITUTE( SUBSTITUTE( SUBSTITUTE( SUBSTITUTE( _xlpm.doi, "/","%2F"), ":","%3A"), "<","%3C"), ">","%3E") ) -> 10.1002%2Fajpa.20684 | K13: =TRIM(_xlfn.TEXTJOIN("_",FALSE(),F13,(SUBSTITUTE(SUBSTITUTE(D13," ",""), "_", "")))) -> Barger_etal_2007_TABLE1 | L13: =J13 & "_" & SUBSTITUTE(SUBSTITUTE(SUBSTITUTE(D13,CHAR(160),"")," ",""),"_","") -> 10.1002%2Fajpa.20684_TABLE1 | M13: {=IFERROR(INDEX(AUTO_Public_TSV_FileList!$A$1:$A$1000,MATCH(TRUE(),EXACT(L13,IFERROR(_xlfn.TEXTBEFORE(AUTO_Public_TSV_FileList!$A$1:$A$1000,".tsv"),"")),0)),"notfound")} -> 10.1002%2Fajpa.20684_TABLE1.tsv | N13: TABLE 1. Volumetric estimates of the amygdaloid complex and the basolateral division | P13: FINISHED | Z13: Zilles | AG13: Zilles | AI13: amygdala subdivision volumes | AJ13: Apes & humans | AL13: primary | AM13: volume
A14: Barger, N., Stefanacci, L., Schumann, C. M., Sherwood, C. C., Annese, J., Allman, J. M., Buckwalter, J. A., Hof, P. R., & Semendeferi, K. (2012). Neuronal populations in the basolateral nuclei of the amygdala are differentially increased in humans compared with apes: A stereological study. J Comp Neurol, 520(13), 3035-3054. https://doi.org/10.1002/cne.23118 | D14: Table 3 | E14: =RIGHT(A14,1) -> 8 | F14: =G14 & IF(H14<>"", "_" & H14, "_") & IF(I14<>"", "_" & I14, "_") & IF(B14<>"", "_" & B14, "") -> Barger_etal_2012 | G14: =SUBSTITUTE(SUBSTITUTE(_xlfn.TEXTBEFORE(A14,","), "-", ""), " ", "") -> Barger | H14: =_xlfn.LET( _xlpm.authors,_xlfn.TEXTBEFORE(A14," ("&I14&")"), _xlpm.hasAmp,ISNUMBER(SEARCH("&",_xlpm.authors)), _xlpm.commasBeforeAmp,IF(_xlpm.hasAmp,LEN(_xlfn.TEXTBEFORE(_xlpm.authors,"&"))-LEN(SUBSTITUTE(_xlfn.TEXTBEFORE(_xlpm.authors,"&"),",","")),0), IF(NOT(_xlpm.hasAmp),"",IF(_xlpm.commasBeforeAmp>2,"etal",TRIM(_xlfn.TEXTBEFORE(_xlfn.TEXTAFTER(_xlpm.authors,"& "),",")))) ) -> etal | I14: =_xlfn.TEXTBEFORE(_xlfn.TEXTAFTER(A14, "("), ")") -> 2012 | J14: =_xlfn.LET( _xlpm.doi,IF(C14<>"",C14,_xlfn.TEXTAFTER(A14,"https://doi.org/")), SUBSTITUTE( SUBSTITUTE( SUBSTITUTE( SUBSTITUTE( _xlpm.doi, "/","%2F"), ":","%3A"), "<","%3C"), ">","%3E") ) -> 10.1002%2Fcne.23118 | K14: =TRIM(_xlfn.TEXTJOIN("_",FALSE(),F14,(SUBSTITUTE(SUBSTITUTE(D14," ",""), "_", "")))) -> Barger_etal_2012_Table3 | L14: =J14 & "_" & SUBSTITUTE(SUBSTITUTE(SUBSTITUTE(D14,CHAR(160),"")," ",""),"_","") -> 10.1002%2Fcne.23118_Table3 | M14: {=IFERROR(INDEX(AUTO_Public_TSV_FileList!$A$1:$A$1000,MATCH(TRUE(),EXACT(L14,IFERROR(_xlfn.TEXTBEFORE(AUTO_Public_TSV_FileList!$A$1:$A$1000,".tsv"),"")),0)),"notfound")} -> 10.1002%2Fcne.23118_Table3.tsv | N14: Table 3. Average Neuron Number x10^6 (SD) for each nucleus in each species | P14: FINISHED | AI14: amygdala neuron numbers (basolateral + central nuclei) | AJ14: Primates | AK14: primary | AL14: primary | AM14: neuron count (stereology)
A15: Barks, S. K., Calhoun, M. E., Hopkins, W. D., Cranfield, M. R., Mudakikwa, A., Stoinski, T. S., Patterson, F. G., Erwin, J. M., Hecht, E. E., Hof, P. R., & Sherwood, C. C. (2014). Brain organization of gorillas reflects species differences in ecology. Am J Phys Anthropol. https://doi.org/10.1002/ajpa.22646 | D15: Fig 4 A | E15: =RIGHT(A15,1) -> 6 | F15: =G15 & IF(H15<>"", "_" & H15, "_") & IF(I15<>"", "_" & I15, "_") & IF(B15<>"", "_" & B15, "") -> Barks_etal_2014 | G15: =SUBSTITUTE(SUBSTITUTE(_xlfn.TEXTBEFORE(A15,","), "-", ""), " ", "") -> Barks | H15: =_xlfn.LET( _xlpm.authors,_xlfn.TEXTBEFORE(A15," ("&I15&")"), _xlpm.hasAmp,ISNUMBER(SEARCH("&",_xlpm.authors)), _xlpm.commasBeforeAmp,IF(_xlpm.hasAmp,LEN(_xlfn.TEXTBEFORE(_xlpm.authors,"&"))-LEN(SUBSTITUTE(_xlfn.TEXTBEFORE(_xlpm.authors,"&"),",","")),0), IF(NOT(_xlpm.hasAmp),"",IF(_xlpm.commasBeforeAmp>2,"etal",TRIM(_xlfn.TEXTBEFORE(_xlfn.TEXTAFTER(_xlpm.authors,"& "),",")))) ) -> etal | I15: =_xlfn.TEXTBEFORE(_xlfn.TEXTAFTER(A15, "("), ")") -> 2014 | J15: =_xlfn.LET( _xlpm.doi,IF(C15<>"",C15,_xlfn.TEXTAFTER(A15,"https://doi.org/")), SUBSTITUTE( SUBSTITUTE( SUBSTITUTE( SUBSTITUTE( _xlpm.doi, "/","%2F"), ":","%3A"), "<","%3C"), ">","%3E") ) -> 10.1002%2Fajpa.22646 | K15: =TRIM(_xlfn.TEXTJOIN("_",FALSE(),F15,(SUBSTITUTE(SUBSTITUTE(D15," ",""), "_", "")))) -> Barks_etal_2014_Fig4A | L15: =J15 & "_" & SUBSTITUTE(SUBSTITUTE(SUBSTITUTE(D15,CHAR(160),"")," ",""),"_","") -> 10.1002%2Fajpa.22646_Fig4A | M15: {=IFERROR(INDEX(AUTO_Public_TSV_FileList!$A$1:$A$1000,MATCH(TRUE(),EXACT(L15,IFERROR(_xlfn.TEXTBEFORE(AUTO_Public_TSV_FileList!$A$1:$A$1000,".tsv"),"")),0)),"notfound")} -> 10.1002%2Fajpa.22646_Fig4A.tsv | O15: Fig4A_allsubjects_volumes | P15: FINISHED | Y15: Barks
A16: Barks, S. K., Calhoun, M. E., Hopkins, W. D., Cranfield, M. R., Mudakikwa, A., Stoinski, T. S., Patterson, F. G., Erwin, J. M., Hecht, E. E., Hof, P. R., & Sherwood, C. C. (2014). Brain organization of gorillas reflects species differences in ecology. Am J Phys Anthropol. https://doi.org/10.1002/ajpa.22646 | D16: Fig 5 A | E16: =RIGHT(A16,1) -> 6 | F16: =G16 & IF(H16<>"", "_" & H16, "_") & IF(I16<>"", "_" & I16, "_") & IF(B16<>"", "_" & B16, "") -> Barks_etal_2014 | G16: =SUBSTITUTE(SUBSTITUTE(_xlfn.TEXTBEFORE(A16,","), "-", ""), " ", "") -> Barks | H16: =_xlfn.LET( _xlpm.authors,_xlfn.TEXTBEFORE(A16," ("&I16&")"), _xlpm.hasAmp,ISNUMBER(SEARCH("&",_xlpm.authors)), _xlpm.commasBeforeAmp,IF(_xlpm.hasAmp,LEN(_xlfn.TEXTBEFORE(_xlpm.authors,"&"))-LEN(SUBSTITUTE(_xlfn.TEXTBEFORE(_xlpm.authors,"&"),",","")),0), IF(NOT(_xlpm.hasAmp),"",IF(_xlpm.commasBeforeAmp>2,"etal",TRIM(_xlfn.TEXTBEFORE(_xlfn.TEXTAFTER(_xlpm.authors,"& "),",")))) ) -> etal | I16: =_xlfn.TEXTBEFORE(_xlfn.TEXTAFTER(A16, "("), ")") -> 2014 | J16: =_xlfn.LET( _xlpm.doi,IF(C16<>"",C16,_xlfn.TEXTAFTER(A16,"https://doi.org/")), SUBSTITUTE( SUBSTITUTE( SUBSTITUTE( SUBSTITUTE( _xlpm.doi, "/","%2F"), ":","%3A"), "<","%3C"), ">","%3E") ) -> 10.1002%2Fajpa.22646 | K16: =TRIM(_xlfn.TEXTJOIN("_",FALSE(),F16,(SUBSTITUTE(SUBSTITUTE(D16," ",""), "_", "")))) -> Barks_etal_2014_Fig5A | L16: =J16 & "_" & SUBSTITUTE(SUBSTITUTE(SUBSTITUTE(D16,CHAR(160),"")," ",""),"_","") -> 10.1002%2Fajpa.22646_Fig5A | M16: {=IFERROR(INDEX(AUTO_Public_TSV_FileList!$A$1:$A$1000,MATCH(TRUE(),EXACT(L16,IFERROR(_xlfn.TEXTBEFORE(AUTO_Public_TSV_FileList!$A$1:$A$1000,".tsv"),"")),0)),"notfound")} -> 10.1002%2Fajpa.22646_Fig5A.tsv | O16: Fig5A_adultsonly_volumes | P16: FINISHED
A17: Barks, S. K., Calhoun, M. E., Hopkins, W. D., Cranfield, M. R., Mudakikwa, A., Stoinski, T. S., Patterson, F. G., Erwin, J. M., Hecht, E. E., Hof, P. R., & Sherwood, C. C. (2014). Brain organization of gorillas reflects species differences in ecology. Am J Phys Anthropol. https://doi.org/10.1002/ajpa.22646 | D17: TABLE 1 | E17: =RIGHT(A17,1) -> 6 | F17: =G17 & IF(H17<>"", "_" & H17, "_") & IF(I17<>"", "_" & I17, "_") & IF(B17<>"", "_" & B17, "") -> Barks_etal_2014 | G17: =SUBSTITUTE(SUBSTITUTE(_xlfn.TEXTBEFORE(A17,","), "-", ""), " ", "") -> Barks | H17: =_xlfn.LET( _xlpm.authors,_xlfn.TEXTBEFORE(A17," ("&I17&")"), _xlpm.hasAmp,ISNUMBER(SEARCH("&",_xlpm.authors)), _xlpm.commasBeforeAmp,IF(_xlpm.hasAmp,LEN(_xlfn.TEXTBEFORE(_xlpm.authors,"&"))-LEN(SUBSTITUTE(_xlfn.TEXTBEFORE(_xlpm.authors,"&"),",","")),0), IF(NOT(_xlpm.hasAmp),"",IF(_xlpm.commasBeforeAmp>2,"etal",TRIM(_xlfn.TEXTBEFORE(_xlfn.TEXTAFTER(_xlpm.authors,"& "),",")))) ) -> etal | I17: =_xlfn.TEXTBEFORE(_xlfn.TEXTAFTER(A17, "("), ")") -> 2014 | J17: =_xlfn.LET( _xlpm.doi,IF(C17<>"",C17,_xlfn.TEXTAFTER(A17,"https://doi.org/")), SUBSTITUTE( SUBSTITUTE( SUBSTITUTE( SUBSTITUTE( _xlpm.doi, "/","%2F"), ":","%3A"), "<","%3C"), ">","%3E") ) -> 10.1002%2Fajpa.22646 | K17: =TRIM(_xlfn.TEXTJOIN("_",FALSE(),F17,(SUBSTITUTE(SUBSTITUTE(D17," ",""), "_", "")))) -> Barks_etal_2014_TABLE1 | L17: =J17 & "_" & SUBSTITUTE(SUBSTITUTE(SUBSTITUTE(D17,CHAR(160),"")," ",""),"_","") -> 10.1002%2Fajpa.22646_TABLE1 | M17: {=IFERROR(INDEX(AUTO_Public_TSV_FileList!$A$1:$A$1000,MATCH(TRUE(),EXACT(L17,IFERROR(_xlfn.TEXTBEFORE(AUTO_Public_TSV_FileList!$A$1:$A$1000,".tsv"),"")),0)),"notfound")} -> 10.1002%2Fajpa.22646_TABLE1.tsv | N17: TABLE 1. Individual data | P17: FINISHED | Y17: Barks
A18: Barks, S. K., Calhoun, M. E., Hopkins, W. D., Cranfield, M. R., Mudakikwa, A., Stoinski, T. S., Patterson, F. G., Erwin, J. M., Hecht, E. E., Hof, P. R., & Sherwood, C. C. (2014). Brain organization of gorillas reflects species differences in ecology. Am J Phys Anthropol. https://doi.org/10.1002/ajpa.22646 | D18: TABLE 2 | E18: =RIGHT(A18,1) -> 6 | F18: =G18 & IF(H18<>"", "_" & H18, "_") & IF(I18<>"", "_" & I18, "_") & IF(B18<>"", "_" & B18, "") -> Barks_etal_2014 | G18: =SUBSTITUTE(SUBSTITUTE(_xlfn.TEXTBEFORE(A18,","), "-", ""), " ", "") -> Barks | H18: =_xlfn.LET( _xlpm.authors,_xlfn.TEXTBEFORE(A18," ("&I18&")"), _xlpm.hasAmp,ISNUMBER(SEARCH("&",_xlpm.authors)), _xlpm.commasBeforeAmp,IF(_xlpm.hasAmp,LEN(_xlfn.TEXTBEFORE(_xlpm.authors,"&"))-LEN(SUBSTITUTE(_xlfn.TEXTBEFORE(_xlpm.authors,"&"),",","")),0), IF(NOT(_xlpm.hasAmp),"",IF(_xlpm.commasBeforeAmp>2,"etal",TRIM(_xlfn.TEXTBEFORE(_xlfn.TEXTAFTER(_xlpm.authors,"& "),",")))) ) -> etal | I18: =_xlfn.TEXTBEFORE(_xlfn.TEXTAFTER(A18, "("), ")") -> 2014 | J18: =_xlfn.LET( _xlpm.doi,IF(C18<>"",C18,_xlfn.TEXTAFTER(A18,"https://doi.org/")), SUBSTITUTE( SUBSTITUTE( SUBSTITUTE( SUBSTITUTE( _xlpm.doi, "/","%2F"), ":","%3A"), "<","%3C"), ">","%3E") ) -> 10.1002%2Fajpa.22646 | K18: =TRIM(_xlfn.TEXTJOIN("_",FALSE(),F18,(SUBSTITUTE(SUBSTITUTE(D18," ",""), "_", "")))) -> Barks_etal_2014_TABLE2 | L18: =J18 & "_" & SUBSTITUTE(SUBSTITUTE(SUBSTITUTE(D18,CHAR(160),"")," ",""),"_","") -> 10.1002%2Fajpa.22646_TABLE2 | M18: {=IFERROR(INDEX(AUTO_Public_TSV_FileList!$A$1:$A$1000,MATCH(TRUE(),EXACT(L18,IFERROR(_xlfn.TEXTBEFORE(AUTO_Public_TSV_FileList!$A$1:$A$1000,".tsv"),"")),0)),"notfound")} -> 10.1002%2Fajpa.22646_TABLE2.tsv | N18: TABLE 2. Stereological sampling of brains | P18: FINISHED
A19: Barks, S. K., Calhoun, M. E., Hopkins, W. D., Cranfield, M. R., Mudakikwa, A., Stoinski, T. S., Patterson, F. G., Erwin, J. M., Hecht, E. E., Hof, P. R., & Sherwood, C. C. (2014). Brain organization of gorillas reflects species differences in ecology. Am J Phys Anthropol. https://doi.org/10.1002/ajpa.22646 | D19: unpublishedviaDeCasien | E19: =RIGHT(A19,1) -> 6 | F19: =G19 & IF(H19<>"", "_" & H19, "_") & IF(I19<>"", "_" & I19, "_") & IF(B19<>"", "_" & B19, "") -> Barks_etal_2014 | G19: =SUBSTITUTE(SUBSTITUTE(_xlfn.TEXTBEFORE(A19,","), "-", ""), " ", "") -> Barks | H19: =_xlfn.LET( _xlpm.authors,_xlfn.TEXTBEFORE(A19," ("&I19&")"), _xlpm.hasAmp,ISNUMBER(SEARCH("&",_xlpm.authors)), _xlpm.commasBeforeAmp,IF(_xlpm.hasAmp,LEN(_xlfn.TEXTBEFORE(_xlpm.authors,"&"))-LEN(SUBSTITUTE(_xlfn.TEXTBEFORE(_xlpm.authors,"&"),",","")),0), IF(NOT(_xlpm.hasAmp),"",IF(_xlpm.commasBeforeAmp>2,"etal",TRIM(_xlfn.TEXTBEFORE(_xlfn.TEXTAFTER(_xlpm.authors,"& "),",")))) ) -> etal | I19: =_xlfn.TEXTBEFORE(_xlfn.TEXTAFTER(A19, "("), ")") -> 2014 | J19: =_xlfn.LET( _xlpm.doi,IF(C19<>"",C19,_xlfn.TEXTAFTER(A19,"https://doi.org/")), SUBSTITUTE( SUBSTITUTE( SUBSTITUTE( SUBSTITUTE( _xlpm.doi, "/","%2F"), ":","%3A"), "<","%3C"), ">","%3E") ) -> 10.1002%2Fajpa.22646 | K19: =TRIM(_xlfn.TEXTJOIN("_",FALSE(),F19,(SUBSTITUTE(SUBSTITUTE(D19," ",""), "_", "")))) -> Barks_etal_2014_unpublishedviaDeCasien | L19: =J19 & "_" & SUBSTITUTE(SUBSTITUTE(SUBSTITUTE(D19,CHAR(160),"")," ",""),"_","") -> 10.1002%2Fajpa.22646_unpublishedviaDeCasien | M19: {=IFERROR(INDEX(AUTO_Public_TSV_FileList!$A$1:$A$1000,MATCH(TRUE(),EXACT(L19,IFERROR(_xlfn.TEXTBEFORE(AUTO_Public_TSV_FileList!$A$1:$A$1000,".tsv"),"")),0)),"notfound")} -> 10.1002%2Fajpa.22646_unpublishedviaDeCasien.tsv | O19: "Sherwood et al.64 and Barks et al.65 provided neocortex, hippocampus, striatum, thalamus, cerebellum, amygdala and insula measures for multiple gorilla species (Gorilla gorilla gorilla, G. g. graueri and G. beringei) from post-mortem MRI scans" (DeCasien and Higham 2019)
A20: Baron, G., Frahm, H. D., & Stephan, H. (1988). Comparison of brain structure volumes in Insectivora and Primates. VIII. Vestibular complex. J Hirnforsch, 29(5), 509-523. http://www.ncbi.nlm.nih.gov/pubmed/3216099 | C20: PMID:3216099 | D20: Table 1 | E20: =RIGHT(A20,1) -> 9 | F20: =G20 & IF(H20<>"", "_" & H20, "_") & IF(I20<>"", "_" & I20, "_") & IF(B20<>"", "_" & B20, "") -> Baron_etal_1988 | G20: =SUBSTITUTE(SUBSTITUTE(_xlfn.TEXTBEFORE(A20,","), "-", ""), " ", "") -> Baron | H20: =_xlfn.LET( _xlpm.authors,_xlfn.TEXTBEFORE(A20," ("&I20&")"), _xlpm.hasAmp,ISNUMBER(SEARCH("&",_xlpm.authors)), _xlpm.commasBeforeAmp,IF(_xlpm.hasAmp,LEN(_xlfn.TEXTBEFORE(_xlpm.authors,"&"))-LEN(SUBSTITUTE(_xlfn.TEXTBEFORE(_xlpm.authors,"&"),",","")),0), IF(NOT(_xlpm.hasAmp),"",IF(_xlpm.commasBeforeAmp>2,"etal",TRIM(_xlfn.TEXTBEFORE(_xlfn.TEXTAFTER(_xlpm.authors,"& "),",")))) ) -> etal | I20: =_xlfn.TEXTBEFORE(_xlfn.TEXTAFTER(A20, "("), ")") -> 1988 | J20: =_xlfn.LET( _xlpm.doi,IF(C20<>"",C20,_xlfn.TEXTAFTER(A20,"https://doi.org/")), SUBSTITUTE( SUBSTITUTE( SUBSTITUTE( SUBSTITUTE( _xlpm.doi, "/","%2F"), ":","%3A"), "<","%3C"), ">","%3E") ) -> PMID%3A3216099 | K20: =TRIM(_xlfn.TEXTJOIN("_",FALSE(),F20,(SUBSTITUTE(SUBSTITUTE(D20," ",""), "_", "")))) -> Baron_etal_1988_Table1 | L20: =J20 & "_" & SUBSTITUTE(SUBSTITUTE(SUBSTITUTE(D20,CHAR(160),"")," ",""),"_","") -> PMID%3A3216099_Table1 | M20: {=IFERROR(INDEX(AUTO_Public_TSV_FileList!$A$1:$A$1000,MATCH(TRUE(),EXACT(L20,IFERROR(_xlfn.TEXTBEFORE(AUTO_Public_TSV_FileList!$A$1:$A$1000,".tsv"),"")),0)),"notfound")} -> PMID%3A3216099_Table1.tsv | N20: Table 1. Volumes and indices of the vestibular complex (VC) and its main components (VM, V1, VL, VS) in Insectivora and Scadentia | P20: FINISHED | Y20: Stephan | Z20: Stephan | AF20: histological sections | AG20: Stephan | AI20: vestibular nuclear complex volume | AJ20: Insectivora, Scandentia & Primates | AL20: primary | AM20: volume
A21: Baron, G., Frahm, H. D., Bhatnagar, K. P., & Stephan, H. (1983). Comparison of brain structure volumes in Insectivora and Primates. III. Main olfactory bulb (MOB). J Hirnforsch, 24(5), 551-568. https://www.ncbi.nlm.nih.gov/pubmed/6663055 | C21: PMID:6663055 | D21: Table 1 | E21: =RIGHT(A21,1) -> 5 | F21: =G21 & IF(H21<>"", "_" & H21, "_") & IF(I21<>"", "_" & I21, "_") & IF(B21<>"", "_" & B21, "") -> Baron_etal_1983 | G21: =SUBSTITUTE(SUBSTITUTE(_xlfn.TEXTBEFORE(A21,","), "-", ""), " ", "") -> Baron | H21: =_xlfn.LET( _xlpm.authors,_xlfn.TEXTBEFORE(A21," ("&I21&")"), _xlpm.hasAmp,ISNUMBER(SEARCH("&",_xlpm.authors)), _xlpm.commasBeforeAmp,IF(_xlpm.hasAmp,LEN(_xlfn.TEXTBEFORE(_xlpm.authors,"&"))-LEN(SUBSTITUTE(_xlfn.TEXTBEFORE(_xlpm.authors,"&"),",","")),0), IF(NOT(_xlpm.hasAmp),"",IF(_xlpm.commasBeforeAmp>2,"etal",TRIM(_xlfn.TEXTBEFORE(_xlfn.TEXTAFTER(_xlpm.authors,"& "),",")))) ) -> etal | I21: =_xlfn.TEXTBEFORE(_xlfn.TEXTAFTER(A21, "("), ")") -> 1983 | J21: =_xlfn.LET( _xlpm.doi,IF(C21<>"",C21,_xlfn.TEXTAFTER(A21,"https://doi.org/")), SUBSTITUTE( SUBSTITUTE( SUBSTITUTE( SUBSTITUTE( _xlpm.doi, "/","%2F"), ":","%3A"), "<","%3C"), ">","%3E") ) -> PMID%3A6663055 | K21: =TRIM(_xlfn.TEXTJOIN("_",FALSE(),F21,(SUBSTITUTE(SUBSTITUTE(D21," ",""), "_", "")))) -> Baron_etal_1983_Table1 | L21: =J21 & "_" & SUBSTITUTE(SUBSTITUTE(SUBSTITUTE(D21,CHAR(160),"")," ",""),"_","") -> PMID%3A6663055_Table1 | M21: {=IFERROR(INDEX(AUTO_Public_TSV_FileList!$A$1:$A$1000,MATCH(TRUE(),EXACT(L21,IFERROR(_xlfn.TEXTBEFORE(AUTO_Public_TSV_FileList!$A$1:$A$1000,".tsv"),"")),0)),"notfound")} -> PMID%3A6663055_Table1.tsv | P21: FINISHED | V21: table | W21: NO - not digitized | Y21: Stephan | Z21: Stephan | AF21: histological sections | AG21: Stephan | AI21: main olfactory bulb (MOB) volume | AJ21: Insectivora, Scandentia & Primates | AK21: primary | AL21: primary | AM21: volume
A22: Baron, G., Stephan, H., & Frahm, H. D. (1987). Comparison of brain structure volumes in Insectivora and Primates. VI. Paleocortical components. J Hirnforsch, 28(4), 463-477. http://www.ncbi.nlm.nih.gov/pubmed/3116076 | C22: PMID:3116076 | D22: Table 1 | E22: =RIGHT(A22,1) -> 6 | F22: =G22 & IF(H22<>"", "_" & H22, "_") & IF(I22<>"", "_" & I22, "_") & IF(B22<>"", "_" & B22, "") -> Baron_etal_1987 | G22: =SUBSTITUTE(SUBSTITUTE(_xlfn.TEXTBEFORE(A22,","), "-", ""), " ", "") -> Baron | H22: =_xlfn.LET( _xlpm.authors,_xlfn.TEXTBEFORE(A22," ("&I22&")"), _xlpm.hasAmp,ISNUMBER(SEARCH("&",_xlpm.authors)), _xlpm.commasBeforeAmp,IF(_xlpm.hasAmp,LEN(_xlfn.TEXTBEFORE(_xlpm.authors,"&"))-LEN(SUBSTITUTE(_xlfn.TEXTBEFORE(_xlpm.authors,"&"),",","")),0), IF(NOT(_xlpm.hasAmp),"",IF(_xlpm.commasBeforeAmp>2,"etal",TRIM(_xlfn.TEXTBEFORE(_xlfn.TEXTAFTER(_xlpm.authors,"& "),",")))) ) -> etal | I22: =_xlfn.TEXTBEFORE(_xlfn.TEXTAFTER(A22, "("), ")") -> 1987 | J22: =_xlfn.LET( _xlpm.doi,IF(C22<>"",C22,_xlfn.TEXTAFTER(A22,"https://doi.org/")), SUBSTITUTE( SUBSTITUTE( SUBSTITUTE( SUBSTITUTE( _xlpm.doi, "/","%2F"), ":","%3A"), "<","%3C"), ">","%3E") ) -> PMID%3A3116076 | K22: =TRIM(_xlfn.TEXTJOIN("_",FALSE(),F22,(SUBSTITUTE(SUBSTITUTE(D22," ",""), "_", "")))) -> Baron_etal_1987_Table1 | L22: =J22 & "_" & SUBSTITUTE(SUBSTITUTE(SUBSTITUTE(D22,CHAR(160),"")," ",""),"_","") -> PMID%3A3116076_Table1 | M22: {=IFERROR(INDEX(AUTO_Public_TSV_FileList!$A$1:$A$1000,MATCH(TRUE(),EXACT(L22,IFERROR(_xlfn.TEXTBEFORE(AUTO_Public_TSV_FileList!$A$1:$A$1000,".tsv"),"")),0)),"notfound")} -> PMID%3A3116076_Table1.tsv | P22: FINISHED | V22: table | W22: NO - not digitized | Y22: Stephan | Z22: Stephan | AF22: histological sections | AG22: Stephan | AI22: brain-structure volume (Comparison series, Part) | AJ22: Insectivora, Scandentia & Primates | AK22: primary | AL22: primary | AM22: volume
A23: Baron, G., Stephan, H., & Frahm, H. D. (1990). Comparison of brain structure volumes in Insectivora and primates. IX. Trigeminal complex. J Hirnforsch, 31(2), 193-200. https://www.ncbi.nlm.nih.gov/pubmed/2358663 | C23: PMID:2358663 | D23: Table 1 | E23: =RIGHT(A23,1) -> 3 | F23: =G23 & IF(H23<>"", "_" & H23, "_") & IF(I23<>"", "_" & I23, "_") & IF(B23<>"", "_" & B23, "") -> Baron_etal_1990 | G23: =SUBSTITUTE(SUBSTITUTE(_xlfn.TEXTBEFORE(A23,","), "-", ""), " ", "") -> Baron | H23: =_xlfn.LET( _xlpm.authors,_xlfn.TEXTBEFORE(A23," ("&I23&")"), _xlpm.hasAmp,ISNUMBER(SEARCH("&",_xlpm.authors)), _xlpm.commasBeforeAmp,IF(_xlpm.hasAmp,LEN(_xlfn.TEXTBEFORE(_xlpm.authors,"&"))-LEN(SUBSTITUTE(_xlfn.TEXTBEFORE(_xlpm.authors,"&"),",","")),0), IF(NOT(_xlpm.hasAmp),"",IF(_xlpm.commasBeforeAmp>2,"etal",TRIM(_xlfn.TEXTBEFORE(_xlfn.TEXTAFTER(_xlpm.authors,"& "),",")))) ) -> etal | I23: =_xlfn.TEXTBEFORE(_xlfn.TEXTAFTER(A23, "("), ")") -> 1990 | J23: =_xlfn.LET( _xlpm.doi,IF(C23<>"",C23,_xlfn.TEXTAFTER(A23,"https://doi.org/")), SUBSTITUTE( SUBSTITUTE( SUBSTITUTE( SUBSTITUTE( _xlpm.doi, "/","%2F"), ":","%3A"), "<","%3C"), ">","%3E") ) -> PMID%3A2358663 | K23: =TRIM(_xlfn.TEXTJOIN("_",FALSE(),F23,(SUBSTITUTE(SUBSTITUTE(D23," ",""), "_", "")))) -> Baron_etal_1990_Table1 | L23: =J23 & "_" & SUBSTITUTE(SUBSTITUTE(SUBSTITUTE(D23,CHAR(160),"")," ",""),"_","") -> PMID%3A2358663_Table1 | M23: {=IFERROR(INDEX(AUTO_Public_TSV_FileList!$A$1:$A$1000,MATCH(TRUE(),EXACT(L23,IFERROR(_xlfn.TEXTBEFORE(AUTO_Public_TSV_FileList!$A$1:$A$1000,".tsv"),"")),0)),"notfound")} -> PMID%3A2358663_Table1.tsv | N23: Table 1 .IX. Trigeminal complex | P23: FINISHED | V23: table | W23: NO - not digitized | Y23: Stephan | Z23: Stephan | AF23: histological sections | AG23: volumetry | AI23: trigeminal complex volume | AJ23: Insectivora, Scandentia & Primates | AK23: primary | AL23: primary | AM23: volume
A24: Baron, G., Stephan, H., & Frahm, H. D. (1996). Comparative Neurobiology in Chiroptera: Macromorphology, Brain Structures, Tables, and Atlases. Birkhaeuser. | C24: ISBN:9783764353704 | D24: Table 10 | E24: =RIGHT(A24,1) -> . | F24: =G24 & IF(H24<>"", "_" & H24, "_") & IF(I24<>"", "_" & I24, "_") & IF(B24<>"", "_" & B24, "") -> Baron_etal_1996 | G24: =SUBSTITUTE(SUBSTITUTE(_xlfn.TEXTBEFORE(A24,","), "-", ""), " ", "") -> Baron | H24: =_xlfn.LET( _xlpm.authors,_xlfn.TEXTBEFORE(A24," ("&I24&")"), _xlpm.hasAmp,ISNUMBER(SEARCH("&",_xlpm.authors)), _xlpm.commasBeforeAmp,IF(_xlpm.hasAmp,LEN(_xlfn.TEXTBEFORE(_xlpm.authors,"&"))-LEN(SUBSTITUTE(_xlfn.TEXTBEFORE(_xlpm.authors,"&"),",","")),0), IF(NOT(_xlpm.hasAmp),"",IF(_xlpm.commasBeforeAmp>2,"etal",TRIM(_xlfn.TEXTBEFORE(_xlfn.TEXTAFTER(_xlpm.authors,"& "),",")))) ) -> etal | I24: =_xlfn.TEXTBEFORE(_xlfn.TEXTAFTER(A24, "("), ")") -> 1996 | J24: =_xlfn.LET( _xlpm.doi,IF(C24<>"",C24,_xlfn.TEXTAFTER(A24,"https://doi.org/")), SUBSTITUTE( SUBSTITUTE( SUBSTITUTE( SUBSTITUTE( _xlpm.doi, "/","%2F"), ":","%3A"), "<","%3C"), ">","%3E") ) -> ISBN%3A9783764353704 | K24: =TRIM(_xlfn.TEXTJOIN("_",FALSE(),F24,(SUBSTITUTE(SUBSTITUTE(D24," ",""), "_", "")))) -> Baron_etal_1996_Table10 | L24: =J24 & "_" & SUBSTITUTE(SUBSTITUTE(SUBSTITUTE(D24,CHAR(160),"")," ",""),"_","") -> ISBN%3A9783764353704_Table10 | M24: {=IFERROR(INDEX(AUTO_Public_TSV_FileList!$A$1:$A$1000,MATCH(TRUE(),EXACT(L24,IFERROR(_xlfn.TEXTBEFORE(AUTO_Public_TSV_FileList!$A$1:$A$1000,".tsv"),"")),0)),"notfound")} -> ISBN%3A9783764353704_Table10.tsv | N24: Table 10. Volumes of five fundamental brain parts | O24: BUILT 2026-08-15: 272 species; five fundamental brain-part volumes. | P24: FINISHED | R24: Baron_etal_1996_Table10_snapshot.csv | S24: Source values preserved; seven blank n values retained as missing. | T24: Baron_etal_1996_Table10.csv | AL24: primary
A25: Baron, G., Stephan, H., & Frahm, H. D. (1996). Comparative Neurobiology in Chiroptera: Macromorphology, Brain Structures, Tables, and Atlases. Birkhaeuser. | C25: ISBN:9783764353704 | D25: Table 32 | E25: =RIGHT(A25,1) -> . | F25: =G25 & IF(H25<>"", "_" & H25, "_") & IF(I25<>"", "_" & I25, "_") & IF(B25<>"", "_" & B25, "") -> Baron_etal_1996 | G25: =SUBSTITUTE(SUBSTITUTE(_xlfn.TEXTBEFORE(A25,","), "-", ""), " ", "") -> Baron | H25: =_xlfn.LET( _xlpm.authors,_xlfn.TEXTBEFORE(A25," ("&I25&")"), _xlpm.hasAmp,ISNUMBER(SEARCH("&",_xlpm.authors)), _xlpm.commasBeforeAmp,IF(_xlpm.hasAmp,LEN(_xlfn.TEXTBEFORE(_xlpm.authors,"&"))-LEN(SUBSTITUTE(_xlfn.TEXTBEFORE(_xlpm.authors,"&"),",","")),0), IF(NOT(_xlpm.hasAmp),"",IF(_xlpm.commasBeforeAmp>2,"etal",TRIM(_xlfn.TEXTBEFORE(_xlfn.TEXTAFTER(_xlpm.authors,"& "),",")))) ) -> etal | I25: =_xlfn.TEXTBEFORE(_xlfn.TEXTAFTER(A25, "("), ")") -> 1996 | J25: =_xlfn.LET( _xlpm.doi,IF(C25<>"",C25,_xlfn.TEXTAFTER(A25,"https://doi.org/")), SUBSTITUTE( SUBSTITUTE( SUBSTITUTE( SUBSTITUTE( _xlpm.doi, "/","%2F"), ":","%3A"), "<","%3C"), ">","%3E") ) -> ISBN%3A9783764353704 | K25: =TRIM(_xlfn.TEXTJOIN("_",FALSE(),F25,(SUBSTITUTE(SUBSTITUTE(D25," ",""), "_", "")))) -> Baron_etal_1996_Table32 | L25: =J25 & "_" & SUBSTITUTE(SUBSTITUTE(SUBSTITUTE(D25,CHAR(160),"")," ",""),"_","") -> ISBN%3A9783764353704_Table32 | M25: {=IFERROR(INDEX(AUTO_Public_TSV_FileList!$A$1:$A$1000,MATCH(TRUE(),EXACT(L25,IFERROR(_xlfn.TEXTBEFORE(AUTO_Public_TSV_FileList!$A$1:$A$1000,".tsv"),"")),0)),"notfound")} -> ISBN%3A9783764353704_Table32.tsv | N25: Table 32. Volumes of telencephalic components | O25: BUILT 2026-08-15: 272 species; telencephalic component volumes. Two source-level component-sum conflicts are retained and reported. | P25: FINISHED | R25: Baron_etal_1996_Table32_snapshot.csv | S25: Source values preserved; two Table 32 versus Table 10 component-sum conflicts flagged, not corrected. | T25: Baron_etal_1996_Table32.csv | AL25: primary
A26: Bauernfeind, A. L., de Sousa, A. A., Avasthi, T., Dobson, S. D., Raghanti, M. A., Lewandowski, A. H., Zilles, K., Semendeferi, K., Allman, J. M., Craig, A. D., Hof, P. R., & Sherwood, C. C. (2013). A volumetric comparison of the insular cortex and its subregions in primates. J Hum Evol, 64(4), 263-279. https://doi.org/10.1016/j.jhevol.2012.12.003 | D26: Table 1 | E26: =RIGHT(A26,1) -> 3 | F26: =G26 & IF(H26<>"", "_" & H26, "_") & IF(I26<>"", "_" & I26, "_") & IF(B26<>"", "_" & B26, "") -> Bauernfeind_etal_2013 | G26: =SUBSTITUTE(SUBSTITUTE(_xlfn.TEXTBEFORE(A26,","), "-", ""), " ", "") -> Bauernfeind | H26: =_xlfn.LET( _xlpm.authors,_xlfn.TEXTBEFORE(A26," ("&I26&")"), _xlpm.hasAmp,ISNUMBER(SEARCH("&",_xlpm.authors)), _xlpm.commasBeforeAmp,IF(_xlpm.hasAmp,LEN(_xlfn.TEXTBEFORE(_xlpm.authors,"&"))-LEN(SUBSTITUTE(_xlfn.TEXTBEFORE(_xlpm.authors,"&"),",","")),0), IF(NOT(_xlpm.hasAmp),"",IF(_xlpm.commasBeforeAmp>2,"etal",TRIM(_xlfn.TEXTBEFORE(_xlfn.TEXTAFTER(_xlpm.authors,"& "),",")))) ) -> etal | I26: =_xlfn.TEXTBEFORE(_xlfn.TEXTAFTER(A26, "("), ")") -> 2013 | J26: =_xlfn.LET( _xlpm.doi,IF(C26<>"",C26,_xlfn.TEXTAFTER(A26,"https://doi.org/")), SUBSTITUTE( SUBSTITUTE( SUBSTITUTE( SUBSTITUTE( _xlpm.doi, "/","%2F"), ":","%3A"), "<","%3C"), ">","%3E") ) -> 10.1016%2Fj.jhevol.2012.12.003 | K26: =TRIM(_xlfn.TEXTJOIN("_",FALSE(),F26,(SUBSTITUTE(SUBSTITUTE(D26," ",""), "_", "")))) -> Bauernfeind_etal_2013_Table1 | L26: =J26 & "_" & SUBSTITUTE(SUBSTITUTE(SUBSTITUTE(D26,CHAR(160),"")," ",""),"_","") -> 10.1016%2Fj.jhevol.2012.12.003_Table1 | M26: {=IFERROR(INDEX(AUTO_Public_TSV_FileList!$A$1:$A$1000,MATCH(TRUE(),EXACT(L26,IFERROR(_xlfn.TEXTBEFORE(AUTO_Public_TSV_FileList!$A$1:$A$1000,".tsv"),"")),0)),"notfound")} -> 10.1016%2Fj.jhevol.2012.12.003_Table1.tsv | N26: Volumetric comparison of the insular cortex (Table 1) | P26: FINISHED | V26: table | Y26: Stephan, Sherwood | AF26: histological sections | AG26: volumetry | AI26: insular cortex volumes | AJ26: Primates | AK26: primary | AL26: primary | AM26: volume
A27: Bauernfeind, A. L., de Sousa, A. A., Avasthi, T., Dobson, S. D., Raghanti, M. A., Lewandowski, A. H., Zilles, K., Semendeferi, K., Allman, J. M., Craig, A. D., Hof, P. R., & Sherwood, C. C. (2013). A volumetric comparison of the insular cortex and its subregions in primates. J Hum Evol, 64(4), 263-279. https://doi.org/10.1016/j.jhevol.2012.12.003 | D27: Table 2 | E27: =RIGHT(A27,1) -> 3 | F27: =G27 & IF(H27<>"", "_" & H27, "_") & IF(I27<>"", "_" & I27, "_") & IF(B27<>"", "_" & B27, "") -> Bauernfeind_etal_2013 | G27: =SUBSTITUTE(SUBSTITUTE(_xlfn.TEXTBEFORE(A27,","), "-", ""), " ", "") -> Bauernfeind | H27: =_xlfn.LET( _xlpm.authors,_xlfn.TEXTBEFORE(A27," ("&I27&")"), _xlpm.hasAmp,ISNUMBER(SEARCH("&",_xlpm.authors)), _xlpm.commasBeforeAmp,IF(_xlpm.hasAmp,LEN(_xlfn.TEXTBEFORE(_xlpm.authors,"&"))-LEN(SUBSTITUTE(_xlfn.TEXTBEFORE(_xlpm.authors,"&"),",","")),0), IF(NOT(_xlpm.hasAmp),"",IF(_xlpm.commasBeforeAmp>2,"etal",TRIM(_xlfn.TEXTBEFORE(_xlfn.TEXTAFTER(_xlpm.authors,"& "),",")))) ) -> etal | I27: =_xlfn.TEXTBEFORE(_xlfn.TEXTAFTER(A27, "("), ")") -> 2013 | J27: =_xlfn.LET( _xlpm.doi,IF(C27<>"",C27,_xlfn.TEXTAFTER(A27,"https://doi.org/")), SUBSTITUTE( SUBSTITUTE( SUBSTITUTE( SUBSTITUTE( _xlpm.doi, "/","%2F"), ":","%3A"), "<","%3C"), ">","%3E") ) -> 10.1016%2Fj.jhevol.2012.12.003 | K27: =TRIM(_xlfn.TEXTJOIN("_",FALSE(),F27,(SUBSTITUTE(SUBSTITUTE(D27," ",""), "_", "")))) -> Bauernfeind_etal_2013_Table2 | L27: =J27 & "_" & SUBSTITUTE(SUBSTITUTE(SUBSTITUTE(D27,CHAR(160),"")," ",""),"_","") -> 10.1016%2Fj.jhevol.2012.12.003_Table2 | M27: {=IFERROR(INDEX(AUTO_Public_TSV_FileList!$A$1:$A$1000,MATCH(TRUE(),EXACT(L27,IFERROR(_xlfn.TEXTBEFORE(AUTO_Public_TSV_FileList!$A$1:$A$1000,".tsv"),"")),0)),"notfound")} -> 10.1016%2Fj.jhevol.2012.12.003_Table2.tsv | P27: FINISHED | V27: table | Y27: Stephan, Sherwood | AF27: histological sections | AG27: volumetry | AI27: insular cortex volumes | AJ27: Primates | AK27: primary | AL27: primary | AM27: volume
A28: Bauernfeind, A. L., de Sousa, A. A., Avasthi, T., Dobson, S. D., Raghanti, M. A., Lewandowski, A. H., Zilles, K., Semendeferi, K., Allman, J. M., Craig, A. D., Hof, P. R., & Sherwood, C. C. (2013). A volumetric comparison of the insular cortex and its subregions in primates. J Hum Evol, 64(4), 263-279. https://doi.org/10.1016/j.jhevol.2012.12.003 | D28: Table 3 | E28: =RIGHT(A28,1) -> 3 | F28: =G28 & IF(H28<>"", "_" & H28, "_") & IF(I28<>"", "_" & I28, "_") & IF(B28<>"", "_" & B28, "") -> Bauernfeind_etal_2013 | G28: =SUBSTITUTE(SUBSTITUTE(_xlfn.TEXTBEFORE(A28,","), "-", ""), " ", "") -> Bauernfeind | H28: =_xlfn.LET( _xlpm.authors,_xlfn.TEXTBEFORE(A28," ("&I28&")"), _xlpm.hasAmp,ISNUMBER(SEARCH("&",_xlpm.authors)), _xlpm.commasBeforeAmp,IF(_xlpm.hasAmp,LEN(_xlfn.TEXTBEFORE(_xlpm.authors,"&"))-LEN(SUBSTITUTE(_xlfn.TEXTBEFORE(_xlpm.authors,"&"),",","")),0), IF(NOT(_xlpm.hasAmp),"",IF(_xlpm.commasBeforeAmp>2,"etal",TRIM(_xlfn.TEXTBEFORE(_xlfn.TEXTAFTER(_xlpm.authors,"& "),",")))) ) -> etal | I28: =_xlfn.TEXTBEFORE(_xlfn.TEXTAFTER(A28, "("), ")") -> 2013 | J28: =_xlfn.LET( _xlpm.doi,IF(C28<>"",C28,_xlfn.TEXTAFTER(A28,"https://doi.org/")), SUBSTITUTE( SUBSTITUTE( SUBSTITUTE( SUBSTITUTE( _xlpm.doi, "/","%2F"), ":","%3A"), "<","%3C"), ">","%3E") ) -> 10.1016%2Fj.jhevol.2012.12.003 | K28: =TRIM(_xlfn.TEXTJOIN("_",FALSE(),F28,(SUBSTITUTE(SUBSTITUTE(D28," ",""), "_", "")))) -> Bauernfeind_etal_2013_Table3 | L28: =J28 & "_" & SUBSTITUTE(SUBSTITUTE(SUBSTITUTE(D28,CHAR(160),"")," ",""),"_","") -> 10.1016%2Fj.jhevol.2012.12.003_Table3 | M28: {=IFERROR(INDEX(AUTO_Public_TSV_FileList!$A$1:$A$1000,MATCH(TRUE(),EXACT(L28,IFERROR(_xlfn.TEXTBEFORE(AUTO_Public_TSV_FileList!$A$1:$A$1000,".tsv"),"")),0)),"notfound")} -> 10.1016%2Fj.jhevol.2012.12.003_Table3.tsv | V28: table | Y28: Stephan, Sherwood | AF28: histological sections | AG28: volumetry | AI28: insular cortex volumes | AJ28: Primates | AK28: primary | AL28: primary | AM28: volume
A29: Bortoff, G. A., & Strick, P. L. (1993). Corticospinal terminations in two New-World primates: Further evidence that corticomotoneuronal connections provide part of the neural substrate for manual dexterity. The Journal of Neuroscience, 13(12), 5105–5118. https://doi.org/10.1523/JNEUROSCI.13-12-05105.1993 | D29: Table 1 | E29: =RIGHT(A29,1) -> 3 | F29: =G29 & IF(H29<>"", "_" & H29, "_") & IF(I29<>"", "_" & I29, "_") & IF(B29<>"", "_" & B29, "") -> Bortoff_Strick_1993 | G29: =SUBSTITUTE(SUBSTITUTE(_xlfn.TEXTBEFORE(A29,","), "-", ""), " ", "") -> Bortoff | H29: =_xlfn.LET( _xlpm.authors,_xlfn.TEXTBEFORE(A29," ("&I29&")"), _xlpm.hasAmp,ISNUMBER(SEARCH("&",_xlpm.authors)), _xlpm.commasBeforeAmp,IF(_xlpm.hasAmp,LEN(_xlfn.TEXTBEFORE(_xlpm.authors,"&"))-LEN(SUBSTITUTE(_xlfn.TEXTBEFORE(_xlpm.authors,"&"),",","")),0), IF(NOT(_xlpm.hasAmp),"",IF(_xlpm.commasBeforeAmp>2,"etal",TRIM(_xlfn.TEXTBEFORE(_xlfn.TEXTAFTER(_xlpm.authors,"& "),",")))) ) -> Strick | I29: =_xlfn.TEXTBEFORE(_xlfn.TEXTAFTER(A29, "("), ")") -> 1993 | J29: =_xlfn.LET( _xlpm.doi,IF(C29<>"",C29,_xlfn.TEXTAFTER(A29,"https://doi.org/")), SUBSTITUTE( SUBSTITUTE( SUBSTITUTE( SUBSTITUTE( _xlpm.doi, "/","%2F"), ":","%3A"), "<","%3C"), ">","%3E") ) -> 10.1523%2FJNEUROSCI.13-12-05105.1993 | K29: =TRIM(_xlfn.TEXTJOIN("_",FALSE(),F29,(SUBSTITUTE(SUBSTITUTE(D29," ",""), "_", "")))) -> Bortoff_Strick_1993_Table1 | L29: =J29 & "_" & SUBSTITUTE(SUBSTITUTE(SUBSTITUTE(D29,CHAR(160),"")," ",""),"_","") -> 10.1523%2FJNEUROSCI.13-12-05105.1993_Table1 | M29: {=IFERROR(INDEX(AUTO_Public_TSV_FileList!$A$1:$A$1000,MATCH(TRUE(),EXACT(L29,IFERROR(_xlfn.TEXTBEFORE(AUTO_Public_TSV_FileList!$A$1:$A$1000,".tsv"),"")),0)),"notfound")} -> 10.1523%2FJNEUROSCI.13-12-05105.1993_Table1.tsv | N29: Curated Table 1. Species-specific corticospinal termination extent and CM-connection inference | O29: Conservative curatorial compilation from Bortoff & Strick (1993) primary tract-tracing evidence. | P29: FINISHED | Q29: Europe PMC | R29: Bortoff_Strick_1993_Table1_snapshot.xlsx | S29: Y | T29: Bortoff_Strick_1993_Table1.csv | U29: pdf + curated snapshot | V29: table | W29: https://europepmc.org/articles/PMC6575756?pdf=render | X29: https://doi.org/10.1523/JNEUROSCI.13-12-05105.1993 | Y29: Bortoff/Strick | AA29: CST ventral-horn / lamina IX termination extent; CM-connection inference | AB29: Two New-World primate species. Grade 0–2 is coded only from explicit species-level terminal-field evidence. CM_monosynaptic remains blank because light microscopy cannot establish direct monosynaptic presence or absence; likely/against is retained separately as inference. Data role = PRIMARY: the WGA-HRP result is Bortoff & Strick’s own, only the 0–2 grading is curatorial (see reference_tables/..._definitions.csv, Method:coding). Keyed on the article DOI — the earlier COMPILATION:Corticospinal_terminations override was removed 2026-08-15; a second CST paper gets its own folder and is pooled in __merging_behaviour, not appended to this table. | AF29: two New-World primate species | AG29: WGA-HRP anterograde tract tracing from primary motor cortex | AH29: spinal cord / M1 output | AI29: corticospinal termination extent and corticomotoneuronal inference | AJ29: Primates | AK29: primary (own WGA-HRP tract tracing); ordinal grade is curated | AL29: primary | AM29: ordinal anatomical grade + qualitative inference
A30: Boyer, D. M., & Harrington, A. R. (2018). Scaling of bony canals for encephalic vessels in euarchontans: Implications for the role of the vertebral artery and brain metabolism. J Hum Evol, 114, 85-101. https://doi.org/10.1016/j.jhevol.2017.09.003 | D30: Table 1 | E30: =RIGHT(A30,1) -> 3 | F30: =G30 & IF(H30<>"", "_" & H30, "_") & IF(I30<>"", "_" & I30, "_") & IF(B30<>"", "_" & B30, "") -> Boyer_Harrington_2018 | G30: =SUBSTITUTE(SUBSTITUTE(_xlfn.TEXTBEFORE(A30,","), "-", ""), " ", "") -> Boyer | H30: =_xlfn.LET( _xlpm.authors,_xlfn.TEXTBEFORE(A30," ("&I30&")"), _xlpm.hasAmp,ISNUMBER(SEARCH("&",_xlpm.authors)), _xlpm.commasBeforeAmp,IF(_xlpm.hasAmp,LEN(_xlfn.TEXTBEFORE(_xlpm.authors,"&"))-LEN(SUBSTITUTE(_xlfn.TEXTBEFORE(_xlpm.authors,"&"),",","")),0), IF(NOT(_xlpm.hasAmp),"",IF(_xlpm.commasBeforeAmp>2,"etal",TRIM(_xlfn.TEXTBEFORE(_xlfn.TEXTAFTER(_xlpm.authors,"& "),",")))) ) -> Harrington | I30: =_xlfn.TEXTBEFORE(_xlfn.TEXTAFTER(A30, "("), ")") -> 2018 | J30: =_xlfn.LET( _xlpm.doi,IF(C30<>"",C30,_xlfn.TEXTAFTER(A30,"https://doi.org/")), SUBSTITUTE( SUBSTITUTE( SUBSTITUTE( SUBSTITUTE( _xlpm.doi, "/","%2F"), ":","%3A"), "<","%3C"), ">","%3E") ) -> 10.1016%2Fj.jhevol.2017.09.003 | K30: =TRIM(_xlfn.TEXTJOIN("_",FALSE(),F30,(SUBSTITUTE(SUBSTITUTE(D30," ",""), "_", "")))) -> Boyer_Harrington_2018_Table1 | L30: =J30 & "_" & SUBSTITUTE(SUBSTITUTE(SUBSTITUTE(D30,CHAR(160),"")," ",""),"_","") -> 10.1016%2Fj.jhevol.2017.09.003_Table1 | M30: {=IFERROR(INDEX(AUTO_Public_TSV_FileList!$A$1:$A$1000,MATCH(TRUE(),EXACT(L30,IFERROR(_xlfn.TEXTBEFORE(AUTO_Public_TSV_FileList!$A$1:$A$1000,".tsv"),"")),0)),"notfound")} -> 10.1016%2Fj.jhevol.2017.09.003_Table1.tsv | N30: Table 1 Taxon list and species mean values.
A31: Boyer, D. M., & Harrington, A. R. (2019). New estimates of blood flow rates in the vertebral artery of euarchontans and their implications for encephalic blood flow scaling: A response to Seymour and Snelling (2018). J Hum Evol, 128, 93-98. https://doi.org/10.1016/j.jhevol.2018.10.002 | D31: SOM Table S6 | E31: =RIGHT(A31,1) -> 2 | F31: =G31 & IF(H31<>"", "_" & H31, "_") & IF(I31<>"", "_" & I31, "_") & IF(B31<>"", "_" & B31, "") -> Boyer_Harrington_2019 | G31: =SUBSTITUTE(SUBSTITUTE(_xlfn.TEXTBEFORE(A31,","), "-", ""), " ", "") -> Boyer | H31: =_xlfn.LET( _xlpm.authors,_xlfn.TEXTBEFORE(A31," ("&I31&")"), _xlpm.hasAmp,ISNUMBER(SEARCH("&",_xlpm.authors)), _xlpm.commasBeforeAmp,IF(_xlpm.hasAmp,LEN(_xlfn.TEXTBEFORE(_xlpm.authors,"&"))-LEN(SUBSTITUTE(_xlfn.TEXTBEFORE(_xlpm.authors,"&"),",","")),0), IF(NOT(_xlpm.hasAmp),"",IF(_xlpm.commasBeforeAmp>2,"etal",TRIM(_xlfn.TEXTBEFORE(_xlfn.TEXTAFTER(_xlpm.authors,"& "),",")))) ) -> Harrington | I31: =_xlfn.TEXTBEFORE(_xlfn.TEXTAFTER(A31, "("), ")") -> 2019 | J31: =_xlfn.LET( _xlpm.doi,IF(C31<>"",C31,_xlfn.TEXTAFTER(A31,"https://doi.org/")), SUBSTITUTE( SUBSTITUTE( SUBSTITUTE( SUBSTITUTE( _xlpm.doi, "/","%2F"), ":","%3A"), "<","%3C"), ">","%3E") ) -> 10.1016%2Fj.jhevol.2018.10.002 | K31: =TRIM(_xlfn.TEXTJOIN("_",FALSE(),F31,(SUBSTITUTE(SUBSTITUTE(D31," ",""), "_", "")))) -> Boyer_Harrington_2019_SOMTableS6 | L31: =J31 & "_" & SUBSTITUTE(SUBSTITUTE(SUBSTITUTE(D31,CHAR(160),"")," ",""),"_","") -> 10.1016%2Fj.jhevol.2018.10.002_SOMTableS6 | M31: {=IFERROR(INDEX(AUTO_Public_TSV_FileList!$A$1:$A$1000,MATCH(TRUE(),EXACT(L31,IFERROR(_xlfn.TEXTBEFORE(AUTO_Public_TSV_FileList!$A$1:$A$1000,".tsv"),"")),0)),"notfound")} -> 10.1016%2Fj.jhevol.2018.10.002_SOMTableS6.tsv
A32: Brodmann, K. (1913). Neue Ergebnisse über die vergleichende histologische Lokalisation der Grosshirnrinde mit besonderer Berücksichtigung des Stirnhirns. Verhandlungen der Anatomischen Gesellschaft, 41, 157-216. | C32: OCLC:8777719 | D32: Table 1 | E32: =RIGHT(A32,1) -> . | F32: =G32 & IF(H32<>"", "_" & H32, "_") & IF(I32<>"", "_" & I32, "_") & IF(B32<>"", "_" & B32, "") -> Brodmann__1913 | G32: =SUBSTITUTE(SUBSTITUTE(_xlfn.TEXTBEFORE(A32,","), "-", ""), " ", "") -> Brodmann | H32: =_xlfn.LET( _xlpm.authors,_xlfn.TEXTBEFORE(A32," ("&I32&")"), _xlpm.hasAmp,ISNUMBER(SEARCH("&",_xlpm.authors)), _xlpm.commasBeforeAmp,IF(_xlpm.hasAmp,LEN(_xlfn.TEXTBEFORE(_xlpm.authors,"&"))-LEN(SUBSTITUTE(_xlfn.TEXTBEFORE(_xlpm.authors,"&"),",","")),0), IF(NOT(_xlpm.hasAmp),"",IF(_xlpm.commasBeforeAmp>2,"etal",TRIM(_xlfn.TEXTBEFORE(_xlfn.TEXTAFTER(_xlpm.authors,"& "),",")))) ) | I32: =_xlfn.TEXTBEFORE(_xlfn.TEXTAFTER(A32, "("), ")") -> 1913 | J32: =_xlfn.LET( _xlpm.doi,IF(C32<>"",C32,_xlfn.TEXTAFTER(A32,"https://doi.org/")), SUBSTITUTE( SUBSTITUTE( SUBSTITUTE( SUBSTITUTE( _xlpm.doi, "/","%2F"), ":","%3A"), "<","%3C"), ">","%3E") ) -> OCLC%3A8777719 | K32: =TRIM(_xlfn.TEXTJOIN("_",FALSE(),F32,(SUBSTITUTE(SUBSTITUTE(D32," ",""), "_", "")))) -> Brodmann__1913_Table1 | L32: =J32 & "_" & SUBSTITUTE(SUBSTITUTE(SUBSTITUTE(D32,CHAR(160),"")," ",""),"_","") -> OCLC%3A8777719_Table1 | M32: {=IFERROR(INDEX(AUTO_Public_TSV_FileList!$A$1:$A$1000,MATCH(TRUE(),EXACT(L32,IFERROR(_xlfn.TEXTBEFORE(AUTO_Public_TSV_FileList!$A$1:$A$1000,".tsv"),"")),0)),"notfound")} -> OCLC%3A8777719_Table1.tsv | N32: Tabelle 1. Gesamtrindenfläche, Furchenrinde und Hirngewicht bei verschiedenen Säugetieren | P32: FINISHED | AI32: total cortical surface area; sulcal cortex; brain weight | AJ32: Mammalia (all orders) | AK32: primary | AL32: primary | AM32: surface area (mm2) + mass (g)
