Workbook

Sheet Sheet1
A1: Citation (APA 7th-Annotated) | B1: sequence | C1: DOI if different from article or doi Alt | D1: Item number | E1: end | F1: Publication name | G1: 1st Author | H1: other author(s) | I1: year | J1: DOI (or Alt) | K1: Item name | L1: Item encoded | M1: Public TSV match from AUTO_Public_TSV_FileList (generated by _tools/file_list.R; do not edit manually) | N1: Item full original title | O1: Note about item | P1: Progress stage | Q1: Online Database | R1: Snapshot | S1: Adjustment made | T1: Source Type | U1: Source format | V1: Source URL direct access | W1: Source URL link | X1: Team | Y1: Collection | Z1: Possible Traits | AA1: Note | AB1: Flags pre-addressed | AC1: Flags possible | AD1: Flags active (skips) | AE1: Sample type | AF1: Method | AG1: Subcategory | AH1: Main Trait(s) | AI1: Taxon group | AJ1: Source type | AK1: Data role (primary/secondary/both) | AL1: Measure type | AM1: relevance | AN1: recommendation
A2: Andelin, A. K., Olavarria, J. F., Fine, I., Taber, E. N., Schwartz, D., Kroenke, C. D., & Stevens, A. A. (2019). The Effect of Onset Age of Visual Deprivation on Visual Cortex Surface Area Across-Species. Cereb Cortex, 29(10), 4321-4333. https://doi.org/10.1093/cercor/bhy315 | D2: Table 4 | E2: =RIGHT(A2,1) -> 5 | F2: =G2 & IF(H2<>"", "_" & H2, "_") & IF(I2<>"", "_" & I2, "_") & IF(B2<>"", "_" & B2, "") -> Andelin_etal_2019 | G2: =SUBSTITUTE(SUBSTITUTE(_xlfn.TEXTBEFORE(A2,","), "-", ""), " ", "") -> Andelin | H2: =_xlfn.LET( _xlpm.authors,_xlfn.TEXTBEFORE(A2," ("&I2&")"), _xlpm.hasAmp,ISNUMBER(SEARCH("&",_xlpm.authors)), _xlpm.commasBeforeAmp,IF(_xlpm.hasAmp,LEN(_xlfn.TEXTBEFORE(_xlpm.authors,"&"))-LEN(SUBSTITUTE(_xlfn.TEXTBEFORE(_xlpm.authors,"&"),",","")),0), IF(NOT(_xlpm.hasAmp),"",IF(_xlpm.commasBeforeAmp>2,"etal",TRIM(_xlfn.TEXTBEFORE(_xlfn.TEXTAFTER(_xlpm.authors,"& "),",")))) ) -> etal | I2: =_xlfn.TEXTBEFORE(_xlfn.TEXTAFTER(A2, "("), ")") -> 2019 | J2: =_xlfn.LET( _xlpm.doi,IF(C2<>"",C2,_xlfn.TEXTAFTER(A2,"https://doi.org/")), SUBSTITUTE( SUBSTITUTE( SUBSTITUTE( SUBSTITUTE( _xlpm.doi, "/","%2F"), ":","%3A"), "<","%3C"), ">","%3E") ) -> 10.1093%2Fcercor%2Fbhy315 | K2: =TRIM(_xlfn.TEXTJOIN("_",FALSE(),F2,(SUBSTITUTE(SUBSTITUTE(D2," ",""), "_", "")))) -> Andelin_etal_2019_Table4 | L2: =J2 & "_" & SUBSTITUTE(SUBSTITUTE(SUBSTITUTE(D2,CHAR(160),"")," ",""),"_","") -> 10.1093%2Fcercor%2Fbhy315_Table4 | M2: {=IFERROR(INDEX(AUTO_Public_TSV_FileList!$A$1:$A$1000,MATCH(TRUE(),EXACT(L2,IFERROR(_xlfn.TEXTBEFORE(AUTO_Public_TSV_FileList!$A$1:$A$1000,".tsv"),"")),0)),"notfound")} -> 10.1093%2Fcercor%2Fbhy315_Table4.tsv | P2: FINISHED | U2: table | AI2: review | AK2: review | AL2: review
A3: Armstrong, E. (1979). Quantitative comparison of the hominoid thalamus. I. Specific sensory relay nuclei. Am J Phys Anthropol, 51(3), 365-382. https://doi.org/10.1002/ajpa.1330510308 | D3: Tables 1-9 | E3: =RIGHT(A3,1) -> 8 | F3: =G3 & IF(H3<>"", "_" & H3, "_") & IF(I3<>"", "_" & I3, "_") & IF(B3<>"", "_" & B3, "") -> Armstrong__1979 | G3: =SUBSTITUTE(SUBSTITUTE(_xlfn.TEXTBEFORE(A3,","), "-", ""), " ", "") -> Armstrong | H3: =_xlfn.LET(_xlpm.authors,_xlfn.TEXTBEFORE(A3," ("&I3&")"),_xlpm.hasAmp,ISNUMBER(SEARCH("&",_xlpm.authors)),_xlpm.commasBeforeAmp,IF(_xlpm.hasAmp,LEN(_xlfn.TEXTBEFORE(_xlpm.authors,"&"))-LEN(SUBSTITUTE(_xlfn.TEXTBEFORE(_xlpm.authors,"&"),",","")),0),IF(NOT(_xlpm.hasAmp),"",IF(_xlpm.commasBeforeAmp>2,"etal",TRIM(_xlfn.TEXTBEFORE(_xlfn.TEXTAFTER(_xlpm.authors,"& "),","))))) | I3: =_xlfn.TEXTBEFORE(_xlfn.TEXTAFTER(A3, "("), ")") -> 1979 | J3: =_xlfn.LET(_xlpm.doi,IF(C3<>"",C3,_xlfn.TEXTAFTER(A3,"https://doi.org/")),SUBSTITUTE(SUBSTITUTE(SUBSTITUTE(SUBSTITUTE(_xlpm.doi,"/","%2F"),":","%3A"),"<","%3C"),">","%3E")) -> 10.1002%2Fajpa.1330510308 | K3: =TRIM(_xlfn.TEXTJOIN("_",FALSE(),F3,(SUBSTITUTE(SUBSTITUTE(D3," ",""), "_", "")))) -> Armstrong__1979_Tables1-9 | L3: =J3 & "_" & SUBSTITUTE(SUBSTITUTE(SUBSTITUTE(D3,CHAR(160),"")," ",""),"_","") -> 10.1002%2Fajpa.1330510308_Tables1-9 | M3: =IFERROR(INDEX(AUTO_Public_TSV_FileList!$A$1:$A$1000,MATCH(TRUE(),EXACT(L3,IFERROR(_xlfn.TEXTBEFORE(AUTO_Public_TSV_FileList!$A$1:$A$1000,".tsv"),"")),0)),"notfound") -> notfound | N3: Tables 1-9. Hominoid thalamic sensory-relay nucleus volumes, neuronal densities and numbers, and neuronal-volume distributions | O3: Primary mixed-datatype series. Table 1 provides LGB, MGBp and VB volumes plus percent of dorsal thalamus; Tables 2-4 density; Table 5 LGB subcomponent volumes; Table 6 neuron counts; Tables 7-9 neuronal perikaryal-volume distributions. Split during build. | P3: FINISHED | Q3: EndNote | T3: pdf | U3: tables | V3: https://doi.org/10.1002/ajpa.1330510308 | W3: https://doi.org/10.1002/ajpa.1330510308 | X3: Armstrong | Z3: LGB/LGBd; MGB parvocellular; ventrobasal complex; dorsal thalamus proportion; neuronal density; neuron number; neuronal perikaryal volume | AA3: Seven hominoid specimens in Table 1; later tables use subsets. Keep specimen-level records and separate regional volume, cell density/count, and cell-size outputs. | AC3: mixed datatypes; specimen abbreviations require a specimen crosswalk; some literature-comparison rows are secondary | AE3: individual hominoid specimens (gibbons, gorilla, chimpanzee, humans) | AF3: histological volumetry; neuronal density/count estimation; neuronal perikaryal morphometry | AG3: thalamic sensory relay nuclei | AH3: regional volumes; neuronal density and number; neuronal size | AI3: Hominoids | AJ3: primary + cited secondary comparisons | AK3: both | AL3: volume + cell density/count + neuronal perikaryal volume
A4: Ashwell, K. W. S. (2020). Quantitative analysis of cerebellar morphology in monotreme, metatherian and eutherian mammals. Zoology (Jena), 139, 125753. https://doi.org/10.1016/j.zool.2020.125753 | D4: Supplementary Table | E4: =RIGHT(A4,1) -> 3 | F4: =G4 & IF(H4<>"", "_" & H4, "_") & IF(I4<>"", "_" & I4, "_") & IF(B4<>"", "_" & B4, "") -> Ashwell__2020 | G4: =SUBSTITUTE(SUBSTITUTE(_xlfn.TEXTBEFORE(A4,","), "-", ""), " ", "") -> Ashwell | H4: =_xlfn.LET( _xlpm.authors,_xlfn.TEXTBEFORE(A4," ("&I4&")"), _xlpm.hasAmp,ISNUMBER(SEARCH("&",_xlpm.authors)), _xlpm.commasBeforeAmp,IF(_xlpm.hasAmp,LEN(_xlfn.TEXTBEFORE(_xlpm.authors,"&"))-LEN(SUBSTITUTE(_xlfn.TEXTBEFORE(_xlpm.authors,"&"),",","")),0), IF(NOT(_xlpm.hasAmp),"",IF(_xlpm.commasBeforeAmp>2,"etal",TRIM(_xlfn.TEXTBEFORE(_xlfn.TEXTAFTER(_xlpm.authors,"& "),",")))) ) | I4: =_xlfn.TEXTBEFORE(_xlfn.TEXTAFTER(A4, "("), ")") -> 2020 | J4: =_xlfn.LET( _xlpm.doi,IF(C4<>"",C4,_xlfn.TEXTAFTER(A4,"https://doi.org/")), SUBSTITUTE( SUBSTITUTE( SUBSTITUTE( SUBSTITUTE( _xlpm.doi, "/","%2F"), ":","%3A"), "<","%3C"), ">","%3E") ) -> 10.1016%2Fj.zool.2020.125753 | K4: =TRIM(_xlfn.TEXTJOIN("_",FALSE(),F4,(SUBSTITUTE(SUBSTITUTE(D4," ",""), "_", "")))) -> Ashwell__2020_SupplementaryTable | L4: =J4 & "_" & SUBSTITUTE(SUBSTITUTE(SUBSTITUTE(D4,CHAR(160),"")," ",""),"_","") -> 10.1016%2Fj.zool.2020.125753_SupplementaryTable | M4: {=IFERROR(INDEX(AUTO_Public_TSV_FileList!$A$1:$A$1000,MATCH(TRUE(),EXACT(L4,IFERROR(_xlfn.TEXTBEFORE(AUTO_Public_TSV_FileList!$A$1:$A$1000,".tsv"),"")),0)),"notfound")} -> 10.1016%2Fj.zool.2020.125753_SupplementaryTable.tsv | N4: Supplementary Table. Cerebellar Morphology Data | P4: FINISHED | X4: Ashwell
A5: Avelino-de-Souza, K., Patzke, N., Karlsson, K. A. E., Manger, P. R., & Herculano-Houzel, S. (2025). Cellular Composition of the Brain of a Northern Minke Whale. J Comp Neurol, 533(9), e70089. https://doi.org/10.1002/cne.70089 | D5: TABLE 1 | E5: =RIGHT(A5,1) -> 9 | F5: =G5 & IF(H5<>"", "_" & H5, "_") & IF(I5<>"", "_" & I5, "_") & IF(B5<>"", "_" & B5, "") -> AvelinodeSouza_etal_2025 | G5: =SUBSTITUTE(SUBSTITUTE(_xlfn.TEXTBEFORE(A5,","), "-", ""), " ", "") -> AvelinodeSouza | H5: =_xlfn.LET( _xlpm.authors,_xlfn.TEXTBEFORE(A5," ("&I5&")"), _xlpm.hasAmp,ISNUMBER(SEARCH("&",_xlpm.authors)), _xlpm.commasBeforeAmp,IF(_xlpm.hasAmp,LEN(_xlfn.TEXTBEFORE(_xlpm.authors,"&"))-LEN(SUBSTITUTE(_xlfn.TEXTBEFORE(_xlpm.authors,"&"),",","")),0), IF(NOT(_xlpm.hasAmp),"",IF(_xlpm.commasBeforeAmp>2,"etal",TRIM(_xlfn.TEXTBEFORE(_xlfn.TEXTAFTER(_xlpm.authors,"& "),",")))) ) -> etal | I5: =_xlfn.TEXTBEFORE(_xlfn.TEXTAFTER(A5, "("), ")") -> 2025 | J5: =_xlfn.LET( _xlpm.doi,IF(C5<>"",C5,_xlfn.TEXTAFTER(A5,"https://doi.org/")), SUBSTITUTE( SUBSTITUTE( SUBSTITUTE( SUBSTITUTE( _xlpm.doi, "/","%2F"), ":","%3A"), "<","%3C"), ">","%3E") ) -> 10.1002%2Fcne.70089 | K5: =TRIM(_xlfn.TEXTJOIN("_",FALSE(),F5,(SUBSTITUTE(SUBSTITUTE(D5," ",""), "_", "")))) -> AvelinodeSouza_etal_2025_TABLE1 | L5: =J5 & "_" & SUBSTITUTE(SUBSTITUTE(SUBSTITUTE(D5,CHAR(160),"")," ",""),"_","") -> 10.1002%2Fcne.70089_TABLE1 | M5: {=IFERROR(INDEX(AUTO_Public_TSV_FileList!$A$1:$A$1000,MATCH(TRUE(),EXACT(L5,IFERROR(_xlfn.TEXTBEFORE(AUTO_Public_TSV_FileList!$A$1:$A$1000,".tsv"),"")),0)),"notfound")} -> 10.1002%2Fcne.70089_TABLE1.tsv | N5: Table 1. Cellular composition of the brain of a Northern minke whale (Balaenoptera acutorostrata) | P5: FINISHED | Q5: added | R5: AvelinodeSouza_etal_2025_TABLE1_snapshot.csv | S5: Y | T5: pdf | U5: table | V5: https://onlinelibrary.wiley.com/doi/10.1002/cne.70089 | W5: https://doi.org/10.1002/cne.70089 | X5: HH | AF5: isotropic fractionator | AG5: placental mammals | AH5: neuron number | AI5: Cetaceans & other placental mammals | AJ5: primary | AK5: primary | AL5: cell count (isotropic fractionator)
A6: Baker, J., Barton, R. A., & Venditti, C. (2025). Human dexterity and brains evolved hand in hand. Communications Biology, 8(1). https://doi.org/10.1038/s42003-025-08686-5 | D6: Supplementary Data 1 | E6: =RIGHT(A6,1) -> 5 | F6: =G6 & IF(H6<>"", "_" & H6, "_") & IF(I6<>"", "_" & I6, "_") & IF(B6<>"", "_" & B6, "") -> Baker_etal_2025 | G6: =SUBSTITUTE(SUBSTITUTE(_xlfn.TEXTBEFORE(A6,","), "-", ""), " ", "") -> Baker | H6: =_xlfn.LET( _xlpm.authors,_xlfn.TEXTBEFORE(A6," ("&I6&")"), _xlpm.hasAmp,ISNUMBER(SEARCH("&",_xlpm.authors)), _xlpm.commasBeforeAmp,IF(_xlpm.hasAmp,LEN(_xlfn.TEXTBEFORE(_xlpm.authors,"&"))-LEN(SUBSTITUTE(_xlfn.TEXTBEFORE(_xlpm.authors,"&"),",","")),0), IF(NOT(_xlpm.hasAmp),"",IF(_xlpm.commasBeforeAmp>2,"etal",TRIM(_xlfn.TEXTBEFORE(_xlfn.TEXTAFTER(_xlpm.authors,"& "),",")))) ) -> etal | I6: =_xlfn.TEXTBEFORE(_xlfn.TEXTAFTER(A6, "("), ")") -> 2025 | J6: =_xlfn.LET( _xlpm.doi,IF(C6<>"",C6,_xlfn.TEXTAFTER(A6,"https://doi.org/")), SUBSTITUTE( SUBSTITUTE( SUBSTITUTE( SUBSTITUTE( _xlpm.doi, "/","%2F"), ":","%3A"), "<","%3C"), ">","%3E") ) -> 10.1038%2Fs42003-025-08686-5 | K6: =TRIM(_xlfn.TEXTJOIN("_",FALSE(),F6,(SUBSTITUTE(SUBSTITUTE(D6," ",""), "_", "")))) -> Baker_etal_2025_SupplementaryData1 | L6: =J6 & "_" & SUBSTITUTE(SUBSTITUTE(SUBSTITUTE(D6,CHAR(160),"")," ",""),"_","") -> 10.1038%2Fs42003-025-08686-5_SupplementaryData1 | M6: {=IFERROR(INDEX(AUTO_Public_TSV_FileList!$A$1:$A$1000,MATCH(TRUE(),EXACT(L6,IFERROR(_xlfn.TEXTBEFORE(AUTO_Public_TSV_FileList!$A$1:$A$1000,".tsv"),"")),0)),"notfound")} -> 10.1038%2Fs42003-025-08686-5_SupplementaryData1.tsv
A7: Balzeau, A., Holloway, R. L., & Grimaud-Hervé, D. (2012). Variations and asymmetries in regional brain surface in the genus Homo. J Hum Evol, 62(6), 696-706. https://doi.org/10.1016/j.jhevol.2012.03.007 | D7: Table 2 | E7: =RIGHT(A7,1) -> 7 | F7: =G7 & IF(H7<>"", "_" & H7, "_") & IF(I7<>"", "_" & I7, "_") & IF(B7<>"", "_" & B7, "") -> Balzeau_etal_2012 | G7: =SUBSTITUTE(SUBSTITUTE(_xlfn.TEXTBEFORE(A7,","), "-", ""), " ", "") -> Balzeau | H7: =_xlfn.LET( _xlpm.authors,_xlfn.TEXTBEFORE(A7," ("&I7&")"), _xlpm.hasAmp,ISNUMBER(SEARCH("&",_xlpm.authors)), _xlpm.commasBeforeAmp,IF(_xlpm.hasAmp,LEN(_xlfn.TEXTBEFORE(_xlpm.authors,"&"))-LEN(SUBSTITUTE(_xlfn.TEXTBEFORE(_xlpm.authors,"&"),",","")),0), IF(NOT(_xlpm.hasAmp),"",IF(_xlpm.commasBeforeAmp>2,"etal",TRIM(_xlfn.TEXTBEFORE(_xlfn.TEXTAFTER(_xlpm.authors,"& "),",")))) ) -> etal | I7: =_xlfn.TEXTBEFORE(_xlfn.TEXTAFTER(A7, "("), ")") -> 2012 | J7: =_xlfn.LET( _xlpm.doi,IF(C7<>"",C7,_xlfn.TEXTAFTER(A7,"https://doi.org/")), SUBSTITUTE( SUBSTITUTE( SUBSTITUTE( SUBSTITUTE( _xlpm.doi, "/","%2F"), ":","%3A"), "<","%3C"), ">","%3E") ) -> 10.1016%2Fj.jhevol.2012.03.007 | K7: =TRIM(_xlfn.TEXTJOIN("_",FALSE(),F7,(SUBSTITUTE(SUBSTITUTE(D7," ",""), "_", "")))) -> Balzeau_etal_2012_Table2 | L7: =J7 & "_" & SUBSTITUTE(SUBSTITUTE(SUBSTITUTE(D7,CHAR(160),"")," ",""),"_","") -> 10.1016%2Fj.jhevol.2012.03.007_Table2 | M7: {=IFERROR(INDEX(AUTO_Public_TSV_FileList!$A$1:$A$1000,MATCH(TRUE(),EXACT(L7,IFERROR(_xlfn.TEXTBEFORE(AUTO_Public_TSV_FileList!$A$1:$A$1000,".tsv"),"")),0)),"notfound")} -> 10.1016%2Fj.jhevol.2012.03.007_Table2.tsv | N7: Table 2. Regression results for the relationship between endocranial volume and the surface of the frontal, parieto-temporal and occipital lobes.
A8: Balzeau, A., Holloway, R. L., & Grimaud-Hervé, D. (2012). Variations and asymmetries in regional brain surface in the genus Homo. J Hum Evol, 62(6), 696-706. https://doi.org/10.1016/j.jhevol.2012.03.007 | D8: Table 3 | E8: =RIGHT(A8,1) -> 7 | F8: =G8 & IF(H8<>"", "_" & H8, "_") & IF(I8<>"", "_" & I8, "_") & IF(B8<>"", "_" & B8, "") -> Balzeau_etal_2012 | G8: =SUBSTITUTE(SUBSTITUTE(_xlfn.TEXTBEFORE(A8,","), "-", ""), " ", "") -> Balzeau | H8: =_xlfn.LET( _xlpm.authors,_xlfn.TEXTBEFORE(A8," ("&I8&")"), _xlpm.hasAmp,ISNUMBER(SEARCH("&",_xlpm.authors)), _xlpm.commasBeforeAmp,IF(_xlpm.hasAmp,LEN(_xlfn.TEXTBEFORE(_xlpm.authors,"&"))-LEN(SUBSTITUTE(_xlfn.TEXTBEFORE(_xlpm.authors,"&"),",","")),0), IF(NOT(_xlpm.hasAmp),"",IF(_xlpm.commasBeforeAmp>2,"etal",TRIM(_xlfn.TEXTBEFORE(_xlfn.TEXTAFTER(_xlpm.authors,"& "),",")))) ) -> etal | I8: =_xlfn.TEXTBEFORE(_xlfn.TEXTAFTER(A8, "("), ")") -> 2012 | J8: =_xlfn.LET( _xlpm.doi,IF(C8<>"",C8,_xlfn.TEXTAFTER(A8,"https://doi.org/")), SUBSTITUTE( SUBSTITUTE( SUBSTITUTE( SUBSTITUTE( _xlpm.doi, "/","%2F"), ":","%3A"), "<","%3C"), ">","%3E") ) -> 10.1016%2Fj.jhevol.2012.03.007 | K8: =TRIM(_xlfn.TEXTJOIN("_",FALSE(),F8,(SUBSTITUTE(SUBSTITUTE(D8," ",""), "_", "")))) -> Balzeau_etal_2012_Table3 | L8: =J8 & "_" & SUBSTITUTE(SUBSTITUTE(SUBSTITUTE(D8,CHAR(160),"")," ",""),"_","") -> 10.1016%2Fj.jhevol.2012.03.007_Table3 | M8: {=IFERROR(INDEX(AUTO_Public_TSV_FileList!$A$1:$A$1000,MATCH(TRUE(),EXACT(L8,IFERROR(_xlfn.TEXTBEFORE(AUTO_Public_TSV_FileList!$A$1:$A$1000,".tsv"),"")),0)),"notfound")} -> 10.1016%2Fj.jhevol.2012.03.007_Table3.tsv | N8: Table 3 Size-corrected dimensions for the surface of the frontal, parieto-temporal and occipital lobes in the different analysed samples.
A9: Balzeau, A., Holloway, R. L., & Grimaud-Hervé, D. (2012). Variations and asymmetries in regional brain surface in the genus Homo. J Hum Evol, 62(6), 696-706. https://doi.org/10.1016/j.jhevol.2012.03.007 | D9: Table 5 | E9: =RIGHT(A9,1) -> 7 | F9: =G9 & IF(H9<>"", "_" & H9, "_") & IF(I9<>"", "_" & I9, "_") & IF(B9<>"", "_" & B9, "") -> Balzeau_etal_2012 | G9: =SUBSTITUTE(SUBSTITUTE(_xlfn.TEXTBEFORE(A9,","), "-", ""), " ", "") -> Balzeau | H9: =_xlfn.LET( _xlpm.authors,_xlfn.TEXTBEFORE(A9," ("&I9&")"), _xlpm.hasAmp,ISNUMBER(SEARCH("&",_xlpm.authors)), _xlpm.commasBeforeAmp,IF(_xlpm.hasAmp,LEN(_xlfn.TEXTBEFORE(_xlpm.authors,"&"))-LEN(SUBSTITUTE(_xlfn.TEXTBEFORE(_xlpm.authors,"&"),",","")),0), IF(NOT(_xlpm.hasAmp),"",IF(_xlpm.commasBeforeAmp>2,"etal",TRIM(_xlfn.TEXTBEFORE(_xlfn.TEXTAFTER(_xlpm.authors,"& "),",")))) ) -> etal | I9: =_xlfn.TEXTBEFORE(_xlfn.TEXTAFTER(A9, "("), ")") -> 2012 | J9: =_xlfn.LET( _xlpm.doi,IF(C9<>"",C9,_xlfn.TEXTAFTER(A9,"https://doi.org/")), SUBSTITUTE( SUBSTITUTE( SUBSTITUTE( SUBSTITUTE( _xlpm.doi, "/","%2F"), ":","%3A"), "<","%3C"), ">","%3E") ) -> 10.1016%2Fj.jhevol.2012.03.007 | K9: =TRIM(_xlfn.TEXTJOIN("_",FALSE(),F9,(SUBSTITUTE(SUBSTITUTE(D9," ",""), "_", "")))) -> Balzeau_etal_2012_Table5 | L9: =J9 & "_" & SUBSTITUTE(SUBSTITUTE(SUBSTITUTE(D9,CHAR(160),"")," ",""),"_","") -> 10.1016%2Fj.jhevol.2012.03.007_Table5 | M9: {=IFERROR(INDEX(AUTO_Public_TSV_FileList!$A$1:$A$1000,MATCH(TRUE(),EXACT(L9,IFERROR(_xlfn.TEXTBEFORE(AUTO_Public_TSV_FileList!$A$1:$A$1000,".tsv"),"")),0)),"notfound")} -> 10.1016%2Fj.jhevol.2012.03.007_Table5.tsv | N9: Table 5 Percentage contribution of frontal, parieto-temporal and occipital lobes to the hemispheres.
A10: Barbeito-Andrés, J., Castro-Fonseca, E., Qiu, L. R., Bernal, V., Lent, R., Henkelman, M., Lukowiak, K., Gleiser, P. M., Hallgrímsson, B., & González, P. N. (2019). Region-specific changes in Mus musculus brain size and cell composition under chronic nutrient restriction. J Exp Biol, 222(Pt 17). https://doi.org/10.1242/jeb.204651 | D10: cell density | E10: =RIGHT(A10,1) -> 1 | F10: =G10 & IF(H10<>"", "_" & H10, "_") & IF(I10<>"", "_" & I10, "_") & IF(B10<>"", "_" & B10, "") -> BarbeitoAndrés_etal_2019 | G10: =SUBSTITUTE(SUBSTITUTE(_xlfn.TEXTBEFORE(A10,","), "-", ""), " ", "") -> BarbeitoAndrés | H10: =_xlfn.LET( _xlpm.authors,_xlfn.TEXTBEFORE(A10," ("&I10&")"), _xlpm.hasAmp,ISNUMBER(SEARCH("&",_xlpm.authors)), _xlpm.commasBeforeAmp,IF(_xlpm.hasAmp,LEN(_xlfn.TEXTBEFORE(_xlpm.authors,"&"))-LEN(SUBSTITUTE(_xlfn.TEXTBEFORE(_xlpm.authors,"&"),",","")),0), IF(NOT(_xlpm.hasAmp),"",IF(_xlpm.commasBeforeAmp>2,"etal",TRIM(_xlfn.TEXTBEFORE(_xlfn.TEXTAFTER(_xlpm.authors,"& "),",")))) ) -> etal | I10: =_xlfn.TEXTBEFORE(_xlfn.TEXTAFTER(A10, "("), ")") -> 2019 | J10: =_xlfn.LET( _xlpm.doi,IF(C10<>"",C10,_xlfn.TEXTAFTER(A10,"https://doi.org/")), SUBSTITUTE( SUBSTITUTE( SUBSTITUTE( SUBSTITUTE( _xlpm.doi, "/","%2F"), ":","%3A"), "<","%3C"), ">","%3E") ) -> 10.1242%2Fjeb.204651 | K10: =TRIM(_xlfn.TEXTJOIN("_",FALSE(),F10,(SUBSTITUTE(SUBSTITUTE(D10," ",""), "_", "")))) -> BarbeitoAndrés_etal_2019_celldensity | L10: =J10 & "_" & SUBSTITUTE(SUBSTITUTE(SUBSTITUTE(D10,CHAR(160),"")," ",""),"_","") -> 10.1242%2Fjeb.204651_celldensity | M10: {=IFERROR(INDEX(AUTO_Public_TSV_FileList!$A$1:$A$1000,MATCH(TRUE(),EXACT(L10,IFERROR(_xlfn.TEXTBEFORE(AUTO_Public_TSV_FileList!$A$1:$A$1000,".tsv"),"")),0)),"notfound")} -> 10.1242%2Fjeb.204651_celldensity.tsv | AF10: isotropic fractionator | AI10: review | AK10: review | AL10: review
A11: Barbeito-Andrés, J., Castro-Fonseca, E., Qiu, L. R., Bernal, V., Lent, R., Henkelman, M., Lukowiak, K., Gleiser, P. M., Hallgrímsson, B., & González, P. N. (2019). Region-specific changes in Mus musculus brain size and cell composition under chronic nutrient restriction. J Exp Biol, 222(Pt 17). https://doi.org/10.1242/jeb.204651 | D11: cell number | E11: =RIGHT(A11,1) -> 1 | F11: =G11 & IF(H11<>"", "_" & H11, "_") & IF(I11<>"", "_" & I11, "_") & IF(B11<>"", "_" & B11, "") -> BarbeitoAndrés_etal_2019 | G11: =SUBSTITUTE(SUBSTITUTE(_xlfn.TEXTBEFORE(A11,","), "-", ""), " ", "") -> BarbeitoAndrés | H11: =_xlfn.LET( _xlpm.authors,_xlfn.TEXTBEFORE(A11," ("&I11&")"), _xlpm.hasAmp,ISNUMBER(SEARCH("&",_xlpm.authors)), _xlpm.commasBeforeAmp,IF(_xlpm.hasAmp,LEN(_xlfn.TEXTBEFORE(_xlpm.authors,"&"))-LEN(SUBSTITUTE(_xlfn.TEXTBEFORE(_xlpm.authors,"&"),",","")),0), IF(NOT(_xlpm.hasAmp),"",IF(_xlpm.commasBeforeAmp>2,"etal",TRIM(_xlfn.TEXTBEFORE(_xlfn.TEXTAFTER(_xlpm.authors,"& "),",")))) ) -> etal | I11: =_xlfn.TEXTBEFORE(_xlfn.TEXTAFTER(A11, "("), ")") -> 2019 | J11: =_xlfn.LET( _xlpm.doi,IF(C11<>"",C11,_xlfn.TEXTAFTER(A11,"https://doi.org/")), SUBSTITUTE( SUBSTITUTE( SUBSTITUTE( SUBSTITUTE( _xlpm.doi, "/","%2F"), ":","%3A"), "<","%3C"), ">","%3E") ) -> 10.1242%2Fjeb.204651 | K11: =TRIM(_xlfn.TEXTJOIN("_",FALSE(),F11,(SUBSTITUTE(SUBSTITUTE(D11," ",""), "_", "")))) -> BarbeitoAndrés_etal_2019_cellnumber | L11: =J11 & "_" & SUBSTITUTE(SUBSTITUTE(SUBSTITUTE(D11,CHAR(160),"")," ",""),"_","") -> 10.1242%2Fjeb.204651_cellnumber | M11: {=IFERROR(INDEX(AUTO_Public_TSV_FileList!$A$1:$A$1000,MATCH(TRUE(),EXACT(L11,IFERROR(_xlfn.TEXTBEFORE(AUTO_Public_TSV_FileList!$A$1:$A$1000,".tsv"),"")),0)),"notfound")} -> 10.1242%2Fjeb.204651_cellnumber.tsv | AF11: isotropic fractionator | AI11: review | AK11: review | AL11: review
A12: Barbeito-Andrés, J., Castro-Fonseca, E., Qiu, L. R., Bernal, V., Lent, R., Henkelman, M., Lukowiak, K., Gleiser, P. M., Hallgrímsson, B., & González, P. N. (2019). Region-specific changes in Mus musculus brain size and cell composition under chronic nutrient restriction. J Exp Biol, 222(Pt 17). https://doi.org/10.1242/jeb.204651 | D12: volumes | E12: =RIGHT(A12,1) -> 1 | F12: =G12 & IF(H12<>"", "_" & H12, "_") & IF(I12<>"", "_" & I12, "_") & IF(B12<>"", "_" & B12, "") -> BarbeitoAndrés_etal_2019 | G12: =SUBSTITUTE(SUBSTITUTE(_xlfn.TEXTBEFORE(A12,","), "-", ""), " ", "") -> BarbeitoAndrés | H12: =_xlfn.LET( _xlpm.authors,_xlfn.TEXTBEFORE(A12," ("&I12&")"), _xlpm.hasAmp,ISNUMBER(SEARCH("&",_xlpm.authors)), _xlpm.commasBeforeAmp,IF(_xlpm.hasAmp,LEN(_xlfn.TEXTBEFORE(_xlpm.authors,"&"))-LEN(SUBSTITUTE(_xlfn.TEXTBEFORE(_xlpm.authors,"&"),",","")),0), IF(NOT(_xlpm.hasAmp),"",IF(_xlpm.commasBeforeAmp>2,"etal",TRIM(_xlfn.TEXTBEFORE(_xlfn.TEXTAFTER(_xlpm.authors,"& "),",")))) ) -> etal | I12: =_xlfn.TEXTBEFORE(_xlfn.TEXTAFTER(A12, "("), ")") -> 2019 | J12: =_xlfn.LET( _xlpm.doi,IF(C12<>"",C12,_xlfn.TEXTAFTER(A12,"https://doi.org/")), SUBSTITUTE( SUBSTITUTE( SUBSTITUTE( SUBSTITUTE( _xlpm.doi, "/","%2F"), ":","%3A"), "<","%3C"), ">","%3E") ) -> 10.1242%2Fjeb.204651 | K12: =TRIM(_xlfn.TEXTJOIN("_",FALSE(),F12,(SUBSTITUTE(SUBSTITUTE(D12," ",""), "_", "")))) -> BarbeitoAndrés_etal_2019_volumes | L12: =J12 & "_" & SUBSTITUTE(SUBSTITUTE(SUBSTITUTE(D12,CHAR(160),"")," ",""),"_","") -> 10.1242%2Fjeb.204651_volumes | M12: {=IFERROR(INDEX(AUTO_Public_TSV_FileList!$A$1:$A$1000,MATCH(TRUE(),EXACT(L12,IFERROR(_xlfn.TEXTBEFORE(AUTO_Public_TSV_FileList!$A$1:$A$1000,".tsv"),"")),0)),"notfound")} -> 10.1242%2Fjeb.204651_volumes.tsv | AF12: isotropic fractionator | AI12: review | AK12: review | AL12: review
A13: Barger, N., Hanson, K. L., Teffer, K., Schenker-Ahmed, N. M., & Semendeferi, K. (2014). Evidence for evolutionary specialization in human limbic structures. Front Hum Neurosci, 8, 277. https://doi.org/10.3389/fnhum.2014.00277 | D13: Table 1 | E13: =RIGHT(A13,1) -> 7 | F13: =G13 & IF(H13<>"", "_" & H13, "_") & IF(I13<>"", "_" & I13, "_") & IF(B13<>"", "_" & B13, "") -> Barger_etal_2014 | G13: =SUBSTITUTE(SUBSTITUTE(_xlfn.TEXTBEFORE(A13,","), "-", ""), " ", "") -> Barger | H13: =_xlfn.LET( _xlpm.authors,_xlfn.TEXTBEFORE(A13," ("&I13&")"), _xlpm.hasAmp,ISNUMBER(SEARCH("&",_xlpm.authors)), _xlpm.commasBeforeAmp,IF(_xlpm.hasAmp,LEN(_xlfn.TEXTBEFORE(_xlpm.authors,"&"))-LEN(SUBSTITUTE(_xlfn.TEXTBEFORE(_xlpm.authors,"&"),",","")),0), IF(NOT(_xlpm.hasAmp),"",IF(_xlpm.commasBeforeAmp>2,"etal",TRIM(_xlfn.TEXTBEFORE(_xlfn.TEXTAFTER(_xlpm.authors,"& "),",")))) ) -> etal | I13: =_xlfn.TEXTBEFORE(_xlfn.TEXTAFTER(A13, "("), ")") -> 2014 | J13: =_xlfn.LET( _xlpm.doi,IF(C13<>"",C13,_xlfn.TEXTAFTER(A13,"https://doi.org/")), SUBSTITUTE( SUBSTITUTE( SUBSTITUTE( SUBSTITUTE( _xlpm.doi, "/","%2F"), ":","%3A"), "<","%3C"), ">","%3E") ) -> 10.3389%2Ffnhum.2014.00277 | K13: =TRIM(_xlfn.TEXTJOIN("_",FALSE(),F13,(SUBSTITUTE(SUBSTITUTE(D13," ",""), "_", "")))) -> Barger_etal_2014_Table1 | L13: =J13 & "_" & SUBSTITUTE(SUBSTITUTE(SUBSTITUTE(D13,CHAR(160),"")," ",""),"_","") -> 10.3389%2Ffnhum.2014.00277_Table1 | M13: {=IFERROR(INDEX(AUTO_Public_TSV_FileList!$A$1:$A$1000,MATCH(TRUE(),EXACT(L13,IFERROR(_xlfn.TEXTBEFORE(AUTO_Public_TSV_FileList!$A$1:$A$1000,".tsv"),"")),0)),"notfound")} -> 10.3389%2Ffnhum.2014.00277_Table1.tsv | N13: Table 1 | Volume of amygdala, hippocampus, and striatum in hominoid species collected with stereological methods. | Y13: Zilles | AE13: histological sections | AF13: Zilles
A14: Barger, N., Stefanacci, L., & Semendeferi, K. (2007). A comparative volumetric analysis of the amygdaloid complex and basolateral division in the human and ape brain. Am J Phys Anthropol, 134(3), 392-403. https://doi.org/10.1002/ajpa.20684 | D14: TABLE 1 | E14: =RIGHT(A14,1) -> 4 | F14: =G14 & IF(H14<>"", "_" & H14, "_") & IF(I14<>"", "_" & I14, "_") & IF(B14<>"", "_" & B14, "") -> Barger_etal_2007 | G14: =SUBSTITUTE(SUBSTITUTE(_xlfn.TEXTBEFORE(A14,","), "-", ""), " ", "") -> Barger | H14: =_xlfn.LET( _xlpm.authors,_xlfn.TEXTBEFORE(A14," ("&I14&")"), _xlpm.hasAmp,ISNUMBER(SEARCH("&",_xlpm.authors)), _xlpm.commasBeforeAmp,IF(_xlpm.hasAmp,LEN(_xlfn.TEXTBEFORE(_xlpm.authors,"&"))-LEN(SUBSTITUTE(_xlfn.TEXTBEFORE(_xlpm.authors,"&"),",","")),0), IF(NOT(_xlpm.hasAmp),"",IF(_xlpm.commasBeforeAmp>2,"etal",TRIM(_xlfn.TEXTBEFORE(_xlfn.TEXTAFTER(_xlpm.authors,"& "),",")))) ) -> etal | I14: =_xlfn.TEXTBEFORE(_xlfn.TEXTAFTER(A14, "("), ")") -> 2007 | J14: =_xlfn.LET( _xlpm.doi,IF(C14<>"",C14,_xlfn.TEXTAFTER(A14,"https://doi.org/")), SUBSTITUTE( SUBSTITUTE( SUBSTITUTE( SUBSTITUTE( _xlpm.doi, "/","%2F"), ":","%3A"), "<","%3C"), ">","%3E") ) -> 10.1002%2Fajpa.20684 | K14: =TRIM(_xlfn.TEXTJOIN("_",FALSE(),F14,(SUBSTITUTE(SUBSTITUTE(D14," ",""), "_", "")))) -> Barger_etal_2007_TABLE1 | L14: =J14 & "_" & SUBSTITUTE(SUBSTITUTE(SUBSTITUTE(D14,CHAR(160),"")," ",""),"_","") -> 10.1002%2Fajpa.20684_TABLE1 | M14: {=IFERROR(INDEX(AUTO_Public_TSV_FileList!$A$1:$A$1000,MATCH(TRUE(),EXACT(L14,IFERROR(_xlfn.TEXTBEFORE(AUTO_Public_TSV_FileList!$A$1:$A$1000,".tsv"),"")),0)),"notfound")} -> 10.1002%2Fajpa.20684_TABLE1.tsv | N14: TABLE 1. Volumetric estimates of the amygdaloid complex and the basolateral division | P14: FINISHED | Y14: Zilles | AF14: Zilles | AH14: amygdala subdivision volumes | AI14: Apes & humans | AK14: primary | AL14: volume
A15: Barger, N., Stefanacci, L., Schumann, C. M., Sherwood, C. C., Annese, J., Allman, J. M., Buckwalter, J. A., Hof, P. R., & Semendeferi, K. (2012). Neuronal populations in the basolateral nuclei of the amygdala are differentially increased in humans compared with apes: A stereological study. J Comp Neurol, 520(13), 3035-3054. https://doi.org/10.1002/cne.23118 | D15: Table 3 | E15: =RIGHT(A15,1) -> 8 | F15: =G15 & IF(H15<>"", "_" & H15, "_") & IF(I15<>"", "_" & I15, "_") & IF(B15<>"", "_" & B15, "") -> Barger_etal_2012 | G15: =SUBSTITUTE(SUBSTITUTE(_xlfn.TEXTBEFORE(A15,","), "-", ""), " ", "") -> Barger | H15: =_xlfn.LET( _xlpm.authors,_xlfn.TEXTBEFORE(A15," ("&I15&")"), _xlpm.hasAmp,ISNUMBER(SEARCH("&",_xlpm.authors)), _xlpm.commasBeforeAmp,IF(_xlpm.hasAmp,LEN(_xlfn.TEXTBEFORE(_xlpm.authors,"&"))-LEN(SUBSTITUTE(_xlfn.TEXTBEFORE(_xlpm.authors,"&"),",","")),0), IF(NOT(_xlpm.hasAmp),"",IF(_xlpm.commasBeforeAmp>2,"etal",TRIM(_xlfn.TEXTBEFORE(_xlfn.TEXTAFTER(_xlpm.authors,"& "),",")))) ) -> etal | I15: =_xlfn.TEXTBEFORE(_xlfn.TEXTAFTER(A15, "("), ")") -> 2012 | J15: =_xlfn.LET( _xlpm.doi,IF(C15<>"",C15,_xlfn.TEXTAFTER(A15,"https://doi.org/")), SUBSTITUTE( SUBSTITUTE( SUBSTITUTE( SUBSTITUTE( _xlpm.doi, "/","%2F"), ":","%3A"), "<","%3C"), ">","%3E") ) -> 10.1002%2Fcne.23118 | K15: =TRIM(_xlfn.TEXTJOIN("_",FALSE(),F15,(SUBSTITUTE(SUBSTITUTE(D15," ",""), "_", "")))) -> Barger_etal_2012_Table3 | L15: =J15 & "_" & SUBSTITUTE(SUBSTITUTE(SUBSTITUTE(D15,CHAR(160),"")," ",""),"_","") -> 10.1002%2Fcne.23118_Table3 | M15: {=IFERROR(INDEX(AUTO_Public_TSV_FileList!$A$1:$A$1000,MATCH(TRUE(),EXACT(L15,IFERROR(_xlfn.TEXTBEFORE(AUTO_Public_TSV_FileList!$A$1:$A$1000,".tsv"),"")),0)),"notfound")} -> 10.1002%2Fcne.23118_Table3.tsv | N15: Table 3. Average Neuron Number x10^6 (SD) for each nucleus in each species | P15: FINISHED | AH15: amygdala neuron numbers (basolateral + central nuclei) | AI15: Primates | AJ15: primary | AK15: primary | AL15: neuron count (stereology)
A16: Barks, S. K., Calhoun, M. E., Hopkins, W. D., Cranfield, M. R., Mudakikwa, A., Stoinski, T. S., Patterson, F. G., Erwin, J. M., Hecht, E. E., Hof, P. R., & Sherwood, C. C. (2014). Brain organization of gorillas reflects species differences in ecology. Am J Phys Anthropol. https://doi.org/10.1002/ajpa.22646 | D16: Fig 4 A | E16: =RIGHT(A16,1) -> 6 | F16: =G16 & IF(H16<>"", "_" & H16, "_") & IF(I16<>"", "_" & I16, "_") & IF(B16<>"", "_" & B16, "") -> Barks_etal_2014 | G16: =SUBSTITUTE(SUBSTITUTE(_xlfn.TEXTBEFORE(A16,","), "-", ""), " ", "") -> Barks | H16: =_xlfn.LET( _xlpm.authors,_xlfn.TEXTBEFORE(A16," ("&I16&")"), _xlpm.hasAmp,ISNUMBER(SEARCH("&",_xlpm.authors)), _xlpm.commasBeforeAmp,IF(_xlpm.hasAmp,LEN(_xlfn.TEXTBEFORE(_xlpm.authors,"&"))-LEN(SUBSTITUTE(_xlfn.TEXTBEFORE(_xlpm.authors,"&"),",","")),0), IF(NOT(_xlpm.hasAmp),"",IF(_xlpm.commasBeforeAmp>2,"etal",TRIM(_xlfn.TEXTBEFORE(_xlfn.TEXTAFTER(_xlpm.authors,"& "),",")))) ) -> etal | I16: =_xlfn.TEXTBEFORE(_xlfn.TEXTAFTER(A16, "("), ")") -> 2014 | J16: =_xlfn.LET( _xlpm.doi,IF(C16<>"",C16,_xlfn.TEXTAFTER(A16,"https://doi.org/")), SUBSTITUTE( SUBSTITUTE( SUBSTITUTE( SUBSTITUTE( _xlpm.doi, "/","%2F"), ":","%3A"), "<","%3C"), ">","%3E") ) -> 10.1002%2Fajpa.22646 | K16: =TRIM(_xlfn.TEXTJOIN("_",FALSE(),F16,(SUBSTITUTE(SUBSTITUTE(D16," ",""), "_", "")))) -> Barks_etal_2014_Fig4A | L16: =J16 & "_" & SUBSTITUTE(SUBSTITUTE(SUBSTITUTE(D16,CHAR(160),"")," ",""),"_","") -> 10.1002%2Fajpa.22646_Fig4A | M16: {=IFERROR(INDEX(AUTO_Public_TSV_FileList!$A$1:$A$1000,MATCH(TRUE(),EXACT(L16,IFERROR(_xlfn.TEXTBEFORE(AUTO_Public_TSV_FileList!$A$1:$A$1000,".tsv"),"")),0)),"notfound")} -> 10.1002%2Fajpa.22646_Fig4A.tsv | O16: Fig4A_allsubjects_volumes | P16: FINISHED | X16: Barks
A17: Barks, S. K., Calhoun, M. E., Hopkins, W. D., Cranfield, M. R., Mudakikwa, A., Stoinski, T. S., Patterson, F. G., Erwin, J. M., Hecht, E. E., Hof, P. R., & Sherwood, C. C. (2014). Brain organization of gorillas reflects species differences in ecology. Am J Phys Anthropol. https://doi.org/10.1002/ajpa.22646 | D17: Fig 5 A | E17: =RIGHT(A17,1) -> 6 | F17: =G17 & IF(H17<>"", "_" & H17, "_") & IF(I17<>"", "_" & I17, "_") & IF(B17<>"", "_" & B17, "") -> Barks_etal_2014 | G17: =SUBSTITUTE(SUBSTITUTE(_xlfn.TEXTBEFORE(A17,","), "-", ""), " ", "") -> Barks | H17: =_xlfn.LET( _xlpm.authors,_xlfn.TEXTBEFORE(A17," ("&I17&")"), _xlpm.hasAmp,ISNUMBER(SEARCH("&",_xlpm.authors)), _xlpm.commasBeforeAmp,IF(_xlpm.hasAmp,LEN(_xlfn.TEXTBEFORE(_xlpm.authors,"&"))-LEN(SUBSTITUTE(_xlfn.TEXTBEFORE(_xlpm.authors,"&"),",","")),0), IF(NOT(_xlpm.hasAmp),"",IF(_xlpm.commasBeforeAmp>2,"etal",TRIM(_xlfn.TEXTBEFORE(_xlfn.TEXTAFTER(_xlpm.authors,"& "),",")))) ) -> etal | I17: =_xlfn.TEXTBEFORE(_xlfn.TEXTAFTER(A17, "("), ")") -> 2014 | J17: =_xlfn.LET( _xlpm.doi,IF(C17<>"",C17,_xlfn.TEXTAFTER(A17,"https://doi.org/")), SUBSTITUTE( SUBSTITUTE( SUBSTITUTE( SUBSTITUTE( _xlpm.doi, "/","%2F"), ":","%3A"), "<","%3C"), ">","%3E") ) -> 10.1002%2Fajpa.22646 | K17: =TRIM(_xlfn.TEXTJOIN("_",FALSE(),F17,(SUBSTITUTE(SUBSTITUTE(D17," ",""), "_", "")))) -> Barks_etal_2014_Fig5A | L17: =J17 & "_" & SUBSTITUTE(SUBSTITUTE(SUBSTITUTE(D17,CHAR(160),"")," ",""),"_","") -> 10.1002%2Fajpa.22646_Fig5A | M17: {=IFERROR(INDEX(AUTO_Public_TSV_FileList!$A$1:$A$1000,MATCH(TRUE(),EXACT(L17,IFERROR(_xlfn.TEXTBEFORE(AUTO_Public_TSV_FileList!$A$1:$A$1000,".tsv"),"")),0)),"notfound")} -> 10.1002%2Fajpa.22646_Fig5A.tsv | O17: Fig5A_adultsonly_volumes | P17: FINISHED
A18: Barks, S. K., Calhoun, M. E., Hopkins, W. D., Cranfield, M. R., Mudakikwa, A., Stoinski, T. S., Patterson, F. G., Erwin, J. M., Hecht, E. E., Hof, P. R., & Sherwood, C. C. (2014). Brain organization of gorillas reflects species differences in ecology. Am J Phys Anthropol. https://doi.org/10.1002/ajpa.22646 | D18: TABLE 1 | E18: =RIGHT(A18,1) -> 6 | F18: =G18 & IF(H18<>"", "_" & H18, "_") & IF(I18<>"", "_" & I18, "_") & IF(B18<>"", "_" & B18, "") -> Barks_etal_2014 | G18: =SUBSTITUTE(SUBSTITUTE(_xlfn.TEXTBEFORE(A18,","), "-", ""), " ", "") -> Barks | H18: =_xlfn.LET( _xlpm.authors,_xlfn.TEXTBEFORE(A18," ("&I18&")"), _xlpm.hasAmp,ISNUMBER(SEARCH("&",_xlpm.authors)), _xlpm.commasBeforeAmp,IF(_xlpm.hasAmp,LEN(_xlfn.TEXTBEFORE(_xlpm.authors,"&"))-LEN(SUBSTITUTE(_xlfn.TEXTBEFORE(_xlpm.authors,"&"),",","")),0), IF(NOT(_xlpm.hasAmp),"",IF(_xlpm.commasBeforeAmp>2,"etal",TRIM(_xlfn.TEXTBEFORE(_xlfn.TEXTAFTER(_xlpm.authors,"& "),",")))) ) -> etal | I18: =_xlfn.TEXTBEFORE(_xlfn.TEXTAFTER(A18, "("), ")") -> 2014 | J18: =_xlfn.LET( _xlpm.doi,IF(C18<>"",C18,_xlfn.TEXTAFTER(A18,"https://doi.org/")), SUBSTITUTE( SUBSTITUTE( SUBSTITUTE( SUBSTITUTE( _xlpm.doi, "/","%2F"), ":","%3A"), "<","%3C"), ">","%3E") ) -> 10.1002%2Fajpa.22646 | K18: =TRIM(_xlfn.TEXTJOIN("_",FALSE(),F18,(SUBSTITUTE(SUBSTITUTE(D18," ",""), "_", "")))) -> Barks_etal_2014_TABLE1 | L18: =J18 & "_" & SUBSTITUTE(SUBSTITUTE(SUBSTITUTE(D18,CHAR(160),"")," ",""),"_","") -> 10.1002%2Fajpa.22646_TABLE1 | M18: {=IFERROR(INDEX(AUTO_Public_TSV_FileList!$A$1:$A$1000,MATCH(TRUE(),EXACT(L18,IFERROR(_xlfn.TEXTBEFORE(AUTO_Public_TSV_FileList!$A$1:$A$1000,".tsv"),"")),0)),"notfound")} -> 10.1002%2Fajpa.22646_TABLE1.tsv | N18: TABLE 1. Individual data | P18: FINISHED | X18: Barks
A19: Barks, S. K., Calhoun, M. E., Hopkins, W. D., Cranfield, M. R., Mudakikwa, A., Stoinski, T. S., Patterson, F. G., Erwin, J. M., Hecht, E. E., Hof, P. R., & Sherwood, C. C. (2014). Brain organization of gorillas reflects species differences in ecology. Am J Phys Anthropol. https://doi.org/10.1002/ajpa.22646 | D19: TABLE 2 | E19: =RIGHT(A19,1) -> 6 | F19: =G19 & IF(H19<>"", "_" & H19, "_") & IF(I19<>"", "_" & I19, "_") & IF(B19<>"", "_" & B19, "") -> Barks_etal_2014 | G19: =SUBSTITUTE(SUBSTITUTE(_xlfn.TEXTBEFORE(A19,","), "-", ""), " ", "") -> Barks | H19: =_xlfn.LET( _xlpm.authors,_xlfn.TEXTBEFORE(A19," ("&I19&")"), _xlpm.hasAmp,ISNUMBER(SEARCH("&",_xlpm.authors)), _xlpm.commasBeforeAmp,IF(_xlpm.hasAmp,LEN(_xlfn.TEXTBEFORE(_xlpm.authors,"&"))-LEN(SUBSTITUTE(_xlfn.TEXTBEFORE(_xlpm.authors,"&"),",","")),0), IF(NOT(_xlpm.hasAmp),"",IF(_xlpm.commasBeforeAmp>2,"etal",TRIM(_xlfn.TEXTBEFORE(_xlfn.TEXTAFTER(_xlpm.authors,"& "),",")))) ) -> etal | I19: =_xlfn.TEXTBEFORE(_xlfn.TEXTAFTER(A19, "("), ")") -> 2014 | J19: =_xlfn.LET( _xlpm.doi,IF(C19<>"",C19,_xlfn.TEXTAFTER(A19,"https://doi.org/")), SUBSTITUTE( SUBSTITUTE( SUBSTITUTE( SUBSTITUTE( _xlpm.doi, "/","%2F"), ":","%3A"), "<","%3C"), ">","%3E") ) -> 10.1002%2Fajpa.22646 | K19: =TRIM(_xlfn.TEXTJOIN("_",FALSE(),F19,(SUBSTITUTE(SUBSTITUTE(D19," ",""), "_", "")))) -> Barks_etal_2014_TABLE2 | L19: =J19 & "_" & SUBSTITUTE(SUBSTITUTE(SUBSTITUTE(D19,CHAR(160),"")," ",""),"_","") -> 10.1002%2Fajpa.22646_TABLE2 | M19: {=IFERROR(INDEX(AUTO_Public_TSV_FileList!$A$1:$A$1000,MATCH(TRUE(),EXACT(L19,IFERROR(_xlfn.TEXTBEFORE(AUTO_Public_TSV_FileList!$A$1:$A$1000,".tsv"),"")),0)),"notfound")} -> 10.1002%2Fajpa.22646_TABLE2.tsv | N19: TABLE 2. Stereological sampling of brains | P19: FINISHED
A20: Barks, S. K., Calhoun, M. E., Hopkins, W. D., Cranfield, M. R., Mudakikwa, A., Stoinski, T. S., Patterson, F. G., Erwin, J. M., Hecht, E. E., Hof, P. R., & Sherwood, C. C. (2014). Brain organization of gorillas reflects species differences in ecology. Am J Phys Anthropol. https://doi.org/10.1002/ajpa.22646 | D20: unpublishedviaDeCasien | E20: =RIGHT(A20,1) -> 6 | F20: =G20 & IF(H20<>"", "_" & H20, "_") & IF(I20<>"", "_" & I20, "_") & IF(B20<>"", "_" & B20, "") -> Barks_etal_2014 | G20: =SUBSTITUTE(SUBSTITUTE(_xlfn.TEXTBEFORE(A20,","), "-", ""), " ", "") -> Barks | H20: =_xlfn.LET( _xlpm.authors,_xlfn.TEXTBEFORE(A20," ("&I20&")"), _xlpm.hasAmp,ISNUMBER(SEARCH("&",_xlpm.authors)), _xlpm.commasBeforeAmp,IF(_xlpm.hasAmp,LEN(_xlfn.TEXTBEFORE(_xlpm.authors,"&"))-LEN(SUBSTITUTE(_xlfn.TEXTBEFORE(_xlpm.authors,"&"),",","")),0), IF(NOT(_xlpm.hasAmp),"",IF(_xlpm.commasBeforeAmp>2,"etal",TRIM(_xlfn.TEXTBEFORE(_xlfn.TEXTAFTER(_xlpm.authors,"& "),",")))) ) -> etal | I20: =_xlfn.TEXTBEFORE(_xlfn.TEXTAFTER(A20, "("), ")") -> 2014 | J20: =_xlfn.LET( _xlpm.doi,IF(C20<>"",C20,_xlfn.TEXTAFTER(A20,"https://doi.org/")), SUBSTITUTE( SUBSTITUTE( SUBSTITUTE( SUBSTITUTE( _xlpm.doi, "/","%2F"), ":","%3A"), "<","%3C"), ">","%3E") ) -> 10.1002%2Fajpa.22646 | K20: =TRIM(_xlfn.TEXTJOIN("_",FALSE(),F20,(SUBSTITUTE(SUBSTITUTE(D20," ",""), "_", "")))) -> Barks_etal_2014_unpublishedviaDeCasien | L20: =J20 & "_" & SUBSTITUTE(SUBSTITUTE(SUBSTITUTE(D20,CHAR(160),"")," ",""),"_","") -> 10.1002%2Fajpa.22646_unpublishedviaDeCasien | M20: {=IFERROR(INDEX(AUTO_Public_TSV_FileList!$A$1:$A$1000,MATCH(TRUE(),EXACT(L20,IFERROR(_xlfn.TEXTBEFORE(AUTO_Public_TSV_FileList!$A$1:$A$1000,".tsv"),"")),0)),"notfound")} -> 10.1002%2Fajpa.22646_unpublishedviaDeCasien.tsv | O20: "Sherwood et al.64 and Barks et al.65 provided neocortex, hippocampus, striatum, thalamus, cerebellum, amygdala and insula measures for multiple gorilla species (Gorilla gorilla gorilla, G. g. graueri and G. beringei) from post-mortem MRI scans" (DeCasien and Higham 2019)
A21: Baron, G., Frahm, H. D., & Stephan, H. (1988). Comparison of brain structure volumes in Insectivora and Primates. VIII. Vestibular complex. J Hirnforsch, 29(5), 509-523. http://www.ncbi.nlm.nih.gov/pubmed/3216099 | C21: PMID:3216099 | D21: Table 1 | E21: =RIGHT(A21,1) -> 9 | F21: =G21 & IF(H21<>"", "_" & H21, "_") & IF(I21<>"", "_" & I21, "_") & IF(B21<>"", "_" & B21, "") -> Baron_etal_1988 | G21: =SUBSTITUTE(SUBSTITUTE(_xlfn.TEXTBEFORE(A21,","), "-", ""), " ", "") -> Baron | H21: =_xlfn.LET( _xlpm.authors,_xlfn.TEXTBEFORE(A21," ("&I21&")"), _xlpm.hasAmp,ISNUMBER(SEARCH("&",_xlpm.authors)), _xlpm.commasBeforeAmp,IF(_xlpm.hasAmp,LEN(_xlfn.TEXTBEFORE(_xlpm.authors,"&"))-LEN(SUBSTITUTE(_xlfn.TEXTBEFORE(_xlpm.authors,"&"),",","")),0), IF(NOT(_xlpm.hasAmp),"",IF(_xlpm.commasBeforeAmp>2,"etal",TRIM(_xlfn.TEXTBEFORE(_xlfn.TEXTAFTER(_xlpm.authors,"& "),",")))) ) -> etal | I21: =_xlfn.TEXTBEFORE(_xlfn.TEXTAFTER(A21, "("), ")") -> 1988 | J21: =_xlfn.LET( _xlpm.doi,IF(C21<>"",C21,_xlfn.TEXTAFTER(A21,"https://doi.org/")), SUBSTITUTE( SUBSTITUTE( SUBSTITUTE( SUBSTITUTE( _xlpm.doi, "/","%2F"), ":","%3A"), "<","%3C"), ">","%3E") ) -> PMID%3A3216099 | K21: =TRIM(_xlfn.TEXTJOIN("_",FALSE(),F21,(SUBSTITUTE(SUBSTITUTE(D21," ",""), "_", "")))) -> Baron_etal_1988_Table1 | L21: =J21 & "_" & SUBSTITUTE(SUBSTITUTE(SUBSTITUTE(D21,CHAR(160),"")," ",""),"_","") -> PMID%3A3216099_Table1 | M21: {=IFERROR(INDEX(AUTO_Public_TSV_FileList!$A$1:$A$1000,MATCH(TRUE(),EXACT(L21,IFERROR(_xlfn.TEXTBEFORE(AUTO_Public_TSV_FileList!$A$1:$A$1000,".tsv"),"")),0)),"notfound")} -> PMID%3A3216099_Table1.tsv | N21: Table 1. Volumes and indices of the vestibular complex (VC) and its main components (VM, V1, VL, VS) in Insectivora and Scadentia | P21: FINISHED | X21: Stephan | Y21: Stephan | AE21: histological sections | AF21: Stephan | AH21: vestibular nuclear complex volume | AI21: Insectivora, Scandentia & Primates | AK21: primary | AL21: volume
A22: Baron, G., Frahm, H. D., Bhatnagar, K. P., & Stephan, H. (1983). Comparison of brain structure volumes in Insectivora and Primates. III. Main olfactory bulb (MOB). J Hirnforsch, 24(5), 551-568. https://www.ncbi.nlm.nih.gov/pubmed/6663055 | C22: PMID:6663055 | D22: Table 1 | E22: =RIGHT(A22,1) -> 5 | F22: =G22 & IF(H22<>"", "_" & H22, "_") & IF(I22<>"", "_" & I22, "_") & IF(B22<>"", "_" & B22, "") -> Baron_etal_1983 | G22: =SUBSTITUTE(SUBSTITUTE(_xlfn.TEXTBEFORE(A22,","), "-", ""), " ", "") -> Baron | H22: =_xlfn.LET( _xlpm.authors,_xlfn.TEXTBEFORE(A22," ("&I22&")"), _xlpm.hasAmp,ISNUMBER(SEARCH("&",_xlpm.authors)), _xlpm.commasBeforeAmp,IF(_xlpm.hasAmp,LEN(_xlfn.TEXTBEFORE(_xlpm.authors,"&"))-LEN(SUBSTITUTE(_xlfn.TEXTBEFORE(_xlpm.authors,"&"),",","")),0), IF(NOT(_xlpm.hasAmp),"",IF(_xlpm.commasBeforeAmp>2,"etal",TRIM(_xlfn.TEXTBEFORE(_xlfn.TEXTAFTER(_xlpm.authors,"& "),",")))) ) -> etal | I22: =_xlfn.TEXTBEFORE(_xlfn.TEXTAFTER(A22, "("), ")") -> 1983 | J22: =_xlfn.LET( _xlpm.doi,IF(C22<>"",C22,_xlfn.TEXTAFTER(A22,"https://doi.org/")), SUBSTITUTE( SUBSTITUTE( SUBSTITUTE( SUBSTITUTE( _xlpm.doi, "/","%2F"), ":","%3A"), "<","%3C"), ">","%3E") ) -> PMID%3A6663055 | K22: =TRIM(_xlfn.TEXTJOIN("_",FALSE(),F22,(SUBSTITUTE(SUBSTITUTE(D22," ",""), "_", "")))) -> Baron_etal_1983_Table1 | L22: =J22 & "_" & SUBSTITUTE(SUBSTITUTE(SUBSTITUTE(D22,CHAR(160),"")," ",""),"_","") -> PMID%3A6663055_Table1 | M22: {=IFERROR(INDEX(AUTO_Public_TSV_FileList!$A$1:$A$1000,MATCH(TRUE(),EXACT(L22,IFERROR(_xlfn.TEXTBEFORE(AUTO_Public_TSV_FileList!$A$1:$A$1000,".tsv"),"")),0)),"notfound")} -> PMID%3A6663055_Table1.tsv | P22: FINISHED | U22: table | V22: NO - not digitized | X22: Stephan | Y22: Stephan | AE22: histological sections | AF22: Stephan | AH22: main olfactory bulb (MOB) volume | AI22: Insectivora, Scandentia & Primates | AJ22: primary | AK22: primary | AL22: volume
A23: Baron, G., Stephan, H., & Frahm, H. D. (1987). Comparison of brain structure volumes in Insectivora and Primates. VI. Paleocortical components. J Hirnforsch, 28(4), 463-477. http://www.ncbi.nlm.nih.gov/pubmed/3116076 | C23: PMID:3116076 | D23: Table 1 | E23: =RIGHT(A23,1) -> 6 | F23: =G23 & IF(H23<>"", "_" & H23, "_") & IF(I23<>"", "_" & I23, "_") & IF(B23<>"", "_" & B23, "") -> Baron_etal_1987 | G23: =SUBSTITUTE(SUBSTITUTE(_xlfn.TEXTBEFORE(A23,","), "-", ""), " ", "") -> Baron | H23: =_xlfn.LET( _xlpm.authors,_xlfn.TEXTBEFORE(A23," ("&I23&")"), _xlpm.hasAmp,ISNUMBER(SEARCH("&",_xlpm.authors)), _xlpm.commasBeforeAmp,IF(_xlpm.hasAmp,LEN(_xlfn.TEXTBEFORE(_xlpm.authors,"&"))-LEN(SUBSTITUTE(_xlfn.TEXTBEFORE(_xlpm.authors,"&"),",","")),0), IF(NOT(_xlpm.hasAmp),"",IF(_xlpm.commasBeforeAmp>2,"etal",TRIM(_xlfn.TEXTBEFORE(_xlfn.TEXTAFTER(_xlpm.authors,"& "),",")))) ) -> etal | I23: =_xlfn.TEXTBEFORE(_xlfn.TEXTAFTER(A23, "("), ")") -> 1987 | J23: =_xlfn.LET( _xlpm.doi,IF(C23<>"",C23,_xlfn.TEXTAFTER(A23,"https://doi.org/")), SUBSTITUTE( SUBSTITUTE( SUBSTITUTE( SUBSTITUTE( _xlpm.doi, "/","%2F"), ":","%3A"), "<","%3C"), ">","%3E") ) -> PMID%3A3116076 | K23: =TRIM(_xlfn.TEXTJOIN("_",FALSE(),F23,(SUBSTITUTE(SUBSTITUTE(D23," ",""), "_", "")))) -> Baron_etal_1987_Table1 | L23: =J23 & "_" & SUBSTITUTE(SUBSTITUTE(SUBSTITUTE(D23,CHAR(160),"")," ",""),"_","") -> PMID%3A3116076_Table1 | M23: {=IFERROR(INDEX(AUTO_Public_TSV_FileList!$A$1:$A$1000,MATCH(TRUE(),EXACT(L23,IFERROR(_xlfn.TEXTBEFORE(AUTO_Public_TSV_FileList!$A$1:$A$1000,".tsv"),"")),0)),"notfound")} -> PMID%3A3116076_Table1.tsv | P23: FINISHED | U23: table | V23: NO - not digitized | X23: Stephan | Y23: Stephan | AE23: histological sections | AF23: Stephan | AH23: brain-structure volume (Comparison series, Part) | AI23: Insectivora, Scandentia & Primates | AJ23: primary | AK23: primary | AL23: volume
A24: Baron, G., Stephan, H., & Frahm, H. D. (1990). Comparison of brain structure volumes in Insectivora and primates. IX. Trigeminal complex. J Hirnforsch, 31(2), 193-200. https://www.ncbi.nlm.nih.gov/pubmed/2358663 | C24: PMID:2358663 | D24: Table 1 | E24: =RIGHT(A24,1) -> 3 | F24: =G24 & IF(H24<>"", "_" & H24, "_") & IF(I24<>"", "_" & I24, "_") & IF(B24<>"", "_" & B24, "") -> Baron_etal_1990 | G24: =SUBSTITUTE(SUBSTITUTE(_xlfn.TEXTBEFORE(A24,","), "-", ""), " ", "") -> Baron | H24: =_xlfn.LET( _xlpm.authors,_xlfn.TEXTBEFORE(A24," ("&I24&")"), _xlpm.hasAmp,ISNUMBER(SEARCH("&",_xlpm.authors)), _xlpm.commasBeforeAmp,IF(_xlpm.hasAmp,LEN(_xlfn.TEXTBEFORE(_xlpm.authors,"&"))-LEN(SUBSTITUTE(_xlfn.TEXTBEFORE(_xlpm.authors,"&"),",","")),0), IF(NOT(_xlpm.hasAmp),"",IF(_xlpm.commasBeforeAmp>2,"etal",TRIM(_xlfn.TEXTBEFORE(_xlfn.TEXTAFTER(_xlpm.authors,"& "),",")))) ) -> etal | I24: =_xlfn.TEXTBEFORE(_xlfn.TEXTAFTER(A24, "("), ")") -> 1990 | J24: =_xlfn.LET( _xlpm.doi,IF(C24<>"",C24,_xlfn.TEXTAFTER(A24,"https://doi.org/")), SUBSTITUTE( SUBSTITUTE( SUBSTITUTE( SUBSTITUTE( _xlpm.doi, "/","%2F"), ":","%3A"), "<","%3C"), ">","%3E") ) -> PMID%3A2358663 | K24: =TRIM(_xlfn.TEXTJOIN("_",FALSE(),F24,(SUBSTITUTE(SUBSTITUTE(D24," ",""), "_", "")))) -> Baron_etal_1990_Table1 | L24: =J24 & "_" & SUBSTITUTE(SUBSTITUTE(SUBSTITUTE(D24,CHAR(160),"")," ",""),"_","") -> PMID%3A2358663_Table1 | M24: {=IFERROR(INDEX(AUTO_Public_TSV_FileList!$A$1:$A$1000,MATCH(TRUE(),EXACT(L24,IFERROR(_xlfn.TEXTBEFORE(AUTO_Public_TSV_FileList!$A$1:$A$1000,".tsv"),"")),0)),"notfound")} -> PMID%3A2358663_Table1.tsv | N24: Table 1 .IX. Trigeminal complex | P24: FINISHED | U24: table | V24: NO - not digitized | X24: Stephan | Y24: Stephan | AE24: histological sections | AF24: volumetry | AH24: trigeminal complex volume | AI24: Insectivora, Scandentia & Primates | AJ24: primary | AK24: primary | AL24: volume
A25: Baron, G., Stephan, H., & Frahm, H. D. (1996). Comparative Neurobiology in Chiroptera: Macromorphology, Brain Structures, Tables, and Atlases. Birkhäuser. | C25: ISBN:9783764353704 | D25: Table 10 | E25: =RIGHT(A25,1) -> . | F25: =G25 & IF(H25<>"", "_" & H25, "_") & IF(I25<>"", "_" & I25, "_") & IF(B25<>"", "_" & B25, "") -> Baron_etal_1996 | G25: =SUBSTITUTE(SUBSTITUTE(_xlfn.TEXTBEFORE(A25,","), "-", ""), " ", "") -> Baron | H25: =_xlfn.LET( _xlpm.authors,_xlfn.TEXTBEFORE(A25," ("&I25&")"), _xlpm.hasAmp,ISNUMBER(SEARCH("&",_xlpm.authors)), _xlpm.commasBeforeAmp,IF(_xlpm.hasAmp,LEN(_xlfn.TEXTBEFORE(_xlpm.authors,"&"))-LEN(SUBSTITUTE(_xlfn.TEXTBEFORE(_xlpm.authors,"&"),",","")),0), IF(NOT(_xlpm.hasAmp),"",IF(_xlpm.commasBeforeAmp>2,"etal",TRIM(_xlfn.TEXTBEFORE(_xlfn.TEXTAFTER(_xlpm.authors,"& "),",")))) ) -> etal | I25: =_xlfn.TEXTBEFORE(_xlfn.TEXTAFTER(A25, "("), ")") -> 1996 | J25: =_xlfn.LET( _xlpm.doi,IF(C25<>"",C25,_xlfn.TEXTAFTER(A25,"https://doi.org/")), SUBSTITUTE( SUBSTITUTE( SUBSTITUTE( SUBSTITUTE( _xlpm.doi, "/","%2F"), ":","%3A"), "<","%3C"), ">","%3E") ) -> ISBN%3A9783764353704 | K25: =TRIM(_xlfn.TEXTJOIN("_",FALSE(),F25,(SUBSTITUTE(SUBSTITUTE(D25," ",""), "_", "")))) -> Baron_etal_1996_Table10 | L25: =J25 & "_" & SUBSTITUTE(SUBSTITUTE(SUBSTITUTE(D25,CHAR(160),"")," ",""),"_","") -> ISBN%3A9783764353704_Table10 | M25: {=IFERROR(INDEX(AUTO_Public_TSV_FileList!$A$1:$A$1000,MATCH(TRUE(),EXACT(L25,IFERROR(_xlfn.TEXTBEFORE(AUTO_Public_TSV_FileList!$A$1:$A$1000,".tsv"),"")),0)),"notfound")} -> ISBN%3A9783764353704_Table10.tsv | O25: BUILT 2026-08-15: 272 species; five fundamental brain-part volumes. | P25: FINISHED | R25: Baron_etal_1996_Table10_snapshot.csv | S25: Source values preserved; seven blank n values retained as missing. | AJ25: primary | AK25: primary
A26: Baron, G., Stephan, H., & Frahm, H. D. (1996). Comparative Neurobiology in Chiroptera: Macromorphology, Brain Structures, Tables, and Atlases. Birkhäuser. | C26: ISBN:9783764353704 | D26: Table 13 | E26: =RIGHT(A26,1) -> . | F26: =G26 & IF(H26<>"", "_" & H26, "_") & IF(I26<>"", "_" & I26, "_") & IF(B26<>"", "_" & B26, "") -> Baron_etal_1996 | G26: =SUBSTITUTE(SUBSTITUTE(_xlfn.TEXTBEFORE(A26,","), "-", ""), " ", "") -> Baron | H26: =_xlfn.LET( _xlpm.authors,_xlfn.TEXTBEFORE(A26," ("&I26&")"), _xlpm.hasAmp,ISNUMBER(SEARCH("&",_xlpm.authors)), _xlpm.commasBeforeAmp,IF(_xlpm.hasAmp,LEN(_xlfn.TEXTBEFORE(_xlpm.authors,"&"))-LEN(SUBSTITUTE(_xlfn.TEXTBEFORE(_xlpm.authors,"&"),",","")),0), IF(NOT(_xlpm.hasAmp),"",IF(_xlpm.commasBeforeAmp>2,"etal",TRIM(_xlfn.TEXTBEFORE(_xlfn.TEXTAFTER(_xlpm.authors,"& "),",")))) ) -> etal | I26: =_xlfn.TEXTBEFORE(_xlfn.TEXTAFTER(A26, "("), ")") -> 1996 | J26: =_xlfn.LET( _xlpm.doi,IF(C26<>"",C26,_xlfn.TEXTAFTER(A26,"https://doi.org/")), SUBSTITUTE( SUBSTITUTE( SUBSTITUTE( SUBSTITUTE( _xlpm.doi, "/","%2F"), ":","%3A"), "<","%3C"), ">","%3E") ) -> ISBN%3A9783764353704 | K26: =TRIM(_xlfn.TEXTJOIN("_",FALSE(),F26,(SUBSTITUTE(SUBSTITUTE(D26," ",""), "_", "")))) -> Baron_etal_1996_Table13 | L26: =J26 & "_" & SUBSTITUTE(SUBSTITUTE(SUBSTITUTE(D26,CHAR(160),"")," ",""),"_","") -> ISBN%3A9783764353704_Table13 | M26: {=IFERROR(INDEX(AUTO_Public_TSV_FileList!$A$1:$A$1000,MATCH(TRUE(),EXACT(L26,IFERROR(_xlfn.TEXTBEFORE(AUTO_Public_TSV_FileList!$A$1:$A$1000,".tsv"),"")),0)),"notfound")} -> notfound | N26: Volumes (in mm3) of the sensory trigeminal complex and of the tractus solitarii and funicular nuclei of the medulla oblongata | O26: Printed columns: TR (complexus sensorius trigeminalis), TSO (nucleus tractus solitarii), FUN (funicular nuclei), FGR (nucleus fascicularis gracilis; the key abbreviates it FOR), FCM (nucleus fascicularis cuneatus medialis), FCE (nucleus fascicularis cuneatus externus). Size indices are Tables 14-15 — do not transcribe. | P26: VERIFIED CITED PAPER — RELEVANT ITEM IDENTIFIED | T26: Book | U26: PDF table | V26: baron_etal_1996 book Comparative Neurobiology.pdf (pp. 74-78) | X26: Stephan | Y26: Stephan | Z26: trigeminal and somatosensory brainstem nucleus volumes | AA26: Not yet transcribed. PDF pages 74-78; N = 150 printed rows. Extend Baron_etal_1996_extract_snapshots.py, which already reads this PDF's text layer for Tables 10 and 32 with an explicit literal OCR-repair table. | AB26: Structure list, species count and the table's size/index role confirmed against the book's own Table 1 key (PDF pp. 264-265) and the printed column header, 2026-08-31. | AC26: Inherits the whole-source merge gate already recorded for Tables 10/32: seven historical taxon concepts in MANUAL_REVIEW, and source rows that collapse to the same species must be averaged within the item before Tier-1 recency resolution. Resolving that gate once unblocks every Baron item, so build order need not wait on it. | AE26: histological sections | AF26: Stephan | AG26: bats | AH26: trigeminal and somatosensory brainstem nucleus volumes | AI26: Mammals | AJ26: primary | AK26: primary | AL26: volume | AM26: high | AN26: Build. A somatosensory brainstem block with no equivalent in any held source.
A27: Baron, G., Stephan, H., & Frahm, H. D. (1996). Comparative Neurobiology in Chiroptera: Macromorphology, Brain Structures, Tables, and Atlases. Birkhäuser. | C27: ISBN:9783764353704 | D27: Table 16 | E27: =RIGHT(A27,1) -> . | F27: =G27 & IF(H27<>"", "_" & H27, "_") & IF(I27<>"", "_" & I27, "_") & IF(B27<>"", "_" & B27, "") -> Baron_etal_1996 | G27: =SUBSTITUTE(SUBSTITUTE(_xlfn.TEXTBEFORE(A27,","), "-", ""), " ", "") -> Baron | H27: =_xlfn.LET( _xlpm.authors,_xlfn.TEXTBEFORE(A27," ("&I27&")"), _xlpm.hasAmp,ISNUMBER(SEARCH("&",_xlpm.authors)), _xlpm.commasBeforeAmp,IF(_xlpm.hasAmp,LEN(_xlfn.TEXTBEFORE(_xlpm.authors,"&"))-LEN(SUBSTITUTE(_xlfn.TEXTBEFORE(_xlpm.authors,"&"),",","")),0), IF(NOT(_xlpm.hasAmp),"",IF(_xlpm.commasBeforeAmp>2,"etal",TRIM(_xlfn.TEXTBEFORE(_xlfn.TEXTAFTER(_xlpm.authors,"& "),",")))) ) -> etal | I27: =_xlfn.TEXTBEFORE(_xlfn.TEXTAFTER(A27, "("), ")") -> 1996 | J27: =_xlfn.LET( _xlpm.doi,IF(C27<>"",C27,_xlfn.TEXTAFTER(A27,"https://doi.org/")), SUBSTITUTE( SUBSTITUTE( SUBSTITUTE( SUBSTITUTE( _xlpm.doi, "/","%2F"), ":","%3A"), "<","%3C"), ">","%3E") ) -> ISBN%3A9783764353704 | K27: =TRIM(_xlfn.TEXTJOIN("_",FALSE(),F27,(SUBSTITUTE(SUBSTITUTE(D27," ",""), "_", "")))) -> Baron_etal_1996_Table16 | L27: =J27 & "_" & SUBSTITUTE(SUBSTITUTE(SUBSTITUTE(D27,CHAR(160),"")," ",""),"_","") -> ISBN%3A9783764353704_Table16 | M27: {=IFERROR(INDEX(AUTO_Public_TSV_FileList!$A$1:$A$1000,MATCH(TRUE(),EXACT(L27,IFERROR(_xlfn.TEXTBEFORE(AUTO_Public_TSV_FileList!$A$1:$A$1000,".tsv"),"")),0)),"notfound")} -> notfound | N27: Volumes of some motor and relay nuclei of the medulla oblongata | O27: Printed columns: mot X (nucleus dorsalis motorius nervi vagi), mot XII (nucleus nervi hypoglossi), REL (nucleus reticularis lateralis), INO (complexus olivaris inferior), PRP (nucleus prepositus hypoglossi). The book's Table 1 key also assigns the subdivided OBL to this table. Size indices are Tables 17-18 — do not transcribe. | P27: VERIFIED CITED PAPER — RELEVANT ITEM IDENTIFIED | T27: Book | U27: PDF table | V27: baron_etal_1996 book Comparative Neurobiology.pdf (pp. 86-90) | X27: Stephan | Y27: Stephan | Z27: medullary motor and relay nucleus volumes | AA27: Not yet transcribed. PDF pages 86-90; N = 150 printed rows. Extend Baron_etal_1996_extract_snapshots.py, which already reads this PDF's text layer for Tables 10 and 32 with an explicit literal OCR-repair table. | AB27: Structure list, species count and the table's size/index role confirmed against the book's own Table 1 key (PDF pp. 264-265) and the printed column header, 2026-08-31. | AC27: Inherits the whole-source merge gate already recorded for Tables 10/32: seven historical taxon concepts in MANUAL_REVIEW, and source rows that collapse to the same species must be averaged within the item before Tier-1 recency resolution. Resolving that gate once unblocks every Baron item, so build order need not wait on it. | AE27: histological sections | AF27: Stephan | AG27: bats | AH27: medullary motor and relay nucleus volumes | AI27: Mammals | AJ27: primary | AK27: primary | AL27: volume | AM27: high | AN27: Build. Motor-system brainstem nuclei; relevant to the M1 / motor-output strand and not held elsewhere.
A28: Baron, G., Stephan, H., & Frahm, H. D. (1996). Comparative Neurobiology in Chiroptera: Macromorphology, Brain Structures, Tables, and Atlases. Birkhäuser. | C28: ISBN:9783764353704 | D28: Table 19 | E28: =RIGHT(A28,1) -> . | F28: =G28 & IF(H28<>"", "_" & H28, "_") & IF(I28<>"", "_" & I28, "_") & IF(B28<>"", "_" & B28, "") -> Baron_etal_1996 | G28: =SUBSTITUTE(SUBSTITUTE(_xlfn.TEXTBEFORE(A28,","), "-", ""), " ", "") -> Baron | H28: =_xlfn.LET( _xlpm.authors,_xlfn.TEXTBEFORE(A28," ("&I28&")"), _xlpm.hasAmp,ISNUMBER(SEARCH("&",_xlpm.authors)), _xlpm.commasBeforeAmp,IF(_xlpm.hasAmp,LEN(_xlfn.TEXTBEFORE(_xlpm.authors,"&"))-LEN(SUBSTITUTE(_xlfn.TEXTBEFORE(_xlpm.authors,"&"),",","")),0), IF(NOT(_xlpm.hasAmp),"",IF(_xlpm.commasBeforeAmp>2,"etal",TRIM(_xlfn.TEXTBEFORE(_xlfn.TEXTAFTER(_xlpm.authors,"& "),",")))) ) -> etal | I28: =_xlfn.TEXTBEFORE(_xlfn.TEXTAFTER(A28, "("), ")") -> 1996 | J28: =_xlfn.LET( _xlpm.doi,IF(C28<>"",C28,_xlfn.TEXTAFTER(A28,"https://doi.org/")), SUBSTITUTE( SUBSTITUTE( SUBSTITUTE( SUBSTITUTE( _xlpm.doi, "/","%2F"), ":","%3A"), "<","%3C"), ">","%3E") ) -> ISBN%3A9783764353704 | K28: =TRIM(_xlfn.TEXTJOIN("_",FALSE(),F28,(SUBSTITUTE(SUBSTITUTE(D28," ",""), "_", "")))) -> Baron_etal_1996_Table19 | L28: =J28 & "_" & SUBSTITUTE(SUBSTITUTE(SUBSTITUTE(D28,CHAR(160),"")," ",""),"_","") -> ISBN%3A9783764353704_Table19 | M28: {=IFERROR(INDEX(AUTO_Public_TSV_FileList!$A$1:$A$1000,MATCH(TRUE(),EXACT(L28,IFERROR(_xlfn.TEXTBEFORE(AUTO_Public_TSV_FileList!$A$1:$A$1000,".tsv"),"")),0)),"notfound")} -> notfound | N28: Volumes of the vestibular nuclei of the medulla oblongata | O28: Printed columns: VC (vestibular complex), VM (medialis), VI (inferior), VL (lateralis), VS (superior). Size indices are Tables 20-21 — do not transcribe. | P28: VERIFIED CITED PAPER — RELEVANT ITEM IDENTIFIED | T28: Book | U28: PDF table | V28: baron_etal_1996 book Comparative Neurobiology.pdf (pp. 98-102) | X28: Stephan | Y28: Stephan | Z28: vestibular nucleus volumes | AA28: Not yet transcribed. PDF pages 98-102; N = 150 printed rows. Extend Baron_etal_1996_extract_snapshots.py, which already reads this PDF's text layer for Tables 10 and 32 with an explicit literal OCR-repair table. | AB28: Structure list, species count and the table's size/index role confirmed against the book's own Table 1 key (PDF pp. 264-265) and the printed column header, 2026-08-31. | AC28: Inherits the whole-source merge gate already recorded for Tables 10/32: seven historical taxon concepts in MANUAL_REVIEW, and source rows that collapse to the same species must be averaged within the item before Tier-1 recency resolution. Resolving that gate once unblocks every Baron item, so build order need not wait on it. | AE28: histological sections | AF28: Stephan | AG28: bats | AH28: vestibular nucleus volumes | AI28: Mammals | AJ28: primary | AK28: primary | AL28: volume | AM28: high | AN28: Build. Direct Chiroptera counterpart of the built Baron_etal_1988_Table1 vestibular complex for Insectivora, Scandentia and Primates — same team, same five subdivisions, so the two can sit in one vestibular product.
A29: Baron, G., Stephan, H., & Frahm, H. D. (1996). Comparative Neurobiology in Chiroptera: Macromorphology, Brain Structures, Tables, and Atlases. Birkhäuser. | C29: ISBN:9783764353704 | D29: Table 2 | E29: =RIGHT(A29,1) -> . | F29: =G29 & IF(H29<>"", "_" & H29, "_") & IF(I29<>"", "_" & I29, "_") & IF(B29<>"", "_" & B29, "") -> Baron_etal_1996 | G29: =SUBSTITUTE(SUBSTITUTE(_xlfn.TEXTBEFORE(A29,","), "-", ""), " ", "") -> Baron | H29: =_xlfn.LET( _xlpm.authors,_xlfn.TEXTBEFORE(A29," ("&I29&")"), _xlpm.hasAmp,ISNUMBER(SEARCH("&",_xlpm.authors)), _xlpm.commasBeforeAmp,IF(_xlpm.hasAmp,LEN(_xlfn.TEXTBEFORE(_xlpm.authors,"&"))-LEN(SUBSTITUTE(_xlfn.TEXTBEFORE(_xlpm.authors,"&"),",","")),0), IF(NOT(_xlpm.hasAmp),"",IF(_xlpm.commasBeforeAmp>2,"etal",TRIM(_xlfn.TEXTBEFORE(_xlfn.TEXTAFTER(_xlpm.authors,"& "),",")))) ) -> etal | I29: =_xlfn.TEXTBEFORE(_xlfn.TEXTAFTER(A29, "("), ")") -> 1996 | J29: =_xlfn.LET( _xlpm.doi,IF(C29<>"",C29,_xlfn.TEXTAFTER(A29,"https://doi.org/")), SUBSTITUTE( SUBSTITUTE( SUBSTITUTE( SUBSTITUTE( _xlpm.doi, "/","%2F"), ":","%3A"), "<","%3C"), ">","%3E") ) -> ISBN%3A9783764353704 | K29: =TRIM(_xlfn.TEXTJOIN("_",FALSE(),F29,(SUBSTITUTE(SUBSTITUTE(D29," ",""), "_", "")))) -> Baron_etal_1996_Table2 | L29: =J29 & "_" & SUBSTITUTE(SUBSTITUTE(SUBSTITUTE(D29,CHAR(160),"")," ",""),"_","") -> ISBN%3A9783764353704_Table2 | M29: {=IFERROR(INDEX(AUTO_Public_TSV_FileList!$A$1:$A$1000,MATCH(TRUE(),EXACT(L29,IFERROR(_xlfn.TEXTBEFORE(AUTO_Public_TSV_FileList!$A$1:$A$1000,".tsv"),"")),0)),"notfound")} -> notfound | N29: Linear measures of brains in mm | O29: Printed columns: n, BL (brain length), HL (hemisphere length), HW (hemisphere width), HH (hemisphere height), a second n, and CCL (corpus callosum length). Species means over the printed n. Proportion indices derived from these measures are Tables 3 and 4 — do not transcribe those. | P29: VERIFIED CITED PAPER — RELEVANT ITEM IDENTIFIED | T29: Book | U29: PDF table | V29: baron_etal_1996 book Comparative Neurobiology.pdf (pp. 4-11) | X29: Stephan | Y29: Stephan | Z29: linear brain measures (mm); corpus callosum length | AA29: Not yet transcribed. PDF pages 4-11; N = 303 printed rows. Extend Baron_etal_1996_extract_snapshots.py, which already reads this PDF's text layer for Tables 10 and 32 with an explicit literal OCR-repair table. | AB29: Structure list, species count and the table's size/index role confirmed against the book's own Table 1 key (PDF pp. 264-265) and the printed column header, 2026-08-31. | AC29: Inherits the whole-source merge gate already recorded for Tables 10/32: seven historical taxon concepts in MANUAL_REVIEW, and source rows that collapse to the same species must be averaged within the item before Tier-1 recency resolution. Resolving that gate once unblocks every Baron item, so build order need not wait on it. | AE29: histological sections | AF29: Stephan | AG29: bats | AH29: linear brain measures (mm); corpus callosum length | AI29: Mammals | AJ29: primary | AK29: primary | AL29: linear measure (mm) | AM29: medium | AN29: Build. The only linear/gross-morphology block in the book and not held anywhere else in the repo. The second n column applies to CCL only and is often blank; keep both n columns as separate fields.
