Workbook

Sheet Sheet1
A1: Citation (APA 7th-Annotated) | B1: sequence | D1: DOI if different from article or doi Alt | E1: Item number | F1: end | G1: Publication name | H1: 1st Author | I1: other author(s) | J1: year | K1: DOI (or Alt) | L1: Item name | M1: Item encoded | N1: Public TSV match from AUTO_Public_TSV_FileList (generated by _tools/file_list.R; do not edit manually) | O1: Item full original title | P1: Note about item | Q1: Progress stage | R1: Online Database | S1: Snapshot | T1: Adjustment made | U1: Data readable file, can use this | V1: Source Type | W1: Source format | X1: Source URL direct access | Y1: Source URL link | Z1: Team | AA1: Collection | AB1: Possible Traits | AC1: Note | AD1: Flags pre-addressed | AE1: Flags possible | AF1: Flags active (skips) | AG1: Sample type | AH1: Method | AI1: Subcategory | AJ1: Main Trait(s) | AK1: Taxon group | AL1: Source type | AM1: Data role (primary/secondary/both) | AN1: Measure type | AO1: entry note | AP1: relevence | AQ1: recommendation
A2: Andelin, A. K., Olavarria, J. F., Fine, I., Taber, E. N., Schwartz, D., Kroenke, C. D., & Stevens, A. A. (2019). The Effect of Onset Age of Visual Deprivation on Visual Cortex Surface Area Across-Species. Cereb Cortex, 29(10), 4321-4333. https://doi.org/10.1093/cercor/bhy315 | E2: Table 4 | F2: =RIGHT(A2,1) -> 5 | G2: =H2 & IF(I2<>"", "_" & I2, "_") & IF(J2<>"", "_" & J2, "_") & IF(B2<>"", "_" & B2, "") -> Andelin_etal_2019 | H2: =SUBSTITUTE(SUBSTITUTE(_xlfn.TEXTBEFORE(A2,","), "-", ""), " ", "") -> Andelin | I2: =_xlfn.LET( _xlpm.authors,_xlfn.TEXTBEFORE(A2," ("&J2&")"), _xlpm.hasAmp,ISNUMBER(SEARCH("&",_xlpm.authors)), _xlpm.commasBeforeAmp,IF(_xlpm.hasAmp,LEN(_xlfn.TEXTBEFORE(_xlpm.authors,"&"))-LEN(SUBSTITUTE(_xlfn.TEXTBEFORE(_xlpm.authors,"&"),",","")),0), IF(NOT(_xlpm.hasAmp),"",IF(_xlpm.commasBeforeAmp>2,"etal",TRIM(_xlfn.TEXTBEFORE(_xlfn.TEXTAFTER(_xlpm.authors,"& "),",")))) ) -> etal | J2: =_xlfn.TEXTBEFORE(_xlfn.TEXTAFTER(A2, "("), ")") -> 2019 | K2: =_xlfn.LET( _xlpm.doi,IF(D2<>"",D2,_xlfn.TEXTAFTER(A2,"https://doi.org/")), SUBSTITUTE( SUBSTITUTE( SUBSTITUTE( SUBSTITUTE( _xlpm.doi, "/","%2F"), ":","%3A"), "<","%3C"), ">","%3E") ) -> 10.1093%2Fcercor%2Fbhy315 | L2: =TRIM(_xlfn.TEXTJOIN("_",FALSE(),G2,(SUBSTITUTE(SUBSTITUTE(E2," ",""), "_", "")))) -> Andelin_etal_2019_Table4 | M2: =K2 & "_" & SUBSTITUTE(SUBSTITUTE(SUBSTITUTE(E2,CHAR(160),"")," ",""),"_","") -> 10.1093%2Fcercor%2Fbhy315_Table4 | N2: {=IFERROR(INDEX(AUTO_Public_TSV_FileList!$A$1:$A$1000,MATCH(TRUE(),EXACT(M2,IFERROR(_xlfn.TEXTBEFORE(AUTO_Public_TSV_FileList!$A$1:$A$1000,".tsv"),"")),0)),"notfound")} -> 10.1093%2Fcercor%2Fbhy315_Table4.tsv | Q2: FINISHED | W2: table | AK2: review | AM2: review | AN2: review
A3: Armstrong, E. (1979). Quantitative comparison of the hominoid thalamus. I. Specific sensory relay nuclei. Am J Phys Anthropol, 51(3), 365-382. https://doi.org/10.1002/ajpa.1330510308 | E3: Tables 1-9 | F3: =RIGHT(A3,1) -> 8 | G3: =H3 & IF(I3<>"", "_" & I3, "_") & IF(J3<>"", "_" & J3, "_") & IF(B3<>"", "_" & B3, "") -> Armstrong__1979 | H3: =SUBSTITUTE(SUBSTITUTE(_xlfn.TEXTBEFORE(A3,","), "-", ""), " ", "") -> Armstrong | I3: =_xlfn.LET(_xlpm.authors,_xlfn.TEXTBEFORE(A3," ("&J3&")"),_xlpm.hasAmp,ISNUMBER(SEARCH("&",_xlpm.authors)),_xlpm.commasBeforeAmp,IF(_xlpm.hasAmp,LEN(_xlfn.TEXTBEFORE(_xlpm.authors,"&"))-LEN(SUBSTITUTE(_xlfn.TEXTBEFORE(_xlpm.authors,"&"),",","")),0),IF(NOT(_xlpm.hasAmp),"",IF(_xlpm.commasBeforeAmp>2,"etal",TRIM(_xlfn.TEXTBEFORE(_xlfn.TEXTAFTER(_xlpm.authors,"& "),","))))) | J3: =_xlfn.TEXTBEFORE(_xlfn.TEXTAFTER(A3, "("), ")") -> 1979 | K3: =_xlfn.LET(_xlpm.doi,IF(D3<>"",D3,_xlfn.TEXTAFTER(A3,"https://doi.org/")),SUBSTITUTE(SUBSTITUTE(SUBSTITUTE(SUBSTITUTE(_xlpm.doi,"/","%2F"),":","%3A"),"<","%3C"),">","%3E")) -> 10.1002%2Fajpa.1330510308 | L3: =TRIM(_xlfn.TEXTJOIN("_",FALSE(),G3,(SUBSTITUTE(SUBSTITUTE(E3," ",""), "_", "")))) -> Armstrong__1979_Tables1-9 | M3: =K3 & "_" & SUBSTITUTE(SUBSTITUTE(SUBSTITUTE(E3,CHAR(160),"")," ",""),"_","") -> 10.1002%2Fajpa.1330510308_Tables1-9 | N3: =IFERROR(INDEX(AUTO_Public_TSV_FileList!$A$1:$A$1000,MATCH(TRUE(),EXACT(M3,IFERROR(_xlfn.TEXTBEFORE(AUTO_Public_TSV_FileList!$A$1:$A$1000,".tsv"),"")),0)),"notfound") -> notfound | O3: Tables 1-9. Hominoid thalamic sensory-relay nucleus volumes, neuronal densities and numbers, and neuronal-volume distributions | P3: Primary mixed-datatype series. Table 1 provides LGB, MGBp and VB volumes plus percent of dorsal thalamus; Tables 2-4 density; Table 5 LGB subcomponent volumes; Table 6 neuron counts; Tables 7-9 neuronal perikaryal-volume distributions. Split during build. | Q3: FINISHED | R3: EndNote | V3: pdf | W3: tables | X3: https://doi.org/10.1002/ajpa.1330510308 | Y3: https://doi.org/10.1002/ajpa.1330510308 | Z3: Armstrong | AB3: LGB/LGBd; MGB parvocellular; ventrobasal complex; dorsal thalamus proportion; neuronal density; neuron number; neuronal perikaryal volume | AC3: Seven hominoid specimens in Table 1; later tables use subsets. Keep specimen-level records and separate regional volume, cell density/count, and cell-size outputs. | AE3: mixed datatypes; specimen abbreviations require a specimen crosswalk; some literature-comparison rows are secondary | AG3: individual hominoid specimens (gibbons, gorilla, chimpanzee, humans) | AH3: histological volumetry; neuronal density/count estimation; neuronal perikaryal morphometry | AI3: thalamic sensory relay nuclei | AJ3: regional volumes; neuronal density and number; neuronal size | AK3: Hominoids | AL3: primary + cited secondary comparisons | AM3: both | AN3: volume + cell density/count + neuronal perikaryal volume
A4: Ashwell, K. W. S. (2020). Quantitative analysis of cerebellar morphology in monotreme, metatherian and eutherian mammals. Zoology (Jena), 139, 125753. https://doi.org/10.1016/j.zool.2020.125753 | E4: Supplementary Table | F4: =RIGHT(A4,1) -> 3 | G4: =H4 & IF(I4<>"", "_" & I4, "_") & IF(J4<>"", "_" & J4, "_") & IF(B4<>"", "_" & B4, "") -> Ashwell__2020 | H4: =SUBSTITUTE(SUBSTITUTE(_xlfn.TEXTBEFORE(A4,","), "-", ""), " ", "") -> Ashwell | I4: =_xlfn.LET( _xlpm.authors,_xlfn.TEXTBEFORE(A4," ("&J4&")"), _xlpm.hasAmp,ISNUMBER(SEARCH("&",_xlpm.authors)), _xlpm.commasBeforeAmp,IF(_xlpm.hasAmp,LEN(_xlfn.TEXTBEFORE(_xlpm.authors,"&"))-LEN(SUBSTITUTE(_xlfn.TEXTBEFORE(_xlpm.authors,"&"),",","")),0), IF(NOT(_xlpm.hasAmp),"",IF(_xlpm.commasBeforeAmp>2,"etal",TRIM(_xlfn.TEXTBEFORE(_xlfn.TEXTAFTER(_xlpm.authors,"& "),",")))) ) | J4: =_xlfn.TEXTBEFORE(_xlfn.TEXTAFTER(A4, "("), ")") -> 2020 | K4: =_xlfn.LET( _xlpm.doi,IF(D4<>"",D4,_xlfn.TEXTAFTER(A4,"https://doi.org/")), SUBSTITUTE( SUBSTITUTE( SUBSTITUTE( SUBSTITUTE( _xlpm.doi, "/","%2F"), ":","%3A"), "<","%3C"), ">","%3E") ) -> 10.1016%2Fj.zool.2020.125753 | L4: =TRIM(_xlfn.TEXTJOIN("_",FALSE(),G4,(SUBSTITUTE(SUBSTITUTE(E4," ",""), "_", "")))) -> Ashwell__2020_SupplementaryTable | M4: =K4 & "_" & SUBSTITUTE(SUBSTITUTE(SUBSTITUTE(E4,CHAR(160),"")," ",""),"_","") -> 10.1016%2Fj.zool.2020.125753_SupplementaryTable | N4: {=IFERROR(INDEX(AUTO_Public_TSV_FileList!$A$1:$A$1000,MATCH(TRUE(),EXACT(M4,IFERROR(_xlfn.TEXTBEFORE(AUTO_Public_TSV_FileList!$A$1:$A$1000,".tsv"),"")),0)),"notfound")} -> 10.1016%2Fj.zool.2020.125753_SupplementaryTable.tsv | O4: Supplementary Table. Cerebellar Morphology Data | Q4: FINISHED | Z4: Ashwell
A5: Avelino-de-Souza, K., Patzke, N., Karlsson, K. A. E., Manger, P. R., & Herculano-Houzel, S. (2025). Cellular Composition of the Brain of a Northern Minke Whale. J Comp Neurol, 533(9), e70089. https://doi.org/10.1002/cne.70089 | E5: TABLE 1 | F5: =RIGHT(A5,1) -> 9 | G5: =H5 & IF(I5<>"", "_" & I5, "_") & IF(J5<>"", "_" & J5, "_") & IF(B5<>"", "_" & B5, "") -> AvelinodeSouza_etal_2025 | H5: =SUBSTITUTE(SUBSTITUTE(_xlfn.TEXTBEFORE(A5,","), "-", ""), " ", "") -> AvelinodeSouza | I5: =_xlfn.LET( _xlpm.authors,_xlfn.TEXTBEFORE(A5," ("&J5&")"), _xlpm.hasAmp,ISNUMBER(SEARCH("&",_xlpm.authors)), _xlpm.commasBeforeAmp,IF(_xlpm.hasAmp,LEN(_xlfn.TEXTBEFORE(_xlpm.authors,"&"))-LEN(SUBSTITUTE(_xlfn.TEXTBEFORE(_xlpm.authors,"&"),",","")),0), IF(NOT(_xlpm.hasAmp),"",IF(_xlpm.commasBeforeAmp>2,"etal",TRIM(_xlfn.TEXTBEFORE(_xlfn.TEXTAFTER(_xlpm.authors,"& "),",")))) ) -> etal | J5: =_xlfn.TEXTBEFORE(_xlfn.TEXTAFTER(A5, "("), ")") -> 2025 | K5: =_xlfn.LET( _xlpm.doi,IF(D5<>"",D5,_xlfn.TEXTAFTER(A5,"https://doi.org/")), SUBSTITUTE( SUBSTITUTE( SUBSTITUTE( SUBSTITUTE( _xlpm.doi, "/","%2F"), ":","%3A"), "<","%3C"), ">","%3E") ) -> 10.1002%2Fcne.70089 | L5: =TRIM(_xlfn.TEXTJOIN("_",FALSE(),G5,(SUBSTITUTE(SUBSTITUTE(E5," ",""), "_", "")))) -> AvelinodeSouza_etal_2025_TABLE1 | M5: =K5 & "_" & SUBSTITUTE(SUBSTITUTE(SUBSTITUTE(E5,CHAR(160),"")," ",""),"_","") -> 10.1002%2Fcne.70089_TABLE1 | N5: {=IFERROR(INDEX(AUTO_Public_TSV_FileList!$A$1:$A$1000,MATCH(TRUE(),EXACT(M5,IFERROR(_xlfn.TEXTBEFORE(AUTO_Public_TSV_FileList!$A$1:$A$1000,".tsv"),"")),0)),"notfound")} -> 10.1002%2Fcne.70089_TABLE1.tsv | O5: Table 1. Cellular composition of the brain of a Northern minke whale (Balaenoptera acutorostrata) | Q5: FINISHED | R5: added | S5: AvelinodeSouza_etal_2025_TABLE1_snapshot.csv | T5: Y | U5: AvelinodeSouza_etal_2025_TABLE1.csv | V5: pdf | W5: table | X5: https://onlinelibrary.wiley.com/doi/10.1002/cne.70089 | Y5: https://doi.org/10.1002/cne.70089 | Z5: HH | AH5: isotropic fractionator | AI5: placental mammals | AJ5: neuron number | AK5: Cetaceans & other placental mammals | AL5: primary | AM5: primary | AN5: cell count (isotropic fractionator)
A6: Baker, J., Barton, R. A., & Venditti, C. (2025). Human dexterity and brains evolved hand in hand. Communications Biology, 8(1). https://doi.org/10.1038/s42003-025-08686-5 | E6: Supplementary Data 1 | F6: =RIGHT(A6,1) -> 5 | G6: =H6 & IF(I6<>"", "_" & I6, "_") & IF(J6<>"", "_" & J6, "_") & IF(B6<>"", "_" & B6, "") -> Baker_etal_2025 | H6: =SUBSTITUTE(SUBSTITUTE(_xlfn.TEXTBEFORE(A6,","), "-", ""), " ", "") -> Baker | I6: =_xlfn.LET( _xlpm.authors,_xlfn.TEXTBEFORE(A6," ("&J6&")"), _xlpm.hasAmp,ISNUMBER(SEARCH("&",_xlpm.authors)), _xlpm.commasBeforeAmp,IF(_xlpm.hasAmp,LEN(_xlfn.TEXTBEFORE(_xlpm.authors,"&"))-LEN(SUBSTITUTE(_xlfn.TEXTBEFORE(_xlpm.authors,"&"),",","")),0), IF(NOT(_xlpm.hasAmp),"",IF(_xlpm.commasBeforeAmp>2,"etal",TRIM(_xlfn.TEXTBEFORE(_xlfn.TEXTAFTER(_xlpm.authors,"& "),",")))) ) -> etal | J6: =_xlfn.TEXTBEFORE(_xlfn.TEXTAFTER(A6, "("), ")") -> 2025 | K6: =_xlfn.LET( _xlpm.doi,IF(D6<>"",D6,_xlfn.TEXTAFTER(A6,"https://doi.org/")), SUBSTITUTE( SUBSTITUTE( SUBSTITUTE( SUBSTITUTE( _xlpm.doi, "/","%2F"), ":","%3A"), "<","%3C"), ">","%3E") ) -> 10.1038%2Fs42003-025-08686-5 | L6: =TRIM(_xlfn.TEXTJOIN("_",FALSE(),G6,(SUBSTITUTE(SUBSTITUTE(E6," ",""), "_", "")))) -> Baker_etal_2025_SupplementaryData1 | M6: =K6 & "_" & SUBSTITUTE(SUBSTITUTE(SUBSTITUTE(E6,CHAR(160),"")," ",""),"_","") -> 10.1038%2Fs42003-025-08686-5_SupplementaryData1 | N6: {=IFERROR(INDEX(AUTO_Public_TSV_FileList!$A$1:$A$1000,MATCH(TRUE(),EXACT(M6,IFERROR(_xlfn.TEXTBEFORE(AUTO_Public_TSV_FileList!$A$1:$A$1000,".tsv"),"")),0)),"notfound")} -> 10.1038%2Fs42003-025-08686-5_SupplementaryData1.tsv
A7: Balzeau, A., Holloway, R. L., & Grimaud-Herve, D. (2012). Variations and asymmetries in regional brain surface in the genus Homo. J Hum Evol, 62(6), 696-706. https://doi.org/10.1016/j.jhevol.2012.03.007 | E7: Table 2 | F7: =RIGHT(A7,1) -> 7 | G7: =H7 & IF(I7<>"", "_" & I7, "_") & IF(J7<>"", "_" & J7, "_") & IF(B7<>"", "_" & B7, "") -> Balzeau_etal_2012 | H7: =SUBSTITUTE(SUBSTITUTE(_xlfn.TEXTBEFORE(A7,","), "-", ""), " ", "") -> Balzeau | I7: =_xlfn.LET( _xlpm.authors,_xlfn.TEXTBEFORE(A7," ("&J7&")"), _xlpm.hasAmp,ISNUMBER(SEARCH("&",_xlpm.authors)), _xlpm.commasBeforeAmp,IF(_xlpm.hasAmp,LEN(_xlfn.TEXTBEFORE(_xlpm.authors,"&"))-LEN(SUBSTITUTE(_xlfn.TEXTBEFORE(_xlpm.authors,"&"),",","")),0), IF(NOT(_xlpm.hasAmp),"",IF(_xlpm.commasBeforeAmp>2,"etal",TRIM(_xlfn.TEXTBEFORE(_xlfn.TEXTAFTER(_xlpm.authors,"& "),",")))) ) -> etal | J7: =_xlfn.TEXTBEFORE(_xlfn.TEXTAFTER(A7, "("), ")") -> 2012 | K7: =_xlfn.LET( _xlpm.doi,IF(D7<>"",D7,_xlfn.TEXTAFTER(A7,"https://doi.org/")), SUBSTITUTE( SUBSTITUTE( SUBSTITUTE( SUBSTITUTE( _xlpm.doi, "/","%2F"), ":","%3A"), "<","%3C"), ">","%3E") ) -> 10.1016%2Fj.jhevol.2012.03.007 | L7: =TRIM(_xlfn.TEXTJOIN("_",FALSE(),G7,(SUBSTITUTE(SUBSTITUTE(E7," ",""), "_", "")))) -> Balzeau_etal_2012_Table2 | M7: =K7 & "_" & SUBSTITUTE(SUBSTITUTE(SUBSTITUTE(E7,CHAR(160),"")," ",""),"_","") -> 10.1016%2Fj.jhevol.2012.03.007_Table2 | N7: {=IFERROR(INDEX(AUTO_Public_TSV_FileList!$A$1:$A$1000,MATCH(TRUE(),EXACT(M7,IFERROR(_xlfn.TEXTBEFORE(AUTO_Public_TSV_FileList!$A$1:$A$1000,".tsv"),"")),0)),"notfound")} -> 10.1016%2Fj.jhevol.2012.03.007_Table2.tsv | O7: Table 2. Regression results for the relationship between endocranial volume and the surface of the frontal, parieto-temporal and occipital lobes.
A8: Balzeau, A., Holloway, R. L., & Grimaud-Herve, D. (2012). Variations and asymmetries in regional brain surface in the genus Homo. J Hum Evol, 62(6), 696-706. https://doi.org/10.1016/j.jhevol.2012.03.007 | E8: Table 3 | F8: =RIGHT(A8,1) -> 7 | G8: =H8 & IF(I8<>"", "_" & I8, "_") & IF(J8<>"", "_" & J8, "_") & IF(B8<>"", "_" & B8, "") -> Balzeau_etal_2012 | H8: =SUBSTITUTE(SUBSTITUTE(_xlfn.TEXTBEFORE(A8,","), "-", ""), " ", "") -> Balzeau | I8: =_xlfn.LET( _xlpm.authors,_xlfn.TEXTBEFORE(A8," ("&J8&")"), _xlpm.hasAmp,ISNUMBER(SEARCH("&",_xlpm.authors)), _xlpm.commasBeforeAmp,IF(_xlpm.hasAmp,LEN(_xlfn.TEXTBEFORE(_xlpm.authors,"&"))-LEN(SUBSTITUTE(_xlfn.TEXTBEFORE(_xlpm.authors,"&"),",","")),0), IF(NOT(_xlpm.hasAmp),"",IF(_xlpm.commasBeforeAmp>2,"etal",TRIM(_xlfn.TEXTBEFORE(_xlfn.TEXTAFTER(_xlpm.authors,"& "),",")))) ) -> etal | J8: =_xlfn.TEXTBEFORE(_xlfn.TEXTAFTER(A8, "("), ")") -> 2012 | K8: =_xlfn.LET( _xlpm.doi,IF(D8<>"",D8,_xlfn.TEXTAFTER(A8,"https://doi.org/")), SUBSTITUTE( SUBSTITUTE( SUBSTITUTE( SUBSTITUTE( _xlpm.doi, "/","%2F"), ":","%3A"), "<","%3C"), ">","%3E") ) -> 10.1016%2Fj.jhevol.2012.03.007 | L8: =TRIM(_xlfn.TEXTJOIN("_",FALSE(),G8,(SUBSTITUTE(SUBSTITUTE(E8," ",""), "_", "")))) -> Balzeau_etal_2012_Table3 | M8: =K8 & "_" & SUBSTITUTE(SUBSTITUTE(SUBSTITUTE(E8,CHAR(160),"")," ",""),"_","") -> 10.1016%2Fj.jhevol.2012.03.007_Table3 | N8: {=IFERROR(INDEX(AUTO_Public_TSV_FileList!$A$1:$A$1000,MATCH(TRUE(),EXACT(M8,IFERROR(_xlfn.TEXTBEFORE(AUTO_Public_TSV_FileList!$A$1:$A$1000,".tsv"),"")),0)),"notfound")} -> 10.1016%2Fj.jhevol.2012.03.007_Table3.tsv | O8: Table 3 Size-corrected dimensions for the surface of the frontal, parieto-temporal and occipital lobes in the different analysed samples.
A9: Balzeau, A., Holloway, R. L., & Grimaud-Herve, D. (2012). Variations and asymmetries in regional brain surface in the genus Homo. J Hum Evol, 62(6), 696-706. https://doi.org/10.1016/j.jhevol.2012.03.007 | E9: Table 5 | F9: =RIGHT(A9,1) -> 7 | G9: =H9 & IF(I9<>"", "_" & I9, "_") & IF(J9<>"", "_" & J9, "_") & IF(B9<>"", "_" & B9, "") -> Balzeau_etal_2012 | H9: =SUBSTITUTE(SUBSTITUTE(_xlfn.TEXTBEFORE(A9,","), "-", ""), " ", "") -> Balzeau | I9: =_xlfn.LET( _xlpm.authors,_xlfn.TEXTBEFORE(A9," ("&J9&")"), _xlpm.hasAmp,ISNUMBER(SEARCH("&",_xlpm.authors)), _xlpm.commasBeforeAmp,IF(_xlpm.hasAmp,LEN(_xlfn.TEXTBEFORE(_xlpm.authors,"&"))-LEN(SUBSTITUTE(_xlfn.TEXTBEFORE(_xlpm.authors,"&"),",","")),0), IF(NOT(_xlpm.hasAmp),"",IF(_xlpm.commasBeforeAmp>2,"etal",TRIM(_xlfn.TEXTBEFORE(_xlfn.TEXTAFTER(_xlpm.authors,"& "),",")))) ) -> etal | J9: =_xlfn.TEXTBEFORE(_xlfn.TEXTAFTER(A9, "("), ")") -> 2012 | K9: =_xlfn.LET( _xlpm.doi,IF(D9<>"",D9,_xlfn.TEXTAFTER(A9,"https://doi.org/")), SUBSTITUTE( SUBSTITUTE( SUBSTITUTE( SUBSTITUTE( _xlpm.doi, "/","%2F"), ":","%3A"), "<","%3C"), ">","%3E") ) -> 10.1016%2Fj.jhevol.2012.03.007 | L9: =TRIM(_xlfn.TEXTJOIN("_",FALSE(),G9,(SUBSTITUTE(SUBSTITUTE(E9," ",""), "_", "")))) -> Balzeau_etal_2012_Table5 | M9: =K9 & "_" & SUBSTITUTE(SUBSTITUTE(SUBSTITUTE(E9,CHAR(160),"")," ",""),"_","") -> 10.1016%2Fj.jhevol.2012.03.007_Table5 | N9: {=IFERROR(INDEX(AUTO_Public_TSV_FileList!$A$1:$A$1000,MATCH(TRUE(),EXACT(M9,IFERROR(_xlfn.TEXTBEFORE(AUTO_Public_TSV_FileList!$A$1:$A$1000,".tsv"),"")),0)),"notfound")} -> 10.1016%2Fj.jhevol.2012.03.007_Table5.tsv | O9: Table 5 Percentage contribution of frontal, parieto-temporal and occipital lobes to the hemispheres.
A10: Barbeito-Andres, J., Castro-Fonseca, E., Qiu, L. R., Bernal, V., Lent, R., Henkelman, M., Lukowiak, K., Gleiser, P. M., Hallgrimsson, B., & Gonzalez, P. N. (2019). Region-specific changes in Mus musculus brain size and cell composition under chronic nutrient restriction. J Exp Biol, 222(Pt 17). https://doi.org/10.1242/jeb.204651 | E10: cell density | F10: =RIGHT(A10,1) -> 1 | G10: =H10 & IF(I10<>"", "_" & I10, "_") & IF(J10<>"", "_" & J10, "_") & IF(B10<>"", "_" & B10, "") -> BarbeitoAndres_etal_2019 | H10: =SUBSTITUTE(SUBSTITUTE(_xlfn.TEXTBEFORE(A10,","), "-", ""), " ", "") -> BarbeitoAndres | I10: =_xlfn.LET( _xlpm.authors,_xlfn.TEXTBEFORE(A10," ("&J10&")"), _xlpm.hasAmp,ISNUMBER(SEARCH("&",_xlpm.authors)), _xlpm.commasBeforeAmp,IF(_xlpm.hasAmp,LEN(_xlfn.TEXTBEFORE(_xlpm.authors,"&"))-LEN(SUBSTITUTE(_xlfn.TEXTBEFORE(_xlpm.authors,"&"),",","")),0), IF(NOT(_xlpm.hasAmp),"",IF(_xlpm.commasBeforeAmp>2,"etal",TRIM(_xlfn.TEXTBEFORE(_xlfn.TEXTAFTER(_xlpm.authors,"& "),",")))) ) -> etal | J10: =_xlfn.TEXTBEFORE(_xlfn.TEXTAFTER(A10, "("), ")") -> 2019 | K10: =_xlfn.LET( _xlpm.doi,IF(D10<>"",D10,_xlfn.TEXTAFTER(A10,"https://doi.org/")), SUBSTITUTE( SUBSTITUTE( SUBSTITUTE( SUBSTITUTE( _xlpm.doi, "/","%2F"), ":","%3A"), "<","%3C"), ">","%3E") ) -> 10.1242%2Fjeb.204651 | L10: =TRIM(_xlfn.TEXTJOIN("_",FALSE(),G10,(SUBSTITUTE(SUBSTITUTE(E10," ",""), "_", "")))) -> BarbeitoAndres_etal_2019_celldensity | M10: =K10 & "_" & SUBSTITUTE(SUBSTITUTE(SUBSTITUTE(E10,CHAR(160),"")," ",""),"_","") -> 10.1242%2Fjeb.204651_celldensity | N10: {=IFERROR(INDEX(AUTO_Public_TSV_FileList!$A$1:$A$1000,MATCH(TRUE(),EXACT(M10,IFERROR(_xlfn.TEXTBEFORE(AUTO_Public_TSV_FileList!$A$1:$A$1000,".tsv"),"")),0)),"notfound")} -> 10.1242%2Fjeb.204651_celldensity.tsv | AH10: isotropic fractionator | AK10: review | AM10: review | AN10: review
A11: Barbeito-Andres, J., Castro-Fonseca, E., Qiu, L. R., Bernal, V., Lent, R., Henkelman, M., Lukowiak, K., Gleiser, P. M., Hallgrimsson, B., & Gonzalez, P. N. (2019). Region-specific changes in Mus musculus brain size and cell composition under chronic nutrient restriction. J Exp Biol, 222(Pt 17). https://doi.org/10.1242/jeb.204651 | E11: cell number | F11: =RIGHT(A11,1) -> 1 | G11: =H11 & IF(I11<>"", "_" & I11, "_") & IF(J11<>"", "_" & J11, "_") & IF(B11<>"", "_" & B11, "") -> BarbeitoAndres_etal_2019 | H11: =SUBSTITUTE(SUBSTITUTE(_xlfn.TEXTBEFORE(A11,","), "-", ""), " ", "") -> BarbeitoAndres | I11: =_xlfn.LET( _xlpm.authors,_xlfn.TEXTBEFORE(A11," ("&J11&")"), _xlpm.hasAmp,ISNUMBER(SEARCH("&",_xlpm.authors)), _xlpm.commasBeforeAmp,IF(_xlpm.hasAmp,LEN(_xlfn.TEXTBEFORE(_xlpm.authors,"&"))-LEN(SUBSTITUTE(_xlfn.TEXTBEFORE(_xlpm.authors,"&"),",","")),0), IF(NOT(_xlpm.hasAmp),"",IF(_xlpm.commasBeforeAmp>2,"etal",TRIM(_xlfn.TEXTBEFORE(_xlfn.TEXTAFTER(_xlpm.authors,"& "),",")))) ) -> etal | J11: =_xlfn.TEXTBEFORE(_xlfn.TEXTAFTER(A11, "("), ")") -> 2019 | K11: =_xlfn.LET( _xlpm.doi,IF(D11<>"",D11,_xlfn.TEXTAFTER(A11,"https://doi.org/")), SUBSTITUTE( SUBSTITUTE( SUBSTITUTE( SUBSTITUTE( _xlpm.doi, "/","%2F"), ":","%3A"), "<","%3C"), ">","%3E") ) -> 10.1242%2Fjeb.204651 | L11: =TRIM(_xlfn.TEXTJOIN("_",FALSE(),G11,(SUBSTITUTE(SUBSTITUTE(E11," ",""), "_", "")))) -> BarbeitoAndres_etal_2019_cellnumber | M11: =K11 & "_" & SUBSTITUTE(SUBSTITUTE(SUBSTITUTE(E11,CHAR(160),"")," ",""),"_","") -> 10.1242%2Fjeb.204651_cellnumber | N11: {=IFERROR(INDEX(AUTO_Public_TSV_FileList!$A$1:$A$1000,MATCH(TRUE(),EXACT(M11,IFERROR(_xlfn.TEXTBEFORE(AUTO_Public_TSV_FileList!$A$1:$A$1000,".tsv"),"")),0)),"notfound")} -> 10.1242%2Fjeb.204651_cellnumber.tsv | AH11: isotropic fractionator | AK11: review | AM11: review | AN11: review
A12: Barbeito-Andres, J., Castro-Fonseca, E., Qiu, L. R., Bernal, V., Lent, R., Henkelman, M., Lukowiak, K., Gleiser, P. M., Hallgrimsson, B., & Gonzalez, P. N. (2019). Region-specific changes in Mus musculus brain size and cell composition under chronic nutrient restriction. J Exp Biol, 222(Pt 17). https://doi.org/10.1242/jeb.204651 | E12: volumes | F12: =RIGHT(A12,1) -> 1 | G12: =H12 & IF(I12<>"", "_" & I12, "_") & IF(J12<>"", "_" & J12, "_") & IF(B12<>"", "_" & B12, "") -> BarbeitoAndres_etal_2019 | H12: =SUBSTITUTE(SUBSTITUTE(_xlfn.TEXTBEFORE(A12,","), "-", ""), " ", "") -> BarbeitoAndres | I12: =_xlfn.LET( _xlpm.authors,_xlfn.TEXTBEFORE(A12," ("&J12&")"), _xlpm.hasAmp,ISNUMBER(SEARCH("&",_xlpm.authors)), _xlpm.commasBeforeAmp,IF(_xlpm.hasAmp,LEN(_xlfn.TEXTBEFORE(_xlpm.authors,"&"))-LEN(SUBSTITUTE(_xlfn.TEXTBEFORE(_xlpm.authors,"&"),",","")),0), IF(NOT(_xlpm.hasAmp),"",IF(_xlpm.commasBeforeAmp>2,"etal",TRIM(_xlfn.TEXTBEFORE(_xlfn.TEXTAFTER(_xlpm.authors,"& "),",")))) ) -> etal | J12: =_xlfn.TEXTBEFORE(_xlfn.TEXTAFTER(A12, "("), ")") -> 2019 | K12: =_xlfn.LET( _xlpm.doi,IF(D12<>"",D12,_xlfn.TEXTAFTER(A12,"https://doi.org/")), SUBSTITUTE( SUBSTITUTE( SUBSTITUTE( SUBSTITUTE( _xlpm.doi, "/","%2F"), ":","%3A"), "<","%3C"), ">","%3E") ) -> 10.1242%2Fjeb.204651 | L12: =TRIM(_xlfn.TEXTJOIN("_",FALSE(),G12,(SUBSTITUTE(SUBSTITUTE(E12," ",""), "_", "")))) -> BarbeitoAndres_etal_2019_volumes | M12: =K12 & "_" & SUBSTITUTE(SUBSTITUTE(SUBSTITUTE(E12,CHAR(160),"")," ",""),"_","") -> 10.1242%2Fjeb.204651_volumes | N12: {=IFERROR(INDEX(AUTO_Public_TSV_FileList!$A$1:$A$1000,MATCH(TRUE(),EXACT(M12,IFERROR(_xlfn.TEXTBEFORE(AUTO_Public_TSV_FileList!$A$1:$A$1000,".tsv"),"")),0)),"notfound")} -> 10.1242%2Fjeb.204651_volumes.tsv | AH12: isotropic fractionator | AK12: review | AM12: review | AN12: review
A13: Barger, N., Hanson, K. L., Teffer, K., Schenker-Ahmed, N. M., & Semendeferi, K. (2014). Evidence for evolutionary specialization in human limbic structures. Front Hum Neurosci, 8, 277. https://doi.org/10.3389/fnhum.2014.00277 | E13: Table 1 | F13: =RIGHT(A13,1) -> 7 | G13: =H13 & IF(I13<>"", "_" & I13, "_") & IF(J13<>"", "_" & J13, "_") & IF(B13<>"", "_" & B13, "") -> Barger_etal_2014 | H13: =SUBSTITUTE(SUBSTITUTE(_xlfn.TEXTBEFORE(A13,","), "-", ""), " ", "") -> Barger | I13: =_xlfn.LET( _xlpm.authors,_xlfn.TEXTBEFORE(A13," ("&J13&")"), _xlpm.hasAmp,ISNUMBER(SEARCH("&",_xlpm.authors)), _xlpm.commasBeforeAmp,IF(_xlpm.hasAmp,LEN(_xlfn.TEXTBEFORE(_xlpm.authors,"&"))-LEN(SUBSTITUTE(_xlfn.TEXTBEFORE(_xlpm.authors,"&"),",","")),0), IF(NOT(_xlpm.hasAmp),"",IF(_xlpm.commasBeforeAmp>2,"etal",TRIM(_xlfn.TEXTBEFORE(_xlfn.TEXTAFTER(_xlpm.authors,"& "),",")))) ) -> etal | J13: =_xlfn.TEXTBEFORE(_xlfn.TEXTAFTER(A13, "("), ")") -> 2014 | K13: =_xlfn.LET( _xlpm.doi,IF(D13<>"",D13,_xlfn.TEXTAFTER(A13,"https://doi.org/")), SUBSTITUTE( SUBSTITUTE( SUBSTITUTE( SUBSTITUTE( _xlpm.doi, "/","%2F"), ":","%3A"), "<","%3C"), ">","%3E") ) -> 10.3389%2Ffnhum.2014.00277 | L13: =TRIM(_xlfn.TEXTJOIN("_",FALSE(),G13,(SUBSTITUTE(SUBSTITUTE(E13," ",""), "_", "")))) -> Barger_etal_2014_Table1 | M13: =K13 & "_" & SUBSTITUTE(SUBSTITUTE(SUBSTITUTE(E13,CHAR(160),"")," ",""),"_","") -> 10.3389%2Ffnhum.2014.00277_Table1 | N13: {=IFERROR(INDEX(AUTO_Public_TSV_FileList!$A$1:$A$1000,MATCH(TRUE(),EXACT(M13,IFERROR(_xlfn.TEXTBEFORE(AUTO_Public_TSV_FileList!$A$1:$A$1000,".tsv"),"")),0)),"notfound")} -> 10.3389%2Ffnhum.2014.00277_Table1.tsv | O13: Table 1 | Volume of amygdala, hippocampus, and striatum in hominoid species collected with stereological methods. | AA13: Zilles | AG13: histological sections | AH13: Zilles
A14: Barger, N., Stefanacci, L., & Semendeferi, K. (2007). A comparative volumetric analysis of the amygdaloid complex and basolateral division in the human and ape brain. Am J Phys Anthropol, 134(3), 392-403. https://doi.org/10.1002/ajpa.20684 | E14: TABLE 1 | F14: =RIGHT(A14,1) -> 4 | G14: =H14 & IF(I14<>"", "_" & I14, "_") & IF(J14<>"", "_" & J14, "_") & IF(B14<>"", "_" & B14, "") -> Barger_etal_2007 | H14: =SUBSTITUTE(SUBSTITUTE(_xlfn.TEXTBEFORE(A14,","), "-", ""), " ", "") -> Barger | I14: =_xlfn.LET( _xlpm.authors,_xlfn.TEXTBEFORE(A14," ("&J14&")"), _xlpm.hasAmp,ISNUMBER(SEARCH("&",_xlpm.authors)), _xlpm.commasBeforeAmp,IF(_xlpm.hasAmp,LEN(_xlfn.TEXTBEFORE(_xlpm.authors,"&"))-LEN(SUBSTITUTE(_xlfn.TEXTBEFORE(_xlpm.authors,"&"),",","")),0), IF(NOT(_xlpm.hasAmp),"",IF(_xlpm.commasBeforeAmp>2,"etal",TRIM(_xlfn.TEXTBEFORE(_xlfn.TEXTAFTER(_xlpm.authors,"& "),",")))) ) -> etal | J14: =_xlfn.TEXTBEFORE(_xlfn.TEXTAFTER(A14, "("), ")") -> 2007 | K14: =_xlfn.LET( _xlpm.doi,IF(D14<>"",D14,_xlfn.TEXTAFTER(A14,"https://doi.org/")), SUBSTITUTE( SUBSTITUTE( SUBSTITUTE( SUBSTITUTE( _xlpm.doi, "/","%2F"), ":","%3A"), "<","%3C"), ">","%3E") ) -> 10.1002%2Fajpa.20684 | L14: =TRIM(_xlfn.TEXTJOIN("_",FALSE(),G14,(SUBSTITUTE(SUBSTITUTE(E14," ",""), "_", "")))) -> Barger_etal_2007_TABLE1 | M14: =K14 & "_" & SUBSTITUTE(SUBSTITUTE(SUBSTITUTE(E14,CHAR(160),"")," ",""),"_","") -> 10.1002%2Fajpa.20684_TABLE1 | N14: {=IFERROR(INDEX(AUTO_Public_TSV_FileList!$A$1:$A$1000,MATCH(TRUE(),EXACT(M14,IFERROR(_xlfn.TEXTBEFORE(AUTO_Public_TSV_FileList!$A$1:$A$1000,".tsv"),"")),0)),"notfound")} -> 10.1002%2Fajpa.20684_TABLE1.tsv | O14: TABLE 1. Volumetric estimates of the amygdaloid complex and the basolateral division | Q14: FINISHED | AA14: Zilles | AH14: Zilles | AJ14: amygdala subdivision volumes | AK14: Apes & humans | AM14: primary | AN14: volume
A15: Barger, N., Stefanacci, L., Schumann, C. M., Sherwood, C. C., Annese, J., Allman, J. M., Buckwalter, J. A., Hof, P. R., & Semendeferi, K. (2012). Neuronal populations in the basolateral nuclei of the amygdala are differentially increased in humans compared with apes: A stereological study. J Comp Neurol, 520(13), 3035-3054. https://doi.org/10.1002/cne.23118 | E15: Table 3 | F15: =RIGHT(A15,1) -> 8 | G15: =H15 & IF(I15<>"", "_" & I15, "_") & IF(J15<>"", "_" & J15, "_") & IF(B15<>"", "_" & B15, "") -> Barger_etal_2012 | H15: =SUBSTITUTE(SUBSTITUTE(_xlfn.TEXTBEFORE(A15,","), "-", ""), " ", "") -> Barger | I15: =_xlfn.LET( _xlpm.authors,_xlfn.TEXTBEFORE(A15," ("&J15&")"), _xlpm.hasAmp,ISNUMBER(SEARCH("&",_xlpm.authors)), _xlpm.commasBeforeAmp,IF(_xlpm.hasAmp,LEN(_xlfn.TEXTBEFORE(_xlpm.authors,"&"))-LEN(SUBSTITUTE(_xlfn.TEXTBEFORE(_xlpm.authors,"&"),",","")),0), IF(NOT(_xlpm.hasAmp),"",IF(_xlpm.commasBeforeAmp>2,"etal",TRIM(_xlfn.TEXTBEFORE(_xlfn.TEXTAFTER(_xlpm.authors,"& "),",")))) ) -> etal | J15: =_xlfn.TEXTBEFORE(_xlfn.TEXTAFTER(A15, "("), ")") -> 2012 | K15: =_xlfn.LET( _xlpm.doi,IF(D15<>"",D15,_xlfn.TEXTAFTER(A15,"https://doi.org/")), SUBSTITUTE( SUBSTITUTE( SUBSTITUTE( SUBSTITUTE( _xlpm.doi, "/","%2F"), ":","%3A"), "<","%3C"), ">","%3E") ) -> 10.1002%2Fcne.23118 | L15: =TRIM(_xlfn.TEXTJOIN("_",FALSE(),G15,(SUBSTITUTE(SUBSTITUTE(E15," ",""), "_", "")))) -> Barger_etal_2012_Table3 | M15: =K15 & "_" & SUBSTITUTE(SUBSTITUTE(SUBSTITUTE(E15,CHAR(160),"")," ",""),"_","") -> 10.1002%2Fcne.23118_Table3 | N15: {=IFERROR(INDEX(AUTO_Public_TSV_FileList!$A$1:$A$1000,MATCH(TRUE(),EXACT(M15,IFERROR(_xlfn.TEXTBEFORE(AUTO_Public_TSV_FileList!$A$1:$A$1000,".tsv"),"")),0)),"notfound")} -> 10.1002%2Fcne.23118_Table3.tsv | O15: Table 3. Average Neuron Number x10^6 (SD) for each nucleus in each species | Q15: FINISHED | AJ15: amygdala neuron numbers (basolateral + central nuclei) | AK15: Primates | AL15: primary | AM15: primary | AN15: neuron count (stereology)
A16: Barks, S. K., Calhoun, M. E., Hopkins, W. D., Cranfield, M. R., Mudakikwa, A., Stoinski, T. S., Patterson, F. G., Erwin, J. M., Hecht, E. E., Hof, P. R., & Sherwood, C. C. (2014). Brain organization of gorillas reflects species differences in ecology. Am J Phys Anthropol. https://doi.org/10.1002/ajpa.22646 | E16: Fig 4 A | F16: =RIGHT(A16,1) -> 6 | G16: =H16 & IF(I16<>"", "_" & I16, "_") & IF(J16<>"", "_" & J16, "_") & IF(B16<>"", "_" & B16, "") -> Barks_etal_2014 | H16: =SUBSTITUTE(SUBSTITUTE(_xlfn.TEXTBEFORE(A16,","), "-", ""), " ", "") -> Barks | I16: =_xlfn.LET( _xlpm.authors,_xlfn.TEXTBEFORE(A16," ("&J16&")"), _xlpm.hasAmp,ISNUMBER(SEARCH("&",_xlpm.authors)), _xlpm.commasBeforeAmp,IF(_xlpm.hasAmp,LEN(_xlfn.TEXTBEFORE(_xlpm.authors,"&"))-LEN(SUBSTITUTE(_xlfn.TEXTBEFORE(_xlpm.authors,"&"),",","")),0), IF(NOT(_xlpm.hasAmp),"",IF(_xlpm.commasBeforeAmp>2,"etal",TRIM(_xlfn.TEXTBEFORE(_xlfn.TEXTAFTER(_xlpm.authors,"& "),",")))) ) -> etal | J16: =_xlfn.TEXTBEFORE(_xlfn.TEXTAFTER(A16, "("), ")") -> 2014 | K16: =_xlfn.LET( _xlpm.doi,IF(D16<>"",D16,_xlfn.TEXTAFTER(A16,"https://doi.org/")), SUBSTITUTE( SUBSTITUTE( SUBSTITUTE( SUBSTITUTE( _xlpm.doi, "/","%2F"), ":","%3A"), "<","%3C"), ">","%3E") ) -> 10.1002%2Fajpa.22646 | L16: =TRIM(_xlfn.TEXTJOIN("_",FALSE(),G16,(SUBSTITUTE(SUBSTITUTE(E16," ",""), "_", "")))) -> Barks_etal_2014_Fig4A | M16: =K16 & "_" & SUBSTITUTE(SUBSTITUTE(SUBSTITUTE(E16,CHAR(160),"")," ",""),"_","") -> 10.1002%2Fajpa.22646_Fig4A | N16: {=IFERROR(INDEX(AUTO_Public_TSV_FileList!$A$1:$A$1000,MATCH(TRUE(),EXACT(M16,IFERROR(_xlfn.TEXTBEFORE(AUTO_Public_TSV_FileList!$A$1:$A$1000,".tsv"),"")),0)),"notfound")} -> 10.1002%2Fajpa.22646_Fig4A.tsv | P16: Fig4A_allsubjects_volumes | Q16: FINISHED | Z16: Barks
A17: Barks, S. K., Calhoun, M. E., Hopkins, W. D., Cranfield, M. R., Mudakikwa, A., Stoinski, T. S., Patterson, F. G., Erwin, J. M., Hecht, E. E., Hof, P. R., & Sherwood, C. C. (2014). Brain organization of gorillas reflects species differences in ecology. Am J Phys Anthropol. https://doi.org/10.1002/ajpa.22646 | E17: Fig 5 A | F17: =RIGHT(A17,1) -> 6 | G17: =H17 & IF(I17<>"", "_" & I17, "_") & IF(J17<>"", "_" & J17, "_") & IF(B17<>"", "_" & B17, "") -> Barks_etal_2014 | H17: =SUBSTITUTE(SUBSTITUTE(_xlfn.TEXTBEFORE(A17,","), "-", ""), " ", "") -> Barks | I17: =_xlfn.LET( _xlpm.authors,_xlfn.TEXTBEFORE(A17," ("&J17&")"), _xlpm.hasAmp,ISNUMBER(SEARCH("&",_xlpm.authors)), _xlpm.commasBeforeAmp,IF(_xlpm.hasAmp,LEN(_xlfn.TEXTBEFORE(_xlpm.authors,"&"))-LEN(SUBSTITUTE(_xlfn.TEXTBEFORE(_xlpm.authors,"&"),",","")),0), IF(NOT(_xlpm.hasAmp),"",IF(_xlpm.commasBeforeAmp>2,"etal",TRIM(_xlfn.TEXTBEFORE(_xlfn.TEXTAFTER(_xlpm.authors,"& "),",")))) ) -> etal | J17: =_xlfn.TEXTBEFORE(_xlfn.TEXTAFTER(A17, "("), ")") -> 2014 | K17: =_xlfn.LET( _xlpm.doi,IF(D17<>"",D17,_xlfn.TEXTAFTER(A17,"https://doi.org/")), SUBSTITUTE( SUBSTITUTE( SUBSTITUTE( SUBSTITUTE( _xlpm.doi, "/","%2F"), ":","%3A"), "<","%3C"), ">","%3E") ) -> 10.1002%2Fajpa.22646 | L17: =TRIM(_xlfn.TEXTJOIN("_",FALSE(),G17,(SUBSTITUTE(SUBSTITUTE(E17," ",""), "_", "")))) -> Barks_etal_2014_Fig5A | M17: =K17 & "_" & SUBSTITUTE(SUBSTITUTE(SUBSTITUTE(E17,CHAR(160),"")," ",""),"_","") -> 10.1002%2Fajpa.22646_Fig5A | N17: {=IFERROR(INDEX(AUTO_Public_TSV_FileList!$A$1:$A$1000,MATCH(TRUE(),EXACT(M17,IFERROR(_xlfn.TEXTBEFORE(AUTO_Public_TSV_FileList!$A$1:$A$1000,".tsv"),"")),0)),"notfound")} -> 10.1002%2Fajpa.22646_Fig5A.tsv | P17: Fig5A_adultsonly_volumes | Q17: FINISHED
A18: Barks, S. K., Calhoun, M. E., Hopkins, W. D., Cranfield, M. R., Mudakikwa, A., Stoinski, T. S., Patterson, F. G., Erwin, J. M., Hecht, E. E., Hof, P. R., & Sherwood, C. C. (2014). Brain organization of gorillas reflects species differences in ecology. Am J Phys Anthropol. https://doi.org/10.1002/ajpa.22646 | E18: TABLE 1 | F18: =RIGHT(A18,1) -> 6 | G18: =H18 & IF(I18<>"", "_" & I18, "_") & IF(J18<>"", "_" & J18, "_") & IF(B18<>"", "_" & B18, "") -> Barks_etal_2014 | H18: =SUBSTITUTE(SUBSTITUTE(_xlfn.TEXTBEFORE(A18,","), "-", ""), " ", "") -> Barks | I18: =_xlfn.LET( _xlpm.authors,_xlfn.TEXTBEFORE(A18," ("&J18&")"), _xlpm.hasAmp,ISNUMBER(SEARCH("&",_xlpm.authors)), _xlpm.commasBeforeAmp,IF(_xlpm.hasAmp,LEN(_xlfn.TEXTBEFORE(_xlpm.authors,"&"))-LEN(SUBSTITUTE(_xlfn.TEXTBEFORE(_xlpm.authors,"&"),",","")),0), IF(NOT(_xlpm.hasAmp),"",IF(_xlpm.commasBeforeAmp>2,"etal",TRIM(_xlfn.TEXTBEFORE(_xlfn.TEXTAFTER(_xlpm.authors,"& "),",")))) ) -> etal | J18: =_xlfn.TEXTBEFORE(_xlfn.TEXTAFTER(A18, "("), ")") -> 2014 | K18: =_xlfn.LET( _xlpm.doi,IF(D18<>"",D18,_xlfn.TEXTAFTER(A18,"https://doi.org/")), SUBSTITUTE( SUBSTITUTE( SUBSTITUTE( SUBSTITUTE( _xlpm.doi, "/","%2F"), ":","%3A"), "<","%3C"), ">","%3E") ) -> 10.1002%2Fajpa.22646 | L18: =TRIM(_xlfn.TEXTJOIN("_",FALSE(),G18,(SUBSTITUTE(SUBSTITUTE(E18," ",""), "_", "")))) -> Barks_etal_2014_TABLE1 | M18: =K18 & "_" & SUBSTITUTE(SUBSTITUTE(SUBSTITUTE(E18,CHAR(160),"")," ",""),"_","") -> 10.1002%2Fajpa.22646_TABLE1 | N18: {=IFERROR(INDEX(AUTO_Public_TSV_FileList!$A$1:$A$1000,MATCH(TRUE(),EXACT(M18,IFERROR(_xlfn.TEXTBEFORE(AUTO_Public_TSV_FileList!$A$1:$A$1000,".tsv"),"")),0)),"notfound")} -> 10.1002%2Fajpa.22646_TABLE1.tsv | O18: TABLE 1. Individual data | Q18: FINISHED | Z18: Barks
A19: Barks, S. K., Calhoun, M. E., Hopkins, W. D., Cranfield, M. R., Mudakikwa, A., Stoinski, T. S., Patterson, F. G., Erwin, J. M., Hecht, E. E., Hof, P. R., & Sherwood, C. C. (2014). Brain organization of gorillas reflects species differences in ecology. Am J Phys Anthropol. https://doi.org/10.1002/ajpa.22646 | E19: TABLE 2 | F19: =RIGHT(A19,1) -> 6 | G19: =H19 & IF(I19<>"", "_" & I19, "_") & IF(J19<>"", "_" & J19, "_") & IF(B19<>"", "_" & B19, "") -> Barks_etal_2014 | H19: =SUBSTITUTE(SUBSTITUTE(_xlfn.TEXTBEFORE(A19,","), "-", ""), " ", "") -> Barks | I19: =_xlfn.LET( _xlpm.authors,_xlfn.TEXTBEFORE(A19," ("&J19&")"), _xlpm.hasAmp,ISNUMBER(SEARCH("&",_xlpm.authors)), _xlpm.commasBeforeAmp,IF(_xlpm.hasAmp,LEN(_xlfn.TEXTBEFORE(_xlpm.authors,"&"))-LEN(SUBSTITUTE(_xlfn.TEXTBEFORE(_xlpm.authors,"&"),",","")),0), IF(NOT(_xlpm.hasAmp),"",IF(_xlpm.commasBeforeAmp>2,"etal",TRIM(_xlfn.TEXTBEFORE(_xlfn.TEXTAFTER(_xlpm.authors,"& "),",")))) ) -> etal | J19: =_xlfn.TEXTBEFORE(_xlfn.TEXTAFTER(A19, "("), ")") -> 2014 | K19: =_xlfn.LET( _xlpm.doi,IF(D19<>"",D19,_xlfn.TEXTAFTER(A19,"https://doi.org/")), SUBSTITUTE( SUBSTITUTE( SUBSTITUTE( SUBSTITUTE( _xlpm.doi, "/","%2F"), ":","%3A"), "<","%3C"), ">","%3E") ) -> 10.1002%2Fajpa.22646 | L19: =TRIM(_xlfn.TEXTJOIN("_",FALSE(),G19,(SUBSTITUTE(SUBSTITUTE(E19," ",""), "_", "")))) -> Barks_etal_2014_TABLE2 | M19: =K19 & "_" & SUBSTITUTE(SUBSTITUTE(SUBSTITUTE(E19,CHAR(160),"")," ",""),"_","") -> 10.1002%2Fajpa.22646_TABLE2 | N19: {=IFERROR(INDEX(AUTO_Public_TSV_FileList!$A$1:$A$1000,MATCH(TRUE(),EXACT(M19,IFERROR(_xlfn.TEXTBEFORE(AUTO_Public_TSV_FileList!$A$1:$A$1000,".tsv"),"")),0)),"notfound")} -> 10.1002%2Fajpa.22646_TABLE2.tsv | O19: TABLE 2. Stereological sampling of brains | Q19: FINISHED
A20: Barks, S. K., Calhoun, M. E., Hopkins, W. D., Cranfield, M. R., Mudakikwa, A., Stoinski, T. S., Patterson, F. G., Erwin, J. M., Hecht, E. E., Hof, P. R., & Sherwood, C. C. (2014). Brain organization of gorillas reflects species differences in ecology. Am J Phys Anthropol. https://doi.org/10.1002/ajpa.22646 | E20: unpublishedviaDeCasien | F20: =RIGHT(A20,1) -> 6 | G20: =H20 & IF(I20<>"", "_" & I20, "_") & IF(J20<>"", "_" & J20, "_") & IF(B20<>"", "_" & B20, "") -> Barks_etal_2014 | H20: =SUBSTITUTE(SUBSTITUTE(_xlfn.TEXTBEFORE(A20,","), "-", ""), " ", "") -> Barks | I20: =_xlfn.LET( _xlpm.authors,_xlfn.TEXTBEFORE(A20," ("&J20&")"), _xlpm.hasAmp,ISNUMBER(SEARCH("&",_xlpm.authors)), _xlpm.commasBeforeAmp,IF(_xlpm.hasAmp,LEN(_xlfn.TEXTBEFORE(_xlpm.authors,"&"))-LEN(SUBSTITUTE(_xlfn.TEXTBEFORE(_xlpm.authors,"&"),",","")),0), IF(NOT(_xlpm.hasAmp),"",IF(_xlpm.commasBeforeAmp>2,"etal",TRIM(_xlfn.TEXTBEFORE(_xlfn.TEXTAFTER(_xlpm.authors,"& "),",")))) ) -> etal | J20: =_xlfn.TEXTBEFORE(_xlfn.TEXTAFTER(A20, "("), ")") -> 2014 | K20: =_xlfn.LET( _xlpm.doi,IF(D20<>"",D20,_xlfn.TEXTAFTER(A20,"https://doi.org/")), SUBSTITUTE( SUBSTITUTE( SUBSTITUTE( SUBSTITUTE( _xlpm.doi, "/","%2F"), ":","%3A"), "<","%3C"), ">","%3E") ) -> 10.1002%2Fajpa.22646 | L20: =TRIM(_xlfn.TEXTJOIN("_",FALSE(),G20,(SUBSTITUTE(SUBSTITUTE(E20," ",""), "_", "")))) -> Barks_etal_2014_unpublishedviaDeCasien | M20: =K20 & "_" & SUBSTITUTE(SUBSTITUTE(SUBSTITUTE(E20,CHAR(160),"")," ",""),"_","") -> 10.1002%2Fajpa.22646_unpublishedviaDeCasien | N20: {=IFERROR(INDEX(AUTO_Public_TSV_FileList!$A$1:$A$1000,MATCH(TRUE(),EXACT(M20,IFERROR(_xlfn.TEXTBEFORE(AUTO_Public_TSV_FileList!$A$1:$A$1000,".tsv"),"")),0)),"notfound")} -> 10.1002%2Fajpa.22646_unpublishedviaDeCasien.tsv | P20: "Sherwood et al.64 and Barks et al.65 provided neocortex, hippocampus, striatum, thalamus, cerebellum, amygdala and insula measures for multiple gorilla species (Gorilla gorilla gorilla, G. g. graueri and G. beringei) from post-mortem MRI scans" (DeCasien and Higham 2019)
A21: Baron, G., Frahm, H. D., & Stephan, H. (1988). Comparison of brain structure volumes in Insectivora and Primates. VIII. Vestibular complex. J Hirnforsch, 29(5), 509-523. http://www.ncbi.nlm.nih.gov/pubmed/3216099 | D21: PMID:3216099 | E21: Table 1 | F21: =RIGHT(A21,1) -> 9 | G21: =H21 & IF(I21<>"", "_" & I21, "_") & IF(J21<>"", "_" & J21, "_") & IF(B21<>"", "_" & B21, "") -> Baron_etal_1988 | H21: =SUBSTITUTE(SUBSTITUTE(_xlfn.TEXTBEFORE(A21,","), "-", ""), " ", "") -> Baron | I21: =_xlfn.LET( _xlpm.authors,_xlfn.TEXTBEFORE(A21," ("&J21&")"), _xlpm.hasAmp,ISNUMBER(SEARCH("&",_xlpm.authors)), _xlpm.commasBeforeAmp,IF(_xlpm.hasAmp,LEN(_xlfn.TEXTBEFORE(_xlpm.authors,"&"))-LEN(SUBSTITUTE(_xlfn.TEXTBEFORE(_xlpm.authors,"&"),",","")),0), IF(NOT(_xlpm.hasAmp),"",IF(_xlpm.commasBeforeAmp>2,"etal",TRIM(_xlfn.TEXTBEFORE(_xlfn.TEXTAFTER(_xlpm.authors,"& "),",")))) ) -> etal | J21: =_xlfn.TEXTBEFORE(_xlfn.TEXTAFTER(A21, "("), ")") -> 1988 | K21: =_xlfn.LET( _xlpm.doi,IF(D21<>"",D21,_xlfn.TEXTAFTER(A21,"https://doi.org/")), SUBSTITUTE( SUBSTITUTE( SUBSTITUTE( SUBSTITUTE( _xlpm.doi, "/","%2F"), ":","%3A"), "<","%3C"), ">","%3E") ) -> PMID%3A3216099 | L21: =TRIM(_xlfn.TEXTJOIN("_",FALSE(),G21,(SUBSTITUTE(SUBSTITUTE(E21," ",""), "_", "")))) -> Baron_etal_1988_Table1 | M21: =K21 & "_" & SUBSTITUTE(SUBSTITUTE(SUBSTITUTE(E21,CHAR(160),"")," ",""),"_","") -> PMID%3A3216099_Table1 | N21: {=IFERROR(INDEX(AUTO_Public_TSV_FileList!$A$1:$A$1000,MATCH(TRUE(),EXACT(M21,IFERROR(_xlfn.TEXTBEFORE(AUTO_Public_TSV_FileList!$A$1:$A$1000,".tsv"),"")),0)),"notfound")} -> PMID%3A3216099_Table1.tsv | O21: Table 1. Volumes and indices of the vestibular complex (VC) and its main components (VM, V1, VL, VS) in Insectivora and Scadentia | Q21: FINISHED | Z21: Stephan | AA21: Stephan | AG21: histological sections | AH21: Stephan | AJ21: vestibular nuclear complex volume | AK21: Insectivora, Scandentia & Primates | AM21: primary | AN21: volume
A22: Baron, G., Frahm, H. D., Bhatnagar, K. P., & Stephan, H. (1983). Comparison of brain structure volumes in Insectivora and Primates. III. Main olfactory bulb (MOB). J Hirnforsch, 24(5), 551-568. https://www.ncbi.nlm.nih.gov/pubmed/6663055 | D22: PMID:6663055 | E22: Table 1 | F22: =RIGHT(A22,1) -> 5 | G22: =H22 & IF(I22<>"", "_" & I22, "_") & IF(J22<>"", "_" & J22, "_") & IF(B22<>"", "_" & B22, "") -> Baron_etal_1983 | H22: =SUBSTITUTE(SUBSTITUTE(_xlfn.TEXTBEFORE(A22,","), "-", ""), " ", "") -> Baron | I22: =_xlfn.LET( _xlpm.authors,_xlfn.TEXTBEFORE(A22," ("&J22&")"), _xlpm.hasAmp,ISNUMBER(SEARCH("&",_xlpm.authors)), _xlpm.commasBeforeAmp,IF(_xlpm.hasAmp,LEN(_xlfn.TEXTBEFORE(_xlpm.authors,"&"))-LEN(SUBSTITUTE(_xlfn.TEXTBEFORE(_xlpm.authors,"&"),",","")),0), IF(NOT(_xlpm.hasAmp),"",IF(_xlpm.commasBeforeAmp>2,"etal",TRIM(_xlfn.TEXTBEFORE(_xlfn.TEXTAFTER(_xlpm.authors,"& "),",")))) ) -> etal | J22: =_xlfn.TEXTBEFORE(_xlfn.TEXTAFTER(A22, "("), ")") -> 1983 | K22: =_xlfn.LET( _xlpm.doi,IF(D22<>"",D22,_xlfn.TEXTAFTER(A22,"https://doi.org/")), SUBSTITUTE( SUBSTITUTE( SUBSTITUTE( SUBSTITUTE( _xlpm.doi, "/","%2F"), ":","%3A"), "<","%3C"), ">","%3E") ) -> PMID%3A6663055 | L22: =TRIM(_xlfn.TEXTJOIN("_",FALSE(),G22,(SUBSTITUTE(SUBSTITUTE(E22," ",""), "_", "")))) -> Baron_etal_1983_Table1 | M22: =K22 & "_" & SUBSTITUTE(SUBSTITUTE(SUBSTITUTE(E22,CHAR(160),"")," ",""),"_","") -> PMID%3A6663055_Table1 | N22: {=IFERROR(INDEX(AUTO_Public_TSV_FileList!$A$1:$A$1000,MATCH(TRUE(),EXACT(M22,IFERROR(_xlfn.TEXTBEFORE(AUTO_Public_TSV_FileList!$A$1:$A$1000,".tsv"),"")),0)),"notfound")} -> PMID%3A6663055_Table1.tsv | Q22: FINISHED | W22: table | X22: NO - not digitized | Z22: Stephan | AA22: Stephan | AG22: histological sections | AH22: Stephan | AJ22: main olfactory bulb (MOB) volume | AK22: Insectivora, Scandentia & Primates | AL22: primary | AM22: primary | AN22: volume
A23: Baron, G., Stephan, H., & Frahm, H. D. (1987). Comparison of brain structure volumes in Insectivora and Primates. VI. Paleocortical components. J Hirnforsch, 28(4), 463-477. http://www.ncbi.nlm.nih.gov/pubmed/3116076 | D23: PMID:3116076 | E23: Table 1 | F23: =RIGHT(A23,1) -> 6 | G23: =H23 & IF(I23<>"", "_" & I23, "_") & IF(J23<>"", "_" & J23, "_") & IF(B23<>"", "_" & B23, "") -> Baron_etal_1987 | H23: =SUBSTITUTE(SUBSTITUTE(_xlfn.TEXTBEFORE(A23,","), "-", ""), " ", "") -> Baron | I23: =_xlfn.LET( _xlpm.authors,_xlfn.TEXTBEFORE(A23," ("&J23&")"), _xlpm.hasAmp,ISNUMBER(SEARCH("&",_xlpm.authors)), _xlpm.commasBeforeAmp,IF(_xlpm.hasAmp,LEN(_xlfn.TEXTBEFORE(_xlpm.authors,"&"))-LEN(SUBSTITUTE(_xlfn.TEXTBEFORE(_xlpm.authors,"&"),",","")),0), IF(NOT(_xlpm.hasAmp),"",IF(_xlpm.commasBeforeAmp>2,"etal",TRIM(_xlfn.TEXTBEFORE(_xlfn.TEXTAFTER(_xlpm.authors,"& "),",")))) ) -> etal | J23: =_xlfn.TEXTBEFORE(_xlfn.TEXTAFTER(A23, "("), ")") -> 1987 | K23: =_xlfn.LET( _xlpm.doi,IF(D23<>"",D23,_xlfn.TEXTAFTER(A23,"https://doi.org/")), SUBSTITUTE( SUBSTITUTE( SUBSTITUTE( SUBSTITUTE( _xlpm.doi, "/","%2F"), ":","%3A"), "<","%3C"), ">","%3E") ) -> PMID%3A3116076 | L23: =TRIM(_xlfn.TEXTJOIN("_",FALSE(),G23,(SUBSTITUTE(SUBSTITUTE(E23," ",""), "_", "")))) -> Baron_etal_1987_Table1 | M23: =K23 & "_" & SUBSTITUTE(SUBSTITUTE(SUBSTITUTE(E23,CHAR(160),"")," ",""),"_","") -> PMID%3A3116076_Table1 | N23: {=IFERROR(INDEX(AUTO_Public_TSV_FileList!$A$1:$A$1000,MATCH(TRUE(),EXACT(M23,IFERROR(_xlfn.TEXTBEFORE(AUTO_Public_TSV_FileList!$A$1:$A$1000,".tsv"),"")),0)),"notfound")} -> PMID%3A3116076_Table1.tsv | Q23: FINISHED | W23: table | X23: NO - not digitized | Z23: Stephan | AA23: Stephan | AG23: histological sections | AH23: Stephan | AJ23: brain-structure volume (Comparison series, Part) | AK23: Insectivora, Scandentia & Primates | AL23: primary | AM23: primary | AN23: volume
A24: Baron, G., Stephan, H., & Frahm, H. D. (1990). Comparison of brain structure volumes in Insectivora and primates. IX. Trigeminal complex. J Hirnforsch, 31(2), 193-200. https://www.ncbi.nlm.nih.gov/pubmed/2358663 | D24: PMID:2358663 | E24: Table 1 | F24: =RIGHT(A24,1) -> 3 | G24: =H24 & IF(I24<>"", "_" & I24, "_") & IF(J24<>"", "_" & J24, "_") & IF(B24<>"", "_" & B24, "") -> Baron_etal_1990 | H24: =SUBSTITUTE(SUBSTITUTE(_xlfn.TEXTBEFORE(A24,","), "-", ""), " ", "") -> Baron | I24: =_xlfn.LET( _xlpm.authors,_xlfn.TEXTBEFORE(A24," ("&J24&")"), _xlpm.hasAmp,ISNUMBER(SEARCH("&",_xlpm.authors)), _xlpm.commasBeforeAmp,IF(_xlpm.hasAmp,LEN(_xlfn.TEXTBEFORE(_xlpm.authors,"&"))-LEN(SUBSTITUTE(_xlfn.TEXTBEFORE(_xlpm.authors,"&"),",","")),0), IF(NOT(_xlpm.hasAmp),"",IF(_xlpm.commasBeforeAmp>2,"etal",TRIM(_xlfn.TEXTBEFORE(_xlfn.TEXTAFTER(_xlpm.authors,"& "),",")))) ) -> etal | J24: =_xlfn.TEXTBEFORE(_xlfn.TEXTAFTER(A24, "("), ")") -> 1990 | K24: =_xlfn.LET( _xlpm.doi,IF(D24<>"",D24,_xlfn.TEXTAFTER(A24,"https://doi.org/")), SUBSTITUTE( SUBSTITUTE( SUBSTITUTE( SUBSTITUTE( _xlpm.doi, "/","%2F"), ":","%3A"), "<","%3C"), ">","%3E") ) -> PMID%3A2358663 | L24: =TRIM(_xlfn.TEXTJOIN("_",FALSE(),G24,(SUBSTITUTE(SUBSTITUTE(E24," ",""), "_", "")))) -> Baron_etal_1990_Table1 | M24: =K24 & "_" & SUBSTITUTE(SUBSTITUTE(SUBSTITUTE(E24,CHAR(160),"")," ",""),"_","") -> PMID%3A2358663_Table1 | N24: {=IFERROR(INDEX(AUTO_Public_TSV_FileList!$A$1:$A$1000,MATCH(TRUE(),EXACT(M24,IFERROR(_xlfn.TEXTBEFORE(AUTO_Public_TSV_FileList!$A$1:$A$1000,".tsv"),"")),0)),"notfound")} -> PMID%3A2358663_Table1.tsv | O24: Table 1 .IX. Trigeminal complex | Q24: FINISHED | W24: table | X24: NO - not digitized | Z24: Stephan | AA24: Stephan | AG24: histological sections | AH24: volumetry | AJ24: trigeminal complex volume | AK24: Insectivora, Scandentia & Primates | AL24: primary | AM24: primary | AN24: volume
A25: Baron, G., Stephan, H., & Frahm, H. D. (1996). Comparative Neurobiology in Chiroptera: Macromorphology, Brain Structures, Tables, and Atlases. Birkhaeuser. | D25: ISBN:9783764353704 | E25: Table 10 | F25: =RIGHT(A25,1) -> . | G25: =H25 & IF(I25<>"", "_" & I25, "_") & IF(J25<>"", "_" & J25, "_") & IF(B25<>"", "_" & B25, "") -> Baron_etal_1996 | H25: =SUBSTITUTE(SUBSTITUTE(_xlfn.TEXTBEFORE(A25,","), "-", ""), " ", "") -> Baron | I25: =_xlfn.LET( _xlpm.authors,_xlfn.TEXTBEFORE(A25," ("&J25&")"), _xlpm.hasAmp,ISNUMBER(SEARCH("&",_xlpm.authors)), _xlpm.commasBeforeAmp,IF(_xlpm.hasAmp,LEN(_xlfn.TEXTBEFORE(_xlpm.authors,"&"))-LEN(SUBSTITUTE(_xlfn.TEXTBEFORE(_xlpm.authors,"&"),",","")),0), IF(NOT(_xlpm.hasAmp),"",IF(_xlpm.commasBeforeAmp>2,"etal",TRIM(_xlfn.TEXTBEFORE(_xlfn.TEXTAFTER(_xlpm.authors,"& "),",")))) ) -> etal | J25: =_xlfn.TEXTBEFORE(_xlfn.TEXTAFTER(A25, "("), ")") -> 1996 | K25: =_xlfn.LET( _xlpm.doi,IF(D25<>"",D25,_xlfn.TEXTAFTER(A25,"https://doi.org/")), SUBSTITUTE( SUBSTITUTE( SUBSTITUTE( SUBSTITUTE( _xlpm.doi, "/","%2F"), ":","%3A"), "<","%3C"), ">","%3E") ) -> ISBN%3A9783764353704 | L25: =TRIM(_xlfn.TEXTJOIN("_",FALSE(),G25,(SUBSTITUTE(SUBSTITUTE(E25," ",""), "_", "")))) -> Baron_etal_1996_Table10 | M25: =K25 & "_" & SUBSTITUTE(SUBSTITUTE(SUBSTITUTE(E25,CHAR(160),"")," ",""),"_","") -> ISBN%3A9783764353704_Table10 | N25: {=IFERROR(INDEX(AUTO_Public_TSV_FileList!$A$1:$A$1000,MATCH(TRUE(),EXACT(M25,IFERROR(_xlfn.TEXTBEFORE(AUTO_Public_TSV_FileList!$A$1:$A$1000,".tsv"),"")),0)),"notfound")} -> ISBN%3A9783764353704_Table10.tsv | O25: BUILT 2026-08-15: 272 species; five fundamental brain-part volumes. | P25: FINISHED | Q25: FINISHED | R25: Baron_etal_1996_Table10_snapshot.csv | S25: Source values preserved; seven blank n values retained as missing. | T25: Baron_etal_1996_Table10.csv | U25: Baron_etal_1996_Table10.csv | AL25: primary | AM25: primary
A26: Baron, G., Stephan, H., & Frahm, H. D. (1996). Comparative Neurobiology in Chiroptera: Macromorphology, Brain Structures, Tables, and Atlases. Birkhaeuser. | D26: ISBN:9783764353704 | E26: Table 32 | F26: =RIGHT(A26,1) -> . | G26: =H26 & IF(I26<>"", "_" & I26, "_") & IF(J26<>"", "_" & J26, "_") & IF(B26<>"", "_" & B26, "") -> Baron_etal_1996 | H26: =SUBSTITUTE(SUBSTITUTE(_xlfn.TEXTBEFORE(A26,","), "-", ""), " ", "") -> Baron | I26: =_xlfn.LET( _xlpm.authors,_xlfn.TEXTBEFORE(A26," ("&J26&")"), _xlpm.hasAmp,ISNUMBER(SEARCH("&",_xlpm.authors)), _xlpm.commasBeforeAmp,IF(_xlpm.hasAmp,LEN(_xlfn.TEXTBEFORE(_xlpm.authors,"&"))-LEN(SUBSTITUTE(_xlfn.TEXTBEFORE(_xlpm.authors,"&"),",","")),0), IF(NOT(_xlpm.hasAmp),"",IF(_xlpm.commasBeforeAmp>2,"etal",TRIM(_xlfn.TEXTBEFORE(_xlfn.TEXTAFTER(_xlpm.authors,"& "),",")))) ) -> etal | J26: =_xlfn.TEXTBEFORE(_xlfn.TEXTAFTER(A26, "("), ")") -> 1996 | K26: =_xlfn.LET( _xlpm.doi,IF(D26<>"",D26,_xlfn.TEXTAFTER(A26,"https://doi.org/")), SUBSTITUTE( SUBSTITUTE( SUBSTITUTE( SUBSTITUTE( _xlpm.doi, "/","%2F"), ":","%3A"), "<","%3C"), ">","%3E") ) -> ISBN%3A9783764353704 | L26: =TRIM(_xlfn.TEXTJOIN("_",FALSE(),G26,(SUBSTITUTE(SUBSTITUTE(E26," ",""), "_", "")))) -> Baron_etal_1996_Table32 | M26: =K26 & "_" & SUBSTITUTE(SUBSTITUTE(SUBSTITUTE(E26,CHAR(160),"")," ",""),"_","") -> ISBN%3A9783764353704_Table32 | N26: {=IFERROR(INDEX(AUTO_Public_TSV_FileList!$A$1:$A$1000,MATCH(TRUE(),EXACT(M26,IFERROR(_xlfn.TEXTBEFORE(AUTO_Public_TSV_FileList!$A$1:$A$1000,".tsv"),"")),0)),"notfound")} -> ISBN%3A9783764353704_Table32.tsv | O26: BUILT 2026-08-15: 272 species; telencephalic component volumes. Two source-level component-sum conflicts are retained and reported. | P26: FINISHED | Q26: FINISHED | R26: Baron_etal_1996_Table32_snapshot.csv | S26: Source values preserved; two Table 32 versus Table 10 component-sum conflicts flagged, not corrected. | T26: Baron_etal_1996_Table32.csv | U26: Baron_etal_1996_Table32.csv | AL26: primary | AM26: primary
A27: Bauernfeind, A. L., de Sousa, A. A., Avasthi, T., Dobson, S. D., Raghanti, M. A., Lewandowski, A. H., Zilles, K., Semendeferi, K., Allman, J. M., Craig, A. D., Hof, P. R., & Sherwood, C. C. (2013). A volumetric comparison of the insular cortex and its subregions in primates. J Hum Evol, 64(4), 263-279. https://doi.org/10.1016/j.jhevol.2012.12.003 | E27: Table 1 | F27: =RIGHT(A27,1) -> 3 | G27: =H27 & IF(I27<>"", "_" & I27, "_") & IF(J27<>"", "_" & J27, "_") & IF(B27<>"", "_" & B27, "") -> Bauernfeind_etal_2013 | H27: =SUBSTITUTE(SUBSTITUTE(_xlfn.TEXTBEFORE(A27,","), "-", ""), " ", "") -> Bauernfeind | I27: =_xlfn.LET( _xlpm.authors,_xlfn.TEXTBEFORE(A27," ("&J27&")"), _xlpm.hasAmp,ISNUMBER(SEARCH("&",_xlpm.authors)), _xlpm.commasBeforeAmp,IF(_xlpm.hasAmp,LEN(_xlfn.TEXTBEFORE(_xlpm.authors,"&"))-LEN(SUBSTITUTE(_xlfn.TEXTBEFORE(_xlpm.authors,"&"),",","")),0), IF(NOT(_xlpm.hasAmp),"",IF(_xlpm.commasBeforeAmp>2,"etal",TRIM(_xlfn.TEXTBEFORE(_xlfn.TEXTAFTER(_xlpm.authors,"& "),",")))) ) -> etal | J27: =_xlfn.TEXTBEFORE(_xlfn.TEXTAFTER(A27, "("), ")") -> 2013 | K27: =_xlfn.LET( _xlpm.doi,IF(D27<>"",D27,_xlfn.TEXTAFTER(A27,"https://doi.org/")), SUBSTITUTE( SUBSTITUTE( SUBSTITUTE( SUBSTITUTE( _xlpm.doi, "/","%2F"), ":","%3A"), "<","%3C"), ">","%3E") ) -> 10.1016%2Fj.jhevol.2012.12.003 | L27: =TRIM(_xlfn.TEXTJOIN("_",FALSE(),G27,(SUBSTITUTE(SUBSTITUTE(E27," ",""), "_", "")))) -> Bauernfeind_etal_2013_Table1 | M27: =K27 & "_" & SUBSTITUTE(SUBSTITUTE(SUBSTITUTE(E27,CHAR(160),"")," ",""),"_","") -> 10.1016%2Fj.jhevol.2012.12.003_Table1 | N27: {=IFERROR(INDEX(AUTO_Public_TSV_FileList!$A$1:$A$1000,MATCH(TRUE(),EXACT(M27,IFERROR(_xlfn.TEXTBEFORE(AUTO_Public_TSV_FileList!$A$1:$A$1000,".tsv"),"")),0)),"notfound")} -> 10.1016%2Fj.jhevol.2012.12.003_Table1.tsv | O27: Volumetric comparison of the insular cortex (Table 1) | Q27: FINISHED | W27: table | Z27: Stephan, Sherwood | AG27: histological sections | AH27: volumetry | AJ27: insular cortex volumes | AK27: Primates | AL27: primary | AM27: primary | AN27: volume
A28: Bauernfeind, A. L., de Sousa, A. A., Avasthi, T., Dobson, S. D., Raghanti, M. A., Lewandowski, A. H., Zilles, K., Semendeferi, K., Allman, J. M., Craig, A. D., Hof, P. R., & Sherwood, C. C. (2013). A volumetric comparison of the insular cortex and its subregions in primates. J Hum Evol, 64(4), 263-279. https://doi.org/10.1016/j.jhevol.2012.12.003 | E28: Table 2 | F28: =RIGHT(A28,1) -> 3 | G28: =H28 & IF(I28<>"", "_" & I28, "_") & IF(J28<>"", "_" & J28, "_") & IF(B28<>"", "_" & B28, "") -> Bauernfeind_etal_2013 | H28: =SUBSTITUTE(SUBSTITUTE(_xlfn.TEXTBEFORE(A28,","), "-", ""), " ", "") -> Bauernfeind | I28: =_xlfn.LET( _xlpm.authors,_xlfn.TEXTBEFORE(A28," ("&J28&")"), _xlpm.hasAmp,ISNUMBER(SEARCH("&",_xlpm.authors)), _xlpm.commasBeforeAmp,IF(_xlpm.hasAmp,LEN(_xlfn.TEXTBEFORE(_xlpm.authors,"&"))-LEN(SUBSTITUTE(_xlfn.TEXTBEFORE(_xlpm.authors,"&"),",","")),0), IF(NOT(_xlpm.hasAmp),"",IF(_xlpm.commasBeforeAmp>2,"etal",TRIM(_xlfn.TEXTBEFORE(_xlfn.TEXTAFTER(_xlpm.authors,"& "),",")))) ) -> etal | J28: =_xlfn.TEXTBEFORE(_xlfn.TEXTAFTER(A28, "("), ")") -> 2013 | K28: =_xlfn.LET( _xlpm.doi,IF(D28<>"",D28,_xlfn.TEXTAFTER(A28,"https://doi.org/")), SUBSTITUTE( SUBSTITUTE( SUBSTITUTE( SUBSTITUTE( _xlpm.doi, "/","%2F"), ":","%3A"), "<","%3C"), ">","%3E") ) -> 10.1016%2Fj.jhevol.2012.12.003 | L28: =TRIM(_xlfn.TEXTJOIN("_",FALSE(),G28,(SUBSTITUTE(SUBSTITUTE(E28," ",""), "_", "")))) -> Bauernfeind_etal_2013_Table2 | M28: =K28 & "_" & SUBSTITUTE(SUBSTITUTE(SUBSTITUTE(E28,CHAR(160),"")," ",""),"_","") -> 10.1016%2Fj.jhevol.2012.12.003_Table2 | N28: {=IFERROR(INDEX(AUTO_Public_TSV_FileList!$A$1:$A$1000,MATCH(TRUE(),EXACT(M28,IFERROR(_xlfn.TEXTBEFORE(AUTO_Public_TSV_FileList!$A$1:$A$1000,".tsv"),"")),0)),"notfound")} -> 10.1016%2Fj.jhevol.2012.12.003_Table2.tsv | Q28: FINISHED | W28: table | Z28: Stephan, Sherwood | AG28: histological sections | AH28: volumetry | AJ28: insular cortex volumes | AK28: Primates | AL28: primary | AM28: primary | AN28: volume
A29: Bauernfeind, A. L., de Sousa, A. A., Avasthi, T., Dobson, S. D., Raghanti, M. A., Lewandowski, A. H., Zilles, K., Semendeferi, K., Allman, J. M., Craig, A. D., Hof, P. R., & Sherwood, C. C. (2013). A volumetric comparison of the insular cortex and its subregions in primates. J Hum Evol, 64(4), 263-279. https://doi.org/10.1016/j.jhevol.2012.12.003 | E29: Table 3 | F29: =RIGHT(A29,1) -> 3 | G29: =H29 & IF(I29<>"", "_" & I29, "_") & IF(J29<>"", "_" & J29, "_") & IF(B29<>"", "_" & B29, "") -> Bauernfeind_etal_2013 | H29: =SUBSTITUTE(SUBSTITUTE(_xlfn.TEXTBEFORE(A29,","), "-", ""), " ", "") -> Bauernfeind | I29: =_xlfn.LET( _xlpm.authors,_xlfn.TEXTBEFORE(A29," ("&J29&")"), _xlpm.hasAmp,ISNUMBER(SEARCH("&",_xlpm.authors)), _xlpm.commasBeforeAmp,IF(_xlpm.hasAmp,LEN(_xlfn.TEXTBEFORE(_xlpm.authors,"&"))-LEN(SUBSTITUTE(_xlfn.TEXTBEFORE(_xlpm.authors,"&"),",","")),0), IF(NOT(_xlpm.hasAmp),"",IF(_xlpm.commasBeforeAmp>2,"etal",TRIM(_xlfn.TEXTBEFORE(_xlfn.TEXTAFTER(_xlpm.authors,"& "),",")))) ) -> etal | J29: =_xlfn.TEXTBEFORE(_xlfn.TEXTAFTER(A29, "("), ")") -> 2013 | K29: =_xlfn.LET( _xlpm.doi,IF(D29<>"",D29,_xlfn.TEXTAFTER(A29,"https://doi.org/")), SUBSTITUTE( SUBSTITUTE( SUBSTITUTE( SUBSTITUTE( _xlpm.doi, "/","%2F"), ":","%3A"), "<","%3C"), ">","%3E") ) -> 10.1016%2Fj.jhevol.2012.12.003 | L29: =TRIM(_xlfn.TEXTJOIN("_",FALSE(),G29,(SUBSTITUTE(SUBSTITUTE(E29," ",""), "_", "")))) -> Bauernfeind_etal_2013_Table3 | M29: =K29 & "_" & SUBSTITUTE(SUBSTITUTE(SUBSTITUTE(E29,CHAR(160),"")," ",""),"_","") -> 10.1016%2Fj.jhevol.2012.12.003_Table3 | N29: {=IFERROR(INDEX(AUTO_Public_TSV_FileList!$A$1:$A$1000,MATCH(TRUE(),EXACT(M29,IFERROR(_xlfn.TEXTBEFORE(AUTO_Public_TSV_FileList!$A$1:$A$1000,".tsv"),"")),0)),"notfound")} -> 10.1016%2Fj.jhevol.2012.12.003_Table3.tsv | W29: table | Z29: Stephan, Sherwood | AG29: histological sections | AH29: volumetry | AJ29: insular cortex volumes | AK29: Primates | AL29: primary | AM29: primary | AN29: volume
A30: Bortoff, G. A., & Strick, P. L. (1993). Corticospinal terminations in two New-World primates: Further evidence that corticomotoneuronal connections provide part of the neural substrate for manual dexterity. The Journal of Neuroscience, 13(12), 5105–5118. https://doi.org/10.1523/JNEUROSCI.13-12-05105.1993 | E30: Table 1 | F30: =RIGHT(A30,1) -> 3 | G30: =H30 & IF(I30<>"", "_" & I30, "_") & IF(J30<>"", "_" & J30, "_") & IF(B30<>"", "_" & B30, "") -> Bortoff_Strick_1993 | H30: =SUBSTITUTE(SUBSTITUTE(_xlfn.TEXTBEFORE(A30,","), "-", ""), " ", "") -> Bortoff | I30: =_xlfn.LET( _xlpm.authors,_xlfn.TEXTBEFORE(A30," ("&J30&")"), _xlpm.hasAmp,ISNUMBER(SEARCH("&",_xlpm.authors)), _xlpm.commasBeforeAmp,IF(_xlpm.hasAmp,LEN(_xlfn.TEXTBEFORE(_xlpm.authors,"&"))-LEN(SUBSTITUTE(_xlfn.TEXTBEFORE(_xlpm.authors,"&"),",","")),0), IF(NOT(_xlpm.hasAmp),"",IF(_xlpm.commasBeforeAmp>2,"etal",TRIM(_xlfn.TEXTBEFORE(_xlfn.TEXTAFTER(_xlpm.authors,"& "),",")))) ) -> Strick | J30: =_xlfn.TEXTBEFORE(_xlfn.TEXTAFTER(A30, "("), ")") -> 1993 | K30: =_xlfn.LET( _xlpm.doi,IF(D30<>"",D30,_xlfn.TEXTAFTER(A30,"https://doi.org/")), SUBSTITUTE( SUBSTITUTE( SUBSTITUTE( SUBSTITUTE( _xlpm.doi, "/","%2F"), ":","%3A"), "<","%3C"), ">","%3E") ) -> 10.1523%2FJNEUROSCI.13-12-05105.1993 | L30: =TRIM(_xlfn.TEXTJOIN("_",FALSE(),G30,(SUBSTITUTE(SUBSTITUTE(E30," ",""), "_", "")))) -> Bortoff_Strick_1993_Table1 | M30: =K30 & "_" & SUBSTITUTE(SUBSTITUTE(SUBSTITUTE(E30,CHAR(160),"")," ",""),"_","") -> 10.1523%2FJNEUROSCI.13-12-05105.1993_Table1 | N30: {=IFERROR(INDEX(AUTO_Public_TSV_FileList!$A$1:$A$1000,MATCH(TRUE(),EXACT(M30,IFERROR(_xlfn.TEXTBEFORE(AUTO_Public_TSV_FileList!$A$1:$A$1000,".tsv"),"")),0)),"notfound")} -> 10.1523%2FJNEUROSCI.13-12-05105.1993_Table1.tsv | O30: Curated Table 1. Species-specific corticospinal termination extent and CM-connection inference | P30: Conservative curatorial compilation from Bortoff & Strick (1993) primary tract-tracing evidence. | Q30: FINISHED | R30: Europe PMC | S30: Bortoff_Strick_1993_Table1_snapshot.xlsx | T30: Y | U30: Bortoff_Strick_1993_Table1.csv | V30: pdf + curated snapshot | W30: table | X30: https://europepmc.org/articles/PMC6575756?pdf=render | Y30: https://doi.org/10.1523/JNEUROSCI.13-12-05105.1993 | Z30: Bortoff/Strick | AB30: CST ventral-horn / lamina IX termination extent; CM-connection inference | AC30: Two New-World primate species. Grade 0–2 is coded only from explicit species-level terminal-field evidence. CM_monosynaptic remains blank because light microscopy cannot establish direct monosynaptic presence or absence; likely/against is retained separately as inference. Data role = PRIMARY: the WGA-HRP result is Bortoff & Strick’s own, only the 0–2 grading is curatorial (see reference_tables/..._definitions.csv, Method:coding). Keyed on the article DOI — the earlier COMPILATION:Corticospinal_terminations override was removed 2026-08-15; a second CST paper gets its own folder and is pooled in __merging_behaviour, not appended to this table. | AG30: two New-World primate species | AH30: WGA-HRP anterograde tract tracing from primary motor cortex | AI30: spinal cord / M1 output | AJ30: corticospinal termination extent and corticomotoneuronal inference | AK30: Primates | AL30: primary (own WGA-HRP tract tracing); ordinal grade is curated | AM30: primary | AN30: ordinal anatomical grade + qualitative inference
A31: Boyer, D. M., & Harrington, A. R. (2018). Scaling of bony canals for encephalic vessels in euarchontans: Implications for the role of the vertebral artery and brain metabolism. J Hum Evol, 114, 85-101. https://doi.org/10.1016/j.jhevol.2017.09.003 | E31: Table 1 | F31: =RIGHT(A31,1) -> 3 | G31: =H31 & IF(I31<>"", "_" & I31, "_") & IF(J31<>"", "_" & J31, "_") & IF(B31<>"", "_" & B31, "") -> Boyer_Harrington_2018 | H31: =SUBSTITUTE(SUBSTITUTE(_xlfn.TEXTBEFORE(A31,","), "-", ""), " ", "") -> Boyer | I31: =_xlfn.LET( _xlpm.authors,_xlfn.TEXTBEFORE(A31," ("&J31&")"), _xlpm.hasAmp,ISNUMBER(SEARCH("&",_xlpm.authors)), _xlpm.commasBeforeAmp,IF(_xlpm.hasAmp,LEN(_xlfn.TEXTBEFORE(_xlpm.authors,"&"))-LEN(SUBSTITUTE(_xlfn.TEXTBEFORE(_xlpm.authors,"&"),",","")),0), IF(NOT(_xlpm.hasAmp),"",IF(_xlpm.commasBeforeAmp>2,"etal",TRIM(_xlfn.TEXTBEFORE(_xlfn.TEXTAFTER(_xlpm.authors,"& "),",")))) ) -> Harrington | J31: =_xlfn.TEXTBEFORE(_xlfn.TEXTAFTER(A31, "("), ")") -> 2018 | K31: =_xlfn.LET( _xlpm.doi,IF(D31<>"",D31,_xlfn.TEXTAFTER(A31,"https://doi.org/")), SUBSTITUTE( SUBSTITUTE( SUBSTITUTE( SUBSTITUTE( _xlpm.doi, "/","%2F"), ":","%3A"), "<","%3C"), ">","%3E") ) -> 10.1016%2Fj.jhevol.2017.09.003 | L31: =TRIM(_xlfn.TEXTJOIN("_",FALSE(),G31,(SUBSTITUTE(SUBSTITUTE(E31," ",""), "_", "")))) -> Boyer_Harrington_2018_Table1 | M31: =K31 & "_" & SUBSTITUTE(SUBSTITUTE(SUBSTITUTE(E31,CHAR(160),"")," ",""),"_","") -> 10.1016%2Fj.jhevol.2017.09.003_Table1 | N31: {=IFERROR(INDEX(AUTO_Public_TSV_FileList!$A$1:$A$1000,MATCH(TRUE(),EXACT(M31,IFERROR(_xlfn.TEXTBEFORE(AUTO_Public_TSV_FileList!$A$1:$A$1000,".tsv"),"")),0)),"notfound")} -> 10.1016%2Fj.jhevol.2017.09.003_Table1.tsv | O31: Table 1 Taxon list and species mean values.
