Workbook

Sheet Sheet1
A1: Citation (APA 7th-Annotated) | B1: sequence | C1: DOI if different from article or doi Alt | D1: Item number | E1: 1st Author | F1: other author(s) | G1: year | H1: Publication name | I1: DOI (or Alt) | J1: Item name | K1: Item encoded | L1: Public TSV match from AUTO_Public_TSV_FileList (generated by _tools/file_list.R; do not edit manually) | M1: Item full original title | N1: Source format | O1: N.B. | P1: Progress stage | Q1: Snapshot name if unchanged | R1: Source URL link | S1: Flags pre-addressed | T1: Flags possible | U1: Flags active (skips) | V1: Topic | W1: Taxon | X1: Main Trait(s) | Y1: Other Trait(s) | Z1: Material type (e.g. histological, MRI) | AA1: Method | AB1: Measure type | AC1: Team | AD1: Collection | AE1: Data role (primary/secondary/both) | AF1: Source (if secondary) | AG1: recommendation
A2: Andelin, A. K., Olavarria, J. F., Fine, I., Taber, E. N., Schwartz, D., Kroenke, C. D., & Stevens, A. A. (2019). The Effect of Onset Age of Visual Deprivation on Visual Cortex Surface Area Across-Species. Cereb Cortex, 29(10), 4321-4333. https://doi.org/10.1093/cercor/bhy315 | D2: Table 4 | E2: =SUBSTITUTE(SUBSTITUTE(_xlfn.TEXTBEFORE(A2,","), "-", ""), " ", "") -> Andelin | F2: {=_xlfn.LET( _xlpm.authors,_xlfn.TEXTBEFORE(A2," ("&G2&")"), _xlpm.hasAmp,ISNUMBER(SEARCH("&",_xlpm.authors)), _xlpm.hasEllipsis,ISNUMBER(SEARCH(_xlfn.UNICHAR(8230),_xlpm.authors)), _xlpm.commasBeforeAmp,IF( _xlpm.hasAmp, LEN(_xlfn.TEXTBEFORE(_xlpm.authors,"&"))-LEN(SUBSTITUTE(_xlfn.TEXTBEFORE(_xlpm.authors,"&"),",","")), 0 ), IF( _xlpm.hasEllipsis, "etal", IF( NOT(_xlpm.hasAmp), "", IF( _xlpm.commasBeforeAmp>2, "etal", SUBSTITUTE(TRIM(_xlfn.TEXTBEFORE(_xlfn.TEXTAFTER(_xlpm.authors,"& "),",")),"-","") ) ) ) )} -> etal | G2: =_xlfn.TEXTBEFORE(_xlfn.TEXTAFTER(A2, "("), ")") -> 2019 | H2: =E2 & IF(F2<>"", "_" & F2, "_") & IF(G2<>"", "_" & G2, "_") & IF(B2<>"", "_" & B2, "") -> Andelin_etal_2019 | I2: =_xlfn.LET( _xlpm.doi,IF(C2<>"",C2,_xlfn.TEXTAFTER(A2,"https://doi.org/")), SUBSTITUTE( SUBSTITUTE( SUBSTITUTE( SUBSTITUTE( _xlpm.doi, "/","%2F"), ":","%3A"), "<","%3C"), ">","%3E") ) -> 10.1093%2Fcercor%2Fbhy315 | J2: =TRIM(_xlfn.TEXTJOIN("_",FALSE(),H2,(SUBSTITUTE(SUBSTITUTE(D2," ",""), "_", "")))) -> Andelin_etal_2019_Table4 | K2: =I2 & "_" & SUBSTITUTE(SUBSTITUTE(SUBSTITUTE(D2,CHAR(160),"")," ",""),"_","") -> 10.1093%2Fcercor%2Fbhy315_Table4 | L2: {=IFERROR(INDEX(AUTO_Public_TSV_FileList!$A$1:$A$1000,MATCH(TRUE(),EXACT(K2,IFERROR(_xlfn.TEXTBEFORE(AUTO_Public_TSV_FileList!$A$1:$A$1000,".tsv"),"")),0)),"notfound")} -> 10.1093%2Fcercor%2Fbhy315_Table4.tsv | N2: table | P2: FINISHED
A3: Armstrong, E. (1979). Quantitative comparison of the hominoid thalamus. I. Specific sensory relay nuclei. Am J Phys Anthropol, 51(3), 365-382. https://doi.org/10.1002/ajpa.1330510308 | D3: Tables 1-9 | E3: =SUBSTITUTE(SUBSTITUTE(_xlfn.TEXTBEFORE(A3,","), "-", ""), " ", "") -> Armstrong | F3: {=_xlfn.LET( _xlpm.authors,_xlfn.TEXTBEFORE(A3," ("&G3&")"), _xlpm.hasAmp,ISNUMBER(SEARCH("&",_xlpm.authors)), _xlpm.hasEllipsis,ISNUMBER(SEARCH(_xlfn.UNICHAR(8230),_xlpm.authors)), _xlpm.commasBeforeAmp,IF( _xlpm.hasAmp, LEN(_xlfn.TEXTBEFORE(_xlpm.authors,"&"))-LEN(SUBSTITUTE(_xlfn.TEXTBEFORE(_xlpm.authors,"&"),",","")), 0 ), IF( _xlpm.hasEllipsis, "etal", IF( NOT(_xlpm.hasAmp), "", IF( _xlpm.commasBeforeAmp>2, "etal", SUBSTITUTE(TRIM(_xlfn.TEXTBEFORE(_xlfn.TEXTAFTER(_xlpm.authors,"& "),",")),"-","") ) ) ) )} | G3: =_xlfn.TEXTBEFORE(_xlfn.TEXTAFTER(A3, "("), ")") -> 1979 | H3: =E3 & IF(F3<>"", "_" & F3, "_") & IF(G3<>"", "_" & G3, "_") & IF(B3<>"", "_" & B3, "") -> Armstrong__1979 | I3: =_xlfn.LET(_xlpm.doi,IF(C3<>"",C3,_xlfn.TEXTAFTER(A3,"https://doi.org/")),SUBSTITUTE(SUBSTITUTE(SUBSTITUTE(SUBSTITUTE(_xlpm.doi,"/","%2F"),":","%3A"),"<","%3C"),">","%3E")) -> 10.1002%2Fajpa.1330510308 | J3: =TRIM(_xlfn.TEXTJOIN("_",FALSE(),H3,(SUBSTITUTE(SUBSTITUTE(D3," ",""), "_", "")))) -> Armstrong__1979_Tables1-9 | K3: =I3 & "_" & SUBSTITUTE(SUBSTITUTE(SUBSTITUTE(D3,CHAR(160),"")," ",""),"_","") -> 10.1002%2Fajpa.1330510308_Tables1-9 | L3: {=IFERROR(INDEX(AUTO_Public_TSV_FileList!$A$1:$A$1000,MATCH(TRUE(),EXACT(K3,IFERROR(_xlfn.TEXTBEFORE(AUTO_Public_TSV_FileList!$A$1:$A$1000,".tsv"),"")),0)),"notfound")} -> 10.1002%2Fajpa.1330510308_Tables1-9.tsv | M3: Tables 1-9. Hominoid thalamic sensory-relay nucleus volumes, neuronal densities and numbers, and neuronal-volume distributions | N3: tables | O3: Primary mixed-datatype series. Table 1 provides LGB, MGBp and VB volumes plus percent of dorsal thalamus; Tables 2-4 density; Table 5 LGB subcomponent volumes; Table 6 neuron counts; Tables 7-9 neuronal perikaryal-volume distributions. Split during build. | P3: FINISHED | R3: https://doi.org/10.1002/ajpa.1330510308 | T3: mixed datatypes; specimen abbreviations require a specimen crosswalk; some literature-comparison rows are secondary | V3: thalamic sensory relay nuclei | W3: Hominoids | X3: regional volumes; neuronal density and number; neuronal size | Y3: LGB/LGBd; MGB parvocellular; ventrobasal complex; dorsal thalamus proportion; neuronal density; neuron number; neuronal perikaryal volume | AA3: histological volumetry; neuronal density/count estimation; neuronal perikaryal morphometry | AB3: volume + cell density/count + neuronal perikaryal volume | AC3: Armstrong | AE3: both | AG3: Keep specimen-level records and separate regional volume, cell density/count, and cell-size outputs.
A4: Ashwell, K. W. S. (2020). Quantitative analysis of cerebellar morphology in monotreme, metatherian and eutherian mammals. Zoology (Jena), 139, 125753. https://doi.org/10.1016/j.zool.2020.125753 | D4: Supplementary Table | E4: =SUBSTITUTE(SUBSTITUTE(_xlfn.TEXTBEFORE(A4,","), "-", ""), " ", "") -> Ashwell | F4: {=_xlfn.LET( _xlpm.authors,_xlfn.TEXTBEFORE(A4," ("&G4&")"), _xlpm.hasAmp,ISNUMBER(SEARCH("&",_xlpm.authors)), _xlpm.hasEllipsis,ISNUMBER(SEARCH(_xlfn.UNICHAR(8230),_xlpm.authors)), _xlpm.commasBeforeAmp,IF( _xlpm.hasAmp, LEN(_xlfn.TEXTBEFORE(_xlpm.authors,"&"))-LEN(SUBSTITUTE(_xlfn.TEXTBEFORE(_xlpm.authors,"&"),",","")), 0 ), IF( _xlpm.hasEllipsis, "etal", IF( NOT(_xlpm.hasAmp), "", IF( _xlpm.commasBeforeAmp>2, "etal", SUBSTITUTE(TRIM(_xlfn.TEXTBEFORE(_xlfn.TEXTAFTER(_xlpm.authors,"& "),",")),"-","") ) ) ) )} | G4: =_xlfn.TEXTBEFORE(_xlfn.TEXTAFTER(A4, "("), ")") -> 2020 | H4: =E4 & IF(F4<>"", "_" & F4, "_") & IF(G4<>"", "_" & G4, "_") & IF(B4<>"", "_" & B4, "") -> Ashwell__2020 | I4: =_xlfn.LET( _xlpm.doi,IF(C4<>"",C4,_xlfn.TEXTAFTER(A4,"https://doi.org/")), SUBSTITUTE( SUBSTITUTE( SUBSTITUTE( SUBSTITUTE( _xlpm.doi, "/","%2F"), ":","%3A"), "<","%3C"), ">","%3E") ) -> 10.1016%2Fj.zool.2020.125753 | J4: =TRIM(_xlfn.TEXTJOIN("_",FALSE(),H4,(SUBSTITUTE(SUBSTITUTE(D4," ",""), "_", "")))) -> Ashwell__2020_SupplementaryTable | K4: =I4 & "_" & SUBSTITUTE(SUBSTITUTE(SUBSTITUTE(D4,CHAR(160),"")," ",""),"_","") -> 10.1016%2Fj.zool.2020.125753_SupplementaryTable | L4: {=IFERROR(INDEX(AUTO_Public_TSV_FileList!$A$1:$A$1000,MATCH(TRUE(),EXACT(K4,IFERROR(_xlfn.TEXTBEFORE(AUTO_Public_TSV_FileList!$A$1:$A$1000,".tsv"),"")),0)),"notfound")} -> 10.1016%2Fj.zool.2020.125753_SupplementaryTable.tsv | M4: Supplementary Table. Cerebellar Morphology Data | P4: FINISHED | AC4: Ashwell
A5: Avelino-de-Souza, K., Patzke, N., Karlsson, K. A. E., Manger, P. R., & Herculano-Houzel, S. (2025). Cellular Composition of the Brain of a Northern Minke Whale. J Comp Neurol, 533(9), e70089. https://doi.org/10.1002/cne.70089 | D5: TABLE 1 | E5: =SUBSTITUTE(SUBSTITUTE(_xlfn.TEXTBEFORE(A5,","), "-", ""), " ", "") -> AvelinodeSouza | F5: {=_xlfn.LET( _xlpm.authors,_xlfn.TEXTBEFORE(A5," ("&G5&")"), _xlpm.hasAmp,ISNUMBER(SEARCH("&",_xlpm.authors)), _xlpm.hasEllipsis,ISNUMBER(SEARCH(_xlfn.UNICHAR(8230),_xlpm.authors)), _xlpm.commasBeforeAmp,IF( _xlpm.hasAmp, LEN(_xlfn.TEXTBEFORE(_xlpm.authors,"&"))-LEN(SUBSTITUTE(_xlfn.TEXTBEFORE(_xlpm.authors,"&"),",","")), 0 ), IF( _xlpm.hasEllipsis, "etal", IF( NOT(_xlpm.hasAmp), "", IF( _xlpm.commasBeforeAmp>2, "etal", SUBSTITUTE(TRIM(_xlfn.TEXTBEFORE(_xlfn.TEXTAFTER(_xlpm.authors,"& "),",")),"-","") ) ) ) )} -> etal | G5: =_xlfn.TEXTBEFORE(_xlfn.TEXTAFTER(A5, "("), ")") -> 2025 | H5: =E5 & IF(F5<>"", "_" & F5, "_") & IF(G5<>"", "_" & G5, "_") & IF(B5<>"", "_" & B5, "") -> AvelinodeSouza_etal_2025 | I5: =_xlfn.LET( _xlpm.doi,IF(C5<>"",C5,_xlfn.TEXTAFTER(A5,"https://doi.org/")), SUBSTITUTE( SUBSTITUTE( SUBSTITUTE( SUBSTITUTE( _xlpm.doi, "/","%2F"), ":","%3A"), "<","%3C"), ">","%3E") ) -> 10.1002%2Fcne.70089 | J5: =TRIM(_xlfn.TEXTJOIN("_",FALSE(),H5,(SUBSTITUTE(SUBSTITUTE(D5," ",""), "_", "")))) -> AvelinodeSouza_etal_2025_TABLE1 | K5: =I5 & "_" & SUBSTITUTE(SUBSTITUTE(SUBSTITUTE(D5,CHAR(160),"")," ",""),"_","") -> 10.1002%2Fcne.70089_TABLE1 | L5: {=IFERROR(INDEX(AUTO_Public_TSV_FileList!$A$1:$A$1000,MATCH(TRUE(),EXACT(K5,IFERROR(_xlfn.TEXTBEFORE(AUTO_Public_TSV_FileList!$A$1:$A$1000,".tsv"),"")),0)),"notfound")} -> 10.1002%2Fcne.70089_TABLE1.tsv | M5: Table 1. Cellular composition of the brain of a Northern minke whale (Balaenoptera acutorostrata) | N5: table | P5: FINISHED | R5: https://doi.org/10.1002/cne.70089 | W5: Cetaceans & others | X5: neuron number | AA5: isotropic fractionator | AB5: cell count | AC5: HH | AE5: primary
A6: Baker, J., Barton, R. A., & Venditti, C. (2025). Human dexterity and brains evolved hand in hand. Communications Biology, 8(1). https://doi.org/10.1038/s42003-025-08686-5 | D6: Supplementary Data 1 | E6: =SUBSTITUTE(SUBSTITUTE(_xlfn.TEXTBEFORE(A6,","), "-", ""), " ", "") -> Baker | F6: {=_xlfn.LET( _xlpm.authors,_xlfn.TEXTBEFORE(A6," ("&G6&")"), _xlpm.hasAmp,ISNUMBER(SEARCH("&",_xlpm.authors)), _xlpm.hasEllipsis,ISNUMBER(SEARCH(_xlfn.UNICHAR(8230),_xlpm.authors)), _xlpm.commasBeforeAmp,IF( _xlpm.hasAmp, LEN(_xlfn.TEXTBEFORE(_xlpm.authors,"&"))-LEN(SUBSTITUTE(_xlfn.TEXTBEFORE(_xlpm.authors,"&"),",","")), 0 ), IF( _xlpm.hasEllipsis, "etal", IF( NOT(_xlpm.hasAmp), "", IF( _xlpm.commasBeforeAmp>2, "etal", SUBSTITUTE(TRIM(_xlfn.TEXTBEFORE(_xlfn.TEXTAFTER(_xlpm.authors,"& "),",")),"-","") ) ) ) )} -> etal | G6: =_xlfn.TEXTBEFORE(_xlfn.TEXTAFTER(A6, "("), ")") -> 2025 | H6: =E6 & IF(F6<>"", "_" & F6, "_") & IF(G6<>"", "_" & G6, "_") & IF(B6<>"", "_" & B6, "") -> Baker_etal_2025 | I6: =_xlfn.LET( _xlpm.doi,IF(C6<>"",C6,_xlfn.TEXTAFTER(A6,"https://doi.org/")), SUBSTITUTE( SUBSTITUTE( SUBSTITUTE( SUBSTITUTE( _xlpm.doi, "/","%2F"), ":","%3A"), "<","%3C"), ">","%3E") ) -> 10.1038%2Fs42003-025-08686-5 | J6: =TRIM(_xlfn.TEXTJOIN("_",FALSE(),H6,(SUBSTITUTE(SUBSTITUTE(D6," ",""), "_", "")))) -> Baker_etal_2025_SupplementaryData1 | K6: =I6 & "_" & SUBSTITUTE(SUBSTITUTE(SUBSTITUTE(D6,CHAR(160),"")," ",""),"_","") -> 10.1038%2Fs42003-025-08686-5_SupplementaryData1 | L6: {=IFERROR(INDEX(AUTO_Public_TSV_FileList!$A$1:$A$1000,MATCH(TRUE(),EXACT(K6,IFERROR(_xlfn.TEXTBEFORE(AUTO_Public_TSV_FileList!$A$1:$A$1000,".tsv"),"")),0)),"notfound")} -> 10.1038%2Fs42003-025-08686-5_SupplementaryData1.tsv | P6: FINISHED
A7: Balzeau, A., Holloway, R. L., & Grimaud-Hervé, D. (2012). Variations and asymmetries in regional brain surface in the genus Homo. J Hum Evol, 62(6), 696-706. https://doi.org/10.1016/j.jhevol.2012.03.007 | D7: Table 2 | E7: =SUBSTITUTE(SUBSTITUTE(_xlfn.TEXTBEFORE(A7,","), "-", ""), " ", "") -> Balzeau | F7: {=_xlfn.LET( _xlpm.authors,_xlfn.TEXTBEFORE(A7," ("&G7&")"), _xlpm.hasAmp,ISNUMBER(SEARCH("&",_xlpm.authors)), _xlpm.hasEllipsis,ISNUMBER(SEARCH(_xlfn.UNICHAR(8230),_xlpm.authors)), _xlpm.commasBeforeAmp,IF( _xlpm.hasAmp, LEN(_xlfn.TEXTBEFORE(_xlpm.authors,"&"))-LEN(SUBSTITUTE(_xlfn.TEXTBEFORE(_xlpm.authors,"&"),",","")), 0 ), IF( _xlpm.hasEllipsis, "etal", IF( NOT(_xlpm.hasAmp), "", IF( _xlpm.commasBeforeAmp>2, "etal", SUBSTITUTE(TRIM(_xlfn.TEXTBEFORE(_xlfn.TEXTAFTER(_xlpm.authors,"& "),",")),"-","") ) ) ) )} -> etal | G7: =_xlfn.TEXTBEFORE(_xlfn.TEXTAFTER(A7, "("), ")") -> 2012 | H7: =E7 & IF(F7<>"", "_" & F7, "_") & IF(G7<>"", "_" & G7, "_") & IF(B7<>"", "_" & B7, "") -> Balzeau_etal_2012 | I7: =_xlfn.LET( _xlpm.doi,IF(C7<>"",C7,_xlfn.TEXTAFTER(A7,"https://doi.org/")), SUBSTITUTE( SUBSTITUTE( SUBSTITUTE( SUBSTITUTE( _xlpm.doi, "/","%2F"), ":","%3A"), "<","%3C"), ">","%3E") ) -> 10.1016%2Fj.jhevol.2012.03.007 | J7: =TRIM(_xlfn.TEXTJOIN("_",FALSE(),H7,(SUBSTITUTE(SUBSTITUTE(D7," ",""), "_", "")))) -> Balzeau_etal_2012_Table2 | K7: =I7 & "_" & SUBSTITUTE(SUBSTITUTE(SUBSTITUTE(D7,CHAR(160),"")," ",""),"_","") -> 10.1016%2Fj.jhevol.2012.03.007_Table2 | L7: {=IFERROR(INDEX(AUTO_Public_TSV_FileList!$A$1:$A$1000,MATCH(TRUE(),EXACT(K7,IFERROR(_xlfn.TEXTBEFORE(AUTO_Public_TSV_FileList!$A$1:$A$1000,".tsv"),"")),0)),"notfound")} -> 10.1016%2Fj.jhevol.2012.03.007_Table2.tsv | M7: Table 2. Regression results for the relationship between endocranial volume and the surface of the frontal, parieto-temporal and occipital lobes. | P7: FINISHED
A8: Balzeau, A., Holloway, R. L., & Grimaud-Hervé, D. (2012). Variations and asymmetries in regional brain surface in the genus Homo. J Hum Evol, 62(6), 696-706. https://doi.org/10.1016/j.jhevol.2012.03.007 | D8: Table 3 | E8: =SUBSTITUTE(SUBSTITUTE(_xlfn.TEXTBEFORE(A8,","), "-", ""), " ", "") -> Balzeau | F8: {=_xlfn.LET( _xlpm.authors,_xlfn.TEXTBEFORE(A8," ("&G8&")"), _xlpm.hasAmp,ISNUMBER(SEARCH("&",_xlpm.authors)), _xlpm.hasEllipsis,ISNUMBER(SEARCH(_xlfn.UNICHAR(8230),_xlpm.authors)), _xlpm.commasBeforeAmp,IF( _xlpm.hasAmp, LEN(_xlfn.TEXTBEFORE(_xlpm.authors,"&"))-LEN(SUBSTITUTE(_xlfn.TEXTBEFORE(_xlpm.authors,"&"),",","")), 0 ), IF( _xlpm.hasEllipsis, "etal", IF( NOT(_xlpm.hasAmp), "", IF( _xlpm.commasBeforeAmp>2, "etal", SUBSTITUTE(TRIM(_xlfn.TEXTBEFORE(_xlfn.TEXTAFTER(_xlpm.authors,"& "),",")),"-","") ) ) ) )} -> etal | G8: =_xlfn.TEXTBEFORE(_xlfn.TEXTAFTER(A8, "("), ")") -> 2012 | H8: =E8 & IF(F8<>"", "_" & F8, "_") & IF(G8<>"", "_" & G8, "_") & IF(B8<>"", "_" & B8, "") -> Balzeau_etal_2012 | I8: =_xlfn.LET( _xlpm.doi,IF(C8<>"",C8,_xlfn.TEXTAFTER(A8,"https://doi.org/")), SUBSTITUTE( SUBSTITUTE( SUBSTITUTE( SUBSTITUTE( _xlpm.doi, "/","%2F"), ":","%3A"), "<","%3C"), ">","%3E") ) -> 10.1016%2Fj.jhevol.2012.03.007 | J8: =TRIM(_xlfn.TEXTJOIN("_",FALSE(),H8,(SUBSTITUTE(SUBSTITUTE(D8," ",""), "_", "")))) -> Balzeau_etal_2012_Table3 | K8: =I8 & "_" & SUBSTITUTE(SUBSTITUTE(SUBSTITUTE(D8,CHAR(160),"")," ",""),"_","") -> 10.1016%2Fj.jhevol.2012.03.007_Table3 | L8: {=IFERROR(INDEX(AUTO_Public_TSV_FileList!$A$1:$A$1000,MATCH(TRUE(),EXACT(K8,IFERROR(_xlfn.TEXTBEFORE(AUTO_Public_TSV_FileList!$A$1:$A$1000,".tsv"),"")),0)),"notfound")} -> 10.1016%2Fj.jhevol.2012.03.007_Table3.tsv | M8: Table 3 Size-corrected dimensions for the surface of the frontal, parieto-temporal and occipital lobes in the different analysed samples. | P8: FINISHED
A9: Balzeau, A., Holloway, R. L., & Grimaud-Hervé, D. (2012). Variations and asymmetries in regional brain surface in the genus Homo. J Hum Evol, 62(6), 696-706. https://doi.org/10.1016/j.jhevol.2012.03.007 | D9: Table 5 | E9: =SUBSTITUTE(SUBSTITUTE(_xlfn.TEXTBEFORE(A9,","), "-", ""), " ", "") -> Balzeau | F9: {=_xlfn.LET( _xlpm.authors,_xlfn.TEXTBEFORE(A9," ("&G9&")"), _xlpm.hasAmp,ISNUMBER(SEARCH("&",_xlpm.authors)), _xlpm.hasEllipsis,ISNUMBER(SEARCH(_xlfn.UNICHAR(8230),_xlpm.authors)), _xlpm.commasBeforeAmp,IF( _xlpm.hasAmp, LEN(_xlfn.TEXTBEFORE(_xlpm.authors,"&"))-LEN(SUBSTITUTE(_xlfn.TEXTBEFORE(_xlpm.authors,"&"),",","")), 0 ), IF( _xlpm.hasEllipsis, "etal", IF( NOT(_xlpm.hasAmp), "", IF( _xlpm.commasBeforeAmp>2, "etal", SUBSTITUTE(TRIM(_xlfn.TEXTBEFORE(_xlfn.TEXTAFTER(_xlpm.authors,"& "),",")),"-","") ) ) ) )} -> etal | G9: =_xlfn.TEXTBEFORE(_xlfn.TEXTAFTER(A9, "("), ")") -> 2012 | H9: =E9 & IF(F9<>"", "_" & F9, "_") & IF(G9<>"", "_" & G9, "_") & IF(B9<>"", "_" & B9, "") -> Balzeau_etal_2012 | I9: =_xlfn.LET( _xlpm.doi,IF(C9<>"",C9,_xlfn.TEXTAFTER(A9,"https://doi.org/")), SUBSTITUTE( SUBSTITUTE( SUBSTITUTE( SUBSTITUTE( _xlpm.doi, "/","%2F"), ":","%3A"), "<","%3C"), ">","%3E") ) -> 10.1016%2Fj.jhevol.2012.03.007 | J9: =TRIM(_xlfn.TEXTJOIN("_",FALSE(),H9,(SUBSTITUTE(SUBSTITUTE(D9," ",""), "_", "")))) -> Balzeau_etal_2012_Table5 | K9: =I9 & "_" & SUBSTITUTE(SUBSTITUTE(SUBSTITUTE(D9,CHAR(160),"")," ",""),"_","") -> 10.1016%2Fj.jhevol.2012.03.007_Table5 | L9: {=IFERROR(INDEX(AUTO_Public_TSV_FileList!$A$1:$A$1000,MATCH(TRUE(),EXACT(K9,IFERROR(_xlfn.TEXTBEFORE(AUTO_Public_TSV_FileList!$A$1:$A$1000,".tsv"),"")),0)),"notfound")} -> 10.1016%2Fj.jhevol.2012.03.007_Table5.tsv | M9: Table 5 Percentage contribution of frontal, parieto-temporal and occipital lobes to the hemispheres. | P9: FINISHED
A10: Barbeito-Andrés, J., Castro-Fonseca, E., Qiu, L. R., Bernal, V., Lent, R., Henkelman, M., Lukowiak, K., Gleiser, P. M., Hallgrímsson, B., & González, P. N. (2019). Region-specific changes in Mus musculus brain size and cell composition under chronic nutrient restriction. J Exp Biol, 222(Pt 17). https://doi.org/10.1242/jeb.204651 | D10: cell density | E10: =SUBSTITUTE(SUBSTITUTE(_xlfn.TEXTBEFORE(A10,","), "-", ""), " ", "") -> BarbeitoAndrés | F10: {=_xlfn.LET( _xlpm.authors,_xlfn.TEXTBEFORE(A10," ("&G10&")"), _xlpm.hasAmp,ISNUMBER(SEARCH("&",_xlpm.authors)), _xlpm.hasEllipsis,ISNUMBER(SEARCH(_xlfn.UNICHAR(8230),_xlpm.authors)), _xlpm.commasBeforeAmp,IF( _xlpm.hasAmp, LEN(_xlfn.TEXTBEFORE(_xlpm.authors,"&"))-LEN(SUBSTITUTE(_xlfn.TEXTBEFORE(_xlpm.authors,"&"),",","")), 0 ), IF( _xlpm.hasEllipsis, "etal", IF( NOT(_xlpm.hasAmp), "", IF( _xlpm.commasBeforeAmp>2, "etal", SUBSTITUTE(TRIM(_xlfn.TEXTBEFORE(_xlfn.TEXTAFTER(_xlpm.authors,"& "),",")),"-","") ) ) ) )} -> etal | G10: =_xlfn.TEXTBEFORE(_xlfn.TEXTAFTER(A10, "("), ")") -> 2019 | H10: =E10 & IF(F10<>"", "_" & F10, "_") & IF(G10<>"", "_" & G10, "_") & IF(B10<>"", "_" & B10, "") -> BarbeitoAndrés_etal_2019 | I10: =_xlfn.LET( _xlpm.doi,IF(C10<>"",C10,_xlfn.TEXTAFTER(A10,"https://doi.org/")), SUBSTITUTE( SUBSTITUTE( SUBSTITUTE( SUBSTITUTE( _xlpm.doi, "/","%2F"), ":","%3A"), "<","%3C"), ">","%3E") ) -> 10.1242%2Fjeb.204651 | J10: =TRIM(_xlfn.TEXTJOIN("_",FALSE(),H10,(SUBSTITUTE(SUBSTITUTE(D10," ",""), "_", "")))) -> BarbeitoAndrés_etal_2019_celldensity | K10: =I10 & "_" & SUBSTITUTE(SUBSTITUTE(SUBSTITUTE(D10,CHAR(160),"")," ",""),"_","") -> 10.1242%2Fjeb.204651_celldensity | L10: {=IFERROR(INDEX(AUTO_Public_TSV_FileList!$A$1:$A$1000,MATCH(TRUE(),EXACT(K10,IFERROR(_xlfn.TEXTBEFORE(AUTO_Public_TSV_FileList!$A$1:$A$1000,".tsv"),"")),0)),"notfound")} -> 10.1242%2Fjeb.204651_celldensity.tsv | P10: FINISHED | AA10: isotropic fractionator | AB10: cell count
A11: Barbeito-Andrés, J., Castro-Fonseca, E., Qiu, L. R., Bernal, V., Lent, R., Henkelman, M., Lukowiak, K., Gleiser, P. M., Hallgrímsson, B., & González, P. N. (2019). Region-specific changes in Mus musculus brain size and cell composition under chronic nutrient restriction. J Exp Biol, 222(Pt 17). https://doi.org/10.1242/jeb.204651 | D11: cell number | E11: =SUBSTITUTE(SUBSTITUTE(_xlfn.TEXTBEFORE(A11,","), "-", ""), " ", "") -> BarbeitoAndrés | F11: {=_xlfn.LET( _xlpm.authors,_xlfn.TEXTBEFORE(A11," ("&G11&")"), _xlpm.hasAmp,ISNUMBER(SEARCH("&",_xlpm.authors)), _xlpm.hasEllipsis,ISNUMBER(SEARCH(_xlfn.UNICHAR(8230),_xlpm.authors)), _xlpm.commasBeforeAmp,IF( _xlpm.hasAmp, LEN(_xlfn.TEXTBEFORE(_xlpm.authors,"&"))-LEN(SUBSTITUTE(_xlfn.TEXTBEFORE(_xlpm.authors,"&"),",","")), 0 ), IF( _xlpm.hasEllipsis, "etal", IF( NOT(_xlpm.hasAmp), "", IF( _xlpm.commasBeforeAmp>2, "etal", SUBSTITUTE(TRIM(_xlfn.TEXTBEFORE(_xlfn.TEXTAFTER(_xlpm.authors,"& "),",")),"-","") ) ) ) )} -> etal | G11: =_xlfn.TEXTBEFORE(_xlfn.TEXTAFTER(A11, "("), ")") -> 2019 | H11: =E11 & IF(F11<>"", "_" & F11, "_") & IF(G11<>"", "_" & G11, "_") & IF(B11<>"", "_" & B11, "") -> BarbeitoAndrés_etal_2019 | I11: =_xlfn.LET( _xlpm.doi,IF(C11<>"",C11,_xlfn.TEXTAFTER(A11,"https://doi.org/")), SUBSTITUTE( SUBSTITUTE( SUBSTITUTE( SUBSTITUTE( _xlpm.doi, "/","%2F"), ":","%3A"), "<","%3C"), ">","%3E") ) -> 10.1242%2Fjeb.204651 | J11: =TRIM(_xlfn.TEXTJOIN("_",FALSE(),H11,(SUBSTITUTE(SUBSTITUTE(D11," ",""), "_", "")))) -> BarbeitoAndrés_etal_2019_cellnumber | K11: =I11 & "_" & SUBSTITUTE(SUBSTITUTE(SUBSTITUTE(D11,CHAR(160),"")," ",""),"_","") -> 10.1242%2Fjeb.204651_cellnumber | L11: {=IFERROR(INDEX(AUTO_Public_TSV_FileList!$A$1:$A$1000,MATCH(TRUE(),EXACT(K11,IFERROR(_xlfn.TEXTBEFORE(AUTO_Public_TSV_FileList!$A$1:$A$1000,".tsv"),"")),0)),"notfound")} -> 10.1242%2Fjeb.204651_cellnumber.tsv | P11: FINISHED | AA11: isotropic fractionator | AB11: cell count
A12: Barbeito-Andrés, J., Castro-Fonseca, E., Qiu, L. R., Bernal, V., Lent, R., Henkelman, M., Lukowiak, K., Gleiser, P. M., Hallgrímsson, B., & González, P. N. (2019). Region-specific changes in Mus musculus brain size and cell composition under chronic nutrient restriction. J Exp Biol, 222(Pt 17). https://doi.org/10.1242/jeb.204651 | D12: volumes | E12: =SUBSTITUTE(SUBSTITUTE(_xlfn.TEXTBEFORE(A12,","), "-", ""), " ", "") -> BarbeitoAndrés | F12: {=_xlfn.LET( _xlpm.authors,_xlfn.TEXTBEFORE(A12," ("&G12&")"), _xlpm.hasAmp,ISNUMBER(SEARCH("&",_xlpm.authors)), _xlpm.hasEllipsis,ISNUMBER(SEARCH(_xlfn.UNICHAR(8230),_xlpm.authors)), _xlpm.commasBeforeAmp,IF( _xlpm.hasAmp, LEN(_xlfn.TEXTBEFORE(_xlpm.authors,"&"))-LEN(SUBSTITUTE(_xlfn.TEXTBEFORE(_xlpm.authors,"&"),",","")), 0 ), IF( _xlpm.hasEllipsis, "etal", IF( NOT(_xlpm.hasAmp), "", IF( _xlpm.commasBeforeAmp>2, "etal", SUBSTITUTE(TRIM(_xlfn.TEXTBEFORE(_xlfn.TEXTAFTER(_xlpm.authors,"& "),",")),"-","") ) ) ) )} -> etal | G12: =_xlfn.TEXTBEFORE(_xlfn.TEXTAFTER(A12, "("), ")") -> 2019 | H12: =E12 & IF(F12<>"", "_" & F12, "_") & IF(G12<>"", "_" & G12, "_") & IF(B12<>"", "_" & B12, "") -> BarbeitoAndrés_etal_2019 | I12: =_xlfn.LET( _xlpm.doi,IF(C12<>"",C12,_xlfn.TEXTAFTER(A12,"https://doi.org/")), SUBSTITUTE( SUBSTITUTE( SUBSTITUTE( SUBSTITUTE( _xlpm.doi, "/","%2F"), ":","%3A"), "<","%3C"), ">","%3E") ) -> 10.1242%2Fjeb.204651 | J12: =TRIM(_xlfn.TEXTJOIN("_",FALSE(),H12,(SUBSTITUTE(SUBSTITUTE(D12," ",""), "_", "")))) -> BarbeitoAndrés_etal_2019_volumes | K12: =I12 & "_" & SUBSTITUTE(SUBSTITUTE(SUBSTITUTE(D12,CHAR(160),"")," ",""),"_","") -> 10.1242%2Fjeb.204651_volumes | L12: {=IFERROR(INDEX(AUTO_Public_TSV_FileList!$A$1:$A$1000,MATCH(TRUE(),EXACT(K12,IFERROR(_xlfn.TEXTBEFORE(AUTO_Public_TSV_FileList!$A$1:$A$1000,".tsv"),"")),0)),"notfound")} -> 10.1242%2Fjeb.204651_volumes.tsv | P12: FINISHED | AA12: isotropic fractionator | AB12: cell count
A13: Barger, N., Hanson, K. L., Teffer, K., Schenker-Ahmed, N. M., & Semendeferi, K. (2014). Evidence for evolutionary specialization in human limbic structures. Front Hum Neurosci, 8, 277. https://doi.org/10.3389/fnhum.2014.00277 | D13: Table 1 | E13: =SUBSTITUTE(SUBSTITUTE(_xlfn.TEXTBEFORE(A13,","), "-", ""), " ", "") -> Barger | F13: {=_xlfn.LET( _xlpm.authors,_xlfn.TEXTBEFORE(A13," ("&G13&")"), _xlpm.hasAmp,ISNUMBER(SEARCH("&",_xlpm.authors)), _xlpm.hasEllipsis,ISNUMBER(SEARCH(_xlfn.UNICHAR(8230),_xlpm.authors)), _xlpm.commasBeforeAmp,IF( _xlpm.hasAmp, LEN(_xlfn.TEXTBEFORE(_xlpm.authors,"&"))-LEN(SUBSTITUTE(_xlfn.TEXTBEFORE(_xlpm.authors,"&"),",","")), 0 ), IF( _xlpm.hasEllipsis, "etal", IF( NOT(_xlpm.hasAmp), "", IF( _xlpm.commasBeforeAmp>2, "etal", SUBSTITUTE(TRIM(_xlfn.TEXTBEFORE(_xlfn.TEXTAFTER(_xlpm.authors,"& "),",")),"-","") ) ) ) )} -> etal | G13: =_xlfn.TEXTBEFORE(_xlfn.TEXTAFTER(A13, "("), ")") -> 2014 | H13: =E13 & IF(F13<>"", "_" & F13, "_") & IF(G13<>"", "_" & G13, "_") & IF(B13<>"", "_" & B13, "") -> Barger_etal_2014 | I13: =_xlfn.LET( _xlpm.doi,IF(C13<>"",C13,_xlfn.TEXTAFTER(A13,"https://doi.org/")), SUBSTITUTE( SUBSTITUTE( SUBSTITUTE( SUBSTITUTE( _xlpm.doi, "/","%2F"), ":","%3A"), "<","%3C"), ">","%3E") ) -> 10.3389%2Ffnhum.2014.00277 | J13: =TRIM(_xlfn.TEXTJOIN("_",FALSE(),H13,(SUBSTITUTE(SUBSTITUTE(D13," ",""), "_", "")))) -> Barger_etal_2014_Table1 | K13: =I13 & "_" & SUBSTITUTE(SUBSTITUTE(SUBSTITUTE(D13,CHAR(160),"")," ",""),"_","") -> 10.3389%2Ffnhum.2014.00277_Table1 | L13: {=IFERROR(INDEX(AUTO_Public_TSV_FileList!$A$1:$A$1000,MATCH(TRUE(),EXACT(K13,IFERROR(_xlfn.TEXTBEFORE(AUTO_Public_TSV_FileList!$A$1:$A$1000,".tsv"),"")),0)),"notfound")} -> 10.3389%2Ffnhum.2014.00277_Table1.tsv | M13: Table 1 | Volume of amygdala, hippocampus, and striatum in hominoid species collected with stereological methods. | P13: FINISHED | Z13: histological sections | AC13: Zilles | AD13: Zilles
A14: Barger, N., Stefanacci, L., & Semendeferi, K. (2007). A comparative volumetric analysis of the amygdaloid complex and basolateral division in the human and ape brain. Am J Phys Anthropol, 134(3), 392-403. https://doi.org/10.1002/ajpa.20684 | D14: TABLE 1 | E14: =SUBSTITUTE(SUBSTITUTE(_xlfn.TEXTBEFORE(A14,","), "-", ""), " ", "") -> Barger | F14: {=_xlfn.LET( _xlpm.authors,_xlfn.TEXTBEFORE(A14," ("&G14&")"), _xlpm.hasAmp,ISNUMBER(SEARCH("&",_xlpm.authors)), _xlpm.hasEllipsis,ISNUMBER(SEARCH(_xlfn.UNICHAR(8230),_xlpm.authors)), _xlpm.commasBeforeAmp,IF( _xlpm.hasAmp, LEN(_xlfn.TEXTBEFORE(_xlpm.authors,"&"))-LEN(SUBSTITUTE(_xlfn.TEXTBEFORE(_xlpm.authors,"&"),",","")), 0 ), IF( _xlpm.hasEllipsis, "etal", IF( NOT(_xlpm.hasAmp), "", IF( _xlpm.commasBeforeAmp>2, "etal", SUBSTITUTE(TRIM(_xlfn.TEXTBEFORE(_xlfn.TEXTAFTER(_xlpm.authors,"& "),",")),"-","") ) ) ) )} -> etal | G14: =_xlfn.TEXTBEFORE(_xlfn.TEXTAFTER(A14, "("), ")") -> 2007 | H14: =E14 & IF(F14<>"", "_" & F14, "_") & IF(G14<>"", "_" & G14, "_") & IF(B14<>"", "_" & B14, "") -> Barger_etal_2007 | I14: =_xlfn.LET( _xlpm.doi,IF(C14<>"",C14,_xlfn.TEXTAFTER(A14,"https://doi.org/")), SUBSTITUTE( SUBSTITUTE( SUBSTITUTE( SUBSTITUTE( _xlpm.doi, "/","%2F"), ":","%3A"), "<","%3C"), ">","%3E") ) -> 10.1002%2Fajpa.20684 | J14: =TRIM(_xlfn.TEXTJOIN("_",FALSE(),H14,(SUBSTITUTE(SUBSTITUTE(D14," ",""), "_", "")))) -> Barger_etal_2007_TABLE1 | K14: =I14 & "_" & SUBSTITUTE(SUBSTITUTE(SUBSTITUTE(D14,CHAR(160),"")," ",""),"_","") -> 10.1002%2Fajpa.20684_TABLE1 | L14: {=IFERROR(INDEX(AUTO_Public_TSV_FileList!$A$1:$A$1000,MATCH(TRUE(),EXACT(K14,IFERROR(_xlfn.TEXTBEFORE(AUTO_Public_TSV_FileList!$A$1:$A$1000,".tsv"),"")),0)),"notfound")} -> 10.1002%2Fajpa.20684_TABLE1.tsv | M14: TABLE 1. Volumetric estimates of the amygdaloid complex and the basolateral division | P14: FINISHED | W14: Apes & humans | X14: amygdala subdivision volumes | AB14: volume | AC14: Zilles | AD14: Zilles | AE14: primary
A15: Barger, N., Stefanacci, L., Schumann, C. M., Sherwood, C. C., Annese, J., Allman, J. M., Buckwalter, J. A., Hof, P. R., & Semendeferi, K. (2012). Neuronal populations in the basolateral nuclei of the amygdala are differentially increased in humans compared with apes: A stereological study. J Comp Neurol, 520(13), 3035-3054. https://doi.org/10.1002/cne.23118 | D15: Table 1 | E15: =SUBSTITUTE(SUBSTITUTE(_xlfn.TEXTBEFORE(A15,","), "-", ""), " ", "") -> Barger | F15: {=_xlfn.LET( _xlpm.authors,_xlfn.TEXTBEFORE(A15," ("&G15&")"), _xlpm.hasAmp,ISNUMBER(SEARCH("&",_xlpm.authors)), _xlpm.hasEllipsis,ISNUMBER(SEARCH(_xlfn.UNICHAR(8230),_xlpm.authors)), _xlpm.commasBeforeAmp,IF( _xlpm.hasAmp, LEN(_xlfn.TEXTBEFORE(_xlpm.authors,"&"))-LEN(SUBSTITUTE(_xlfn.TEXTBEFORE(_xlpm.authors,"&"),",","")), 0 ), IF( _xlpm.hasEllipsis, "etal", IF( NOT(_xlpm.hasAmp), "", IF( _xlpm.commasBeforeAmp>2, "etal", SUBSTITUTE(TRIM(_xlfn.TEXTBEFORE(_xlfn.TEXTAFTER(_xlpm.authors,"& "),",")),"-","") ) ) ) )} -> etal | G15: =_xlfn.TEXTBEFORE(_xlfn.TEXTAFTER(A15, "("), ")") -> 2012 | H15: =E15 & IF(F15<>"", "_" & F15, "_") & IF(G15<>"", "_" & G15, "_") & IF(B15<>"", "_" & B15, "") -> Barger_etal_2012 | I15: =_xlfn.LET( _xlpm.doi,IF(C15<>"",C15,_xlfn.TEXTAFTER(A15,"https://doi.org/")), SUBSTITUTE( SUBSTITUTE( SUBSTITUTE( SUBSTITUTE( _xlpm.doi, "/","%2F"), ":","%3A"), "<","%3C"), ">","%3E") ) -> 10.1002%2Fcne.23118 | J15: =TRIM(_xlfn.TEXTJOIN("_",FALSE(),H15,(SUBSTITUTE(SUBSTITUTE(D15," ",""), "_", "")))) -> Barger_etal_2012_Table1 | K15: =I15 & "_" & SUBSTITUTE(SUBSTITUTE(SUBSTITUTE(D15,CHAR(160),"")," ",""),"_","") -> 10.1002%2Fcne.23118_Table1 | L15: {=IFERROR(INDEX(AUTO_Public_TSV_FileList!$A$1:$A$1000,MATCH(TRUE(),EXACT(K15,IFERROR(_xlfn.TEXTBEFORE(AUTO_Public_TSV_FileList!$A$1:$A$1000,".tsv"),"")),0)),"notfound")} -> 10.1002%2Fcne.23118_Table1.tsv | M15: Table 1. Specimens in Sample | N15: PDF (printed table) | P15: FINISHED | V15: Amygdala neuron number (specimen sample) | W15: Apes & humans; Old World monkey | X15: specimen sample: species, sex, age, hemisphere, collection provenance | Z15: histological sections | AB15: specimen metadata (not a volumetric/neuron measure) | AD15: Multiple (Semendeferi lab + contributed collections; see item note) | AE15: primary
A16: Barger, N., Stefanacci, L., Schumann, C. M., Sherwood, C. C., Annese, J., Allman, J. M., Buckwalter, J. A., Hof, P. R., & Semendeferi, K. (2012). Neuronal populations in the basolateral nuclei of the amygdala are differentially increased in humans compared with apes: A stereological study. J Comp Neurol, 520(13), 3035-3054. https://doi.org/10.1002/cne.23118 | D16: Table 3 | E16: =SUBSTITUTE(SUBSTITUTE(_xlfn.TEXTBEFORE(A16,","), "-", ""), " ", "") -> Barger | F16: {=_xlfn.LET( _xlpm.authors,_xlfn.TEXTBEFORE(A16," ("&G16&")"), _xlpm.hasAmp,ISNUMBER(SEARCH("&",_xlpm.authors)), _xlpm.hasEllipsis,ISNUMBER(SEARCH(_xlfn.UNICHAR(8230),_xlpm.authors)), _xlpm.commasBeforeAmp,IF( _xlpm.hasAmp, LEN(_xlfn.TEXTBEFORE(_xlpm.authors,"&"))-LEN(SUBSTITUTE(_xlfn.TEXTBEFORE(_xlpm.authors,"&"),",","")), 0 ), IF( _xlpm.hasEllipsis, "etal", IF( NOT(_xlpm.hasAmp), "", IF( _xlpm.commasBeforeAmp>2, "etal", SUBSTITUTE(TRIM(_xlfn.TEXTBEFORE(_xlfn.TEXTAFTER(_xlpm.authors,"& "),",")),"-","") ) ) ) )} -> etal | G16: =_xlfn.TEXTBEFORE(_xlfn.TEXTAFTER(A16, "("), ")") -> 2012 | H16: =E16 & IF(F16<>"", "_" & F16, "_") & IF(G16<>"", "_" & G16, "_") & IF(B16<>"", "_" & B16, "") -> Barger_etal_2012 | I16: =_xlfn.LET( _xlpm.doi,IF(C16<>"",C16,_xlfn.TEXTAFTER(A16,"https://doi.org/")), SUBSTITUTE( SUBSTITUTE( SUBSTITUTE( SUBSTITUTE( _xlpm.doi, "/","%2F"), ":","%3A"), "<","%3C"), ">","%3E") ) -> 10.1002%2Fcne.23118 | J16: =TRIM(_xlfn.TEXTJOIN("_",FALSE(),H16,(SUBSTITUTE(SUBSTITUTE(D16," ",""), "_", "")))) -> Barger_etal_2012_Table3 | K16: =I16 & "_" & SUBSTITUTE(SUBSTITUTE(SUBSTITUTE(D16,CHAR(160),"")," ",""),"_","") -> 10.1002%2Fcne.23118_Table3 | L16: {=IFERROR(INDEX(AUTO_Public_TSV_FileList!$A$1:$A$1000,MATCH(TRUE(),EXACT(K16,IFERROR(_xlfn.TEXTBEFORE(AUTO_Public_TSV_FileList!$A$1:$A$1000,".tsv"),"")),0)),"notfound")} -> 10.1002%2Fcne.23118_Table3.tsv | M16: Table 3. Average Neuron Number x10^6 (SD) for each nucleus in each species | P16: FINISHED | W16: Primates | X16: amygdala neuron numbers (basolateral + central nuclei) | AB16: neuron count (stereology) | AE16: primary
A17: Barks, S. K., Calhoun, M. E., Hopkins, W. D., Cranfield, M. R., Mudakikwa, A., Stoinski, T. S., Patterson, F. G., Erwin, J. M., Hecht, E. E., Hof, P. R., & Sherwood, C. C. (2014). Brain organization of gorillas reflects species differences in ecology. Am J Phys Anthropol. https://doi.org/10.1002/ajpa.22646 | D17: Fig 4 A | E17: =SUBSTITUTE(SUBSTITUTE(_xlfn.TEXTBEFORE(A17,","), "-", ""), " ", "") -> Barks | F17: {=_xlfn.LET( _xlpm.authors,_xlfn.TEXTBEFORE(A17," ("&G17&")"), _xlpm.hasAmp,ISNUMBER(SEARCH("&",_xlpm.authors)), _xlpm.hasEllipsis,ISNUMBER(SEARCH(_xlfn.UNICHAR(8230),_xlpm.authors)), _xlpm.commasBeforeAmp,IF( _xlpm.hasAmp, LEN(_xlfn.TEXTBEFORE(_xlpm.authors,"&"))-LEN(SUBSTITUTE(_xlfn.TEXTBEFORE(_xlpm.authors,"&"),",","")), 0 ), IF( _xlpm.hasEllipsis, "etal", IF( NOT(_xlpm.hasAmp), "", IF( _xlpm.commasBeforeAmp>2, "etal", SUBSTITUTE(TRIM(_xlfn.TEXTBEFORE(_xlfn.TEXTAFTER(_xlpm.authors,"& "),",")),"-","") ) ) ) )} -> etal | G17: =_xlfn.TEXTBEFORE(_xlfn.TEXTAFTER(A17, "("), ")") -> 2014 | H17: =E17 & IF(F17<>"", "_" & F17, "_") & IF(G17<>"", "_" & G17, "_") & IF(B17<>"", "_" & B17, "") -> Barks_etal_2014 | I17: =_xlfn.LET( _xlpm.doi,IF(C17<>"",C17,_xlfn.TEXTAFTER(A17,"https://doi.org/")), SUBSTITUTE( SUBSTITUTE( SUBSTITUTE( SUBSTITUTE( _xlpm.doi, "/","%2F"), ":","%3A"), "<","%3C"), ">","%3E") ) -> 10.1002%2Fajpa.22646 | J17: =TRIM(_xlfn.TEXTJOIN("_",FALSE(),H17,(SUBSTITUTE(SUBSTITUTE(D17," ",""), "_", "")))) -> Barks_etal_2014_Fig4A | K17: =I17 & "_" & SUBSTITUTE(SUBSTITUTE(SUBSTITUTE(D17,CHAR(160),"")," ",""),"_","") -> 10.1002%2Fajpa.22646_Fig4A | L17: {=IFERROR(INDEX(AUTO_Public_TSV_FileList!$A$1:$A$1000,MATCH(TRUE(),EXACT(K17,IFERROR(_xlfn.TEXTBEFORE(AUTO_Public_TSV_FileList!$A$1:$A$1000,".tsv"),"")),0)),"notfound")} -> 10.1002%2Fajpa.22646_Fig4A.tsv | M17: Fig4A_allsubjects_volumes | P17: FINISHED | AC17: Barks
A18: Barks, S. K., Calhoun, M. E., Hopkins, W. D., Cranfield, M. R., Mudakikwa, A., Stoinski, T. S., Patterson, F. G., Erwin, J. M., Hecht, E. E., Hof, P. R., & Sherwood, C. C. (2014). Brain organization of gorillas reflects species differences in ecology. Am J Phys Anthropol. https://doi.org/10.1002/ajpa.22646 | D18: Fig 5 A | E18: =SUBSTITUTE(SUBSTITUTE(_xlfn.TEXTBEFORE(A18,","), "-", ""), " ", "") -> Barks | F18: {=_xlfn.LET( _xlpm.authors,_xlfn.TEXTBEFORE(A18," ("&G18&")"), _xlpm.hasAmp,ISNUMBER(SEARCH("&",_xlpm.authors)), _xlpm.hasEllipsis,ISNUMBER(SEARCH(_xlfn.UNICHAR(8230),_xlpm.authors)), _xlpm.commasBeforeAmp,IF( _xlpm.hasAmp, LEN(_xlfn.TEXTBEFORE(_xlpm.authors,"&"))-LEN(SUBSTITUTE(_xlfn.TEXTBEFORE(_xlpm.authors,"&"),",","")), 0 ), IF( _xlpm.hasEllipsis, "etal", IF( NOT(_xlpm.hasAmp), "", IF( _xlpm.commasBeforeAmp>2, "etal", SUBSTITUTE(TRIM(_xlfn.TEXTBEFORE(_xlfn.TEXTAFTER(_xlpm.authors,"& "),",")),"-","") ) ) ) )} -> etal | G18: =_xlfn.TEXTBEFORE(_xlfn.TEXTAFTER(A18, "("), ")") -> 2014 | H18: =E18 & IF(F18<>"", "_" & F18, "_") & IF(G18<>"", "_" & G18, "_") & IF(B18<>"", "_" & B18, "") -> Barks_etal_2014 | I18: =_xlfn.LET( _xlpm.doi,IF(C18<>"",C18,_xlfn.TEXTAFTER(A18,"https://doi.org/")), SUBSTITUTE( SUBSTITUTE( SUBSTITUTE( SUBSTITUTE( _xlpm.doi, "/","%2F"), ":","%3A"), "<","%3C"), ">","%3E") ) -> 10.1002%2Fajpa.22646 | J18: =TRIM(_xlfn.TEXTJOIN("_",FALSE(),H18,(SUBSTITUTE(SUBSTITUTE(D18," ",""), "_", "")))) -> Barks_etal_2014_Fig5A | K18: =I18 & "_" & SUBSTITUTE(SUBSTITUTE(SUBSTITUTE(D18,CHAR(160),"")," ",""),"_","") -> 10.1002%2Fajpa.22646_Fig5A | L18: {=IFERROR(INDEX(AUTO_Public_TSV_FileList!$A$1:$A$1000,MATCH(TRUE(),EXACT(K18,IFERROR(_xlfn.TEXTBEFORE(AUTO_Public_TSV_FileList!$A$1:$A$1000,".tsv"),"")),0)),"notfound")} -> 10.1002%2Fajpa.22646_Fig5A.tsv | M18: Fig5A_adultsonly_volumes | P18: FINISHED
A19: Barks, S. K., Calhoun, M. E., Hopkins, W. D., Cranfield, M. R., Mudakikwa, A., Stoinski, T. S., Patterson, F. G., Erwin, J. M., Hecht, E. E., Hof, P. R., & Sherwood, C. C. (2014). Brain organization of gorillas reflects species differences in ecology. Am J Phys Anthropol. https://doi.org/10.1002/ajpa.22646 | D19: TABLE 1 | E19: =SUBSTITUTE(SUBSTITUTE(_xlfn.TEXTBEFORE(A19,","), "-", ""), " ", "") -> Barks | F19: {=_xlfn.LET( _xlpm.authors,_xlfn.TEXTBEFORE(A19," ("&G19&")"), _xlpm.hasAmp,ISNUMBER(SEARCH("&",_xlpm.authors)), _xlpm.hasEllipsis,ISNUMBER(SEARCH(_xlfn.UNICHAR(8230),_xlpm.authors)), _xlpm.commasBeforeAmp,IF( _xlpm.hasAmp, LEN(_xlfn.TEXTBEFORE(_xlpm.authors,"&"))-LEN(SUBSTITUTE(_xlfn.TEXTBEFORE(_xlpm.authors,"&"),",","")), 0 ), IF( _xlpm.hasEllipsis, "etal", IF( NOT(_xlpm.hasAmp), "", IF( _xlpm.commasBeforeAmp>2, "etal", SUBSTITUTE(TRIM(_xlfn.TEXTBEFORE(_xlfn.TEXTAFTER(_xlpm.authors,"& "),",")),"-","") ) ) ) )} -> etal | G19: =_xlfn.TEXTBEFORE(_xlfn.TEXTAFTER(A19, "("), ")") -> 2014 | H19: =E19 & IF(F19<>"", "_" & F19, "_") & IF(G19<>"", "_" & G19, "_") & IF(B19<>"", "_" & B19, "") -> Barks_etal_2014 | I19: =_xlfn.LET( _xlpm.doi,IF(C19<>"",C19,_xlfn.TEXTAFTER(A19,"https://doi.org/")), SUBSTITUTE( SUBSTITUTE( SUBSTITUTE( SUBSTITUTE( _xlpm.doi, "/","%2F"), ":","%3A"), "<","%3C"), ">","%3E") ) -> 10.1002%2Fajpa.22646 | J19: =TRIM(_xlfn.TEXTJOIN("_",FALSE(),H19,(SUBSTITUTE(SUBSTITUTE(D19," ",""), "_", "")))) -> Barks_etal_2014_TABLE1 | K19: =I19 & "_" & SUBSTITUTE(SUBSTITUTE(SUBSTITUTE(D19,CHAR(160),"")," ",""),"_","") -> 10.1002%2Fajpa.22646_TABLE1 | L19: {=IFERROR(INDEX(AUTO_Public_TSV_FileList!$A$1:$A$1000,MATCH(TRUE(),EXACT(K19,IFERROR(_xlfn.TEXTBEFORE(AUTO_Public_TSV_FileList!$A$1:$A$1000,".tsv"),"")),0)),"notfound")} -> 10.1002%2Fajpa.22646_TABLE1.tsv | M19: TABLE 1. Individual data | P19: FINISHED | AC19: Barks
A20: Barks, S. K., Calhoun, M. E., Hopkins, W. D., Cranfield, M. R., Mudakikwa, A., Stoinski, T. S., Patterson, F. G., Erwin, J. M., Hecht, E. E., Hof, P. R., & Sherwood, C. C. (2014). Brain organization of gorillas reflects species differences in ecology. Am J Phys Anthropol. https://doi.org/10.1002/ajpa.22646 | D20: TABLE 2 | E20: =SUBSTITUTE(SUBSTITUTE(_xlfn.TEXTBEFORE(A20,","), "-", ""), " ", "") -> Barks | F20: {=_xlfn.LET( _xlpm.authors,_xlfn.TEXTBEFORE(A20," ("&G20&")"), _xlpm.hasAmp,ISNUMBER(SEARCH("&",_xlpm.authors)), _xlpm.hasEllipsis,ISNUMBER(SEARCH(_xlfn.UNICHAR(8230),_xlpm.authors)), _xlpm.commasBeforeAmp,IF( _xlpm.hasAmp, LEN(_xlfn.TEXTBEFORE(_xlpm.authors,"&"))-LEN(SUBSTITUTE(_xlfn.TEXTBEFORE(_xlpm.authors,"&"),",","")), 0 ), IF( _xlpm.hasEllipsis, "etal", IF( NOT(_xlpm.hasAmp), "", IF( _xlpm.commasBeforeAmp>2, "etal", SUBSTITUTE(TRIM(_xlfn.TEXTBEFORE(_xlfn.TEXTAFTER(_xlpm.authors,"& "),",")),"-","") ) ) ) )} -> etal | G20: =_xlfn.TEXTBEFORE(_xlfn.TEXTAFTER(A20, "("), ")") -> 2014 | H20: =E20 & IF(F20<>"", "_" & F20, "_") & IF(G20<>"", "_" & G20, "_") & IF(B20<>"", "_" & B20, "") -> Barks_etal_2014 | I20: =_xlfn.LET( _xlpm.doi,IF(C20<>"",C20,_xlfn.TEXTAFTER(A20,"https://doi.org/")), SUBSTITUTE( SUBSTITUTE( SUBSTITUTE( SUBSTITUTE( _xlpm.doi, "/","%2F"), ":","%3A"), "<","%3C"), ">","%3E") ) -> 10.1002%2Fajpa.22646 | J20: =TRIM(_xlfn.TEXTJOIN("_",FALSE(),H20,(SUBSTITUTE(SUBSTITUTE(D20," ",""), "_", "")))) -> Barks_etal_2014_TABLE2 | K20: =I20 & "_" & SUBSTITUTE(SUBSTITUTE(SUBSTITUTE(D20,CHAR(160),"")," ",""),"_","") -> 10.1002%2Fajpa.22646_TABLE2 | L20: {=IFERROR(INDEX(AUTO_Public_TSV_FileList!$A$1:$A$1000,MATCH(TRUE(),EXACT(K20,IFERROR(_xlfn.TEXTBEFORE(AUTO_Public_TSV_FileList!$A$1:$A$1000,".tsv"),"")),0)),"notfound")} -> 10.1002%2Fajpa.22646_TABLE2.tsv | M20: TABLE 2. Stereological sampling of brains | P20: FINISHED
A21: Barks, S. K., Calhoun, M. E., Hopkins, W. D., Cranfield, M. R., Mudakikwa, A., Stoinski, T. S., Patterson, F. G., Erwin, J. M., Hecht, E. E., Hof, P. R., & Sherwood, C. C. (2014). Brain organization of gorillas reflects species differences in ecology. Am J Phys Anthropol. https://doi.org/10.1002/ajpa.22646 | D21: unpublishedviaDeCasien | E21: =SUBSTITUTE(SUBSTITUTE(_xlfn.TEXTBEFORE(A21,","), "-", ""), " ", "") -> Barks | F21: {=_xlfn.LET( _xlpm.authors,_xlfn.TEXTBEFORE(A21," ("&G21&")"), _xlpm.hasAmp,ISNUMBER(SEARCH("&",_xlpm.authors)), _xlpm.hasEllipsis,ISNUMBER(SEARCH(_xlfn.UNICHAR(8230),_xlpm.authors)), _xlpm.commasBeforeAmp,IF( _xlpm.hasAmp, LEN(_xlfn.TEXTBEFORE(_xlpm.authors,"&"))-LEN(SUBSTITUTE(_xlfn.TEXTBEFORE(_xlpm.authors,"&"),",","")), 0 ), IF( _xlpm.hasEllipsis, "etal", IF( NOT(_xlpm.hasAmp), "", IF( _xlpm.commasBeforeAmp>2, "etal", SUBSTITUTE(TRIM(_xlfn.TEXTBEFORE(_xlfn.TEXTAFTER(_xlpm.authors,"& "),",")),"-","") ) ) ) )} -> etal | G21: =_xlfn.TEXTBEFORE(_xlfn.TEXTAFTER(A21, "("), ")") -> 2014 | H21: =E21 & IF(F21<>"", "_" & F21, "_") & IF(G21<>"", "_" & G21, "_") & IF(B21<>"", "_" & B21, "") -> Barks_etal_2014 | I21: =_xlfn.LET( _xlpm.doi,IF(C21<>"",C21,_xlfn.TEXTAFTER(A21,"https://doi.org/")), SUBSTITUTE( SUBSTITUTE( SUBSTITUTE( SUBSTITUTE( _xlpm.doi, "/","%2F"), ":","%3A"), "<","%3C"), ">","%3E") ) -> 10.1002%2Fajpa.22646 | J21: =TRIM(_xlfn.TEXTJOIN("_",FALSE(),H21,(SUBSTITUTE(SUBSTITUTE(D21," ",""), "_", "")))) -> Barks_etal_2014_unpublishedviaDeCasien | K21: =I21 & "_" & SUBSTITUTE(SUBSTITUTE(SUBSTITUTE(D21,CHAR(160),"")," ",""),"_","") -> 10.1002%2Fajpa.22646_unpublishedviaDeCasien | L21: {=IFERROR(INDEX(AUTO_Public_TSV_FileList!$A$1:$A$1000,MATCH(TRUE(),EXACT(K21,IFERROR(_xlfn.TEXTBEFORE(AUTO_Public_TSV_FileList!$A$1:$A$1000,".tsv"),"")),0)),"notfound")} -> 10.1002%2Fajpa.22646_unpublishedviaDeCasien.tsv | O21: "Sherwood et al.64 and Barks et al.65 provided neocortex, hippocampus, striatum, thalamus, cerebellum, amygdala and insula measures for multiple gorilla species (Gorilla gorilla gorilla, G. g. graueri and G. beringei) from post-mortem MRI scans" (DeCasien and Higham 2019) | P21: FINISHED
A22: Baron, G., Frahm, H. D., & Stephan, H. (1988). Comparison of brain structure volumes in Insectivora and Primates. VIII. Vestibular complex. J Hirnforsch, 29(5), 509-523. http://www.ncbi.nlm.nih.gov/pubmed/3216099 | C22: PMID:3216099 | D22: Table 1 | E22: =SUBSTITUTE(SUBSTITUTE(_xlfn.TEXTBEFORE(A22,","), "-", ""), " ", "") -> Baron | F22: {=_xlfn.LET( _xlpm.authors,_xlfn.TEXTBEFORE(A22," ("&G22&")"), _xlpm.hasAmp,ISNUMBER(SEARCH("&",_xlpm.authors)), _xlpm.hasEllipsis,ISNUMBER(SEARCH(_xlfn.UNICHAR(8230),_xlpm.authors)), _xlpm.commasBeforeAmp,IF( _xlpm.hasAmp, LEN(_xlfn.TEXTBEFORE(_xlpm.authors,"&"))-LEN(SUBSTITUTE(_xlfn.TEXTBEFORE(_xlpm.authors,"&"),",","")), 0 ), IF( _xlpm.hasEllipsis, "etal", IF( NOT(_xlpm.hasAmp), "", IF( _xlpm.commasBeforeAmp>2, "etal", SUBSTITUTE(TRIM(_xlfn.TEXTBEFORE(_xlfn.TEXTAFTER(_xlpm.authors,"& "),",")),"-","") ) ) ) )} -> etal | G22: =_xlfn.TEXTBEFORE(_xlfn.TEXTAFTER(A22, "("), ")") -> 1988 | H22: =E22 & IF(F22<>"", "_" & F22, "_") & IF(G22<>"", "_" & G22, "_") & IF(B22<>"", "_" & B22, "") -> Baron_etal_1988 | I22: =_xlfn.LET( _xlpm.doi,IF(C22<>"",C22,_xlfn.TEXTAFTER(A22,"https://doi.org/")), SUBSTITUTE( SUBSTITUTE( SUBSTITUTE( SUBSTITUTE( _xlpm.doi, "/","%2F"), ":","%3A"), "<","%3C"), ">","%3E") ) -> PMID%3A3216099 | J22: =TRIM(_xlfn.TEXTJOIN("_",FALSE(),H22,(SUBSTITUTE(SUBSTITUTE(D22," ",""), "_", "")))) -> Baron_etal_1988_Table1 | K22: =I22 & "_" & SUBSTITUTE(SUBSTITUTE(SUBSTITUTE(D22,CHAR(160),"")," ",""),"_","") -> PMID%3A3216099_Table1 | L22: {=IFERROR(INDEX(AUTO_Public_TSV_FileList!$A$1:$A$1000,MATCH(TRUE(),EXACT(K22,IFERROR(_xlfn.TEXTBEFORE(AUTO_Public_TSV_FileList!$A$1:$A$1000,".tsv"),"")),0)),"notfound")} -> PMID%3A3216099_Table1.tsv | M22: Table 1. Volumes and indices of the vestibular complex (VC) and its main components (VM, V1, VL, VS) in Insectivora and Scadentia | P22: FINISHED | W22: Insectivora, Scandentia & Primates | X22: vestibular nuclear complex volume | Z22: histological sections | AB22: volume | AC22: Stephan | AD22: Stephan | AE22: primary
A23: Baron, G., Frahm, H. D., Bhatnagar, K. P., & Stephan, H. (1983). Comparison of brain structure volumes in Insectivora and Primates. III. Main olfactory bulb (MOB). J Hirnforsch, 24(5), 551-568. https://www.ncbi.nlm.nih.gov/pubmed/6663055 | C23: PMID:6663055 | D23: Table 1 | E23: =SUBSTITUTE(SUBSTITUTE(_xlfn.TEXTBEFORE(A23,","), "-", ""), " ", "") -> Baron | F23: {=_xlfn.LET( _xlpm.authors,_xlfn.TEXTBEFORE(A23," ("&G23&")"), _xlpm.hasAmp,ISNUMBER(SEARCH("&",_xlpm.authors)), _xlpm.hasEllipsis,ISNUMBER(SEARCH(_xlfn.UNICHAR(8230),_xlpm.authors)), _xlpm.commasBeforeAmp,IF( _xlpm.hasAmp, LEN(_xlfn.TEXTBEFORE(_xlpm.authors,"&"))-LEN(SUBSTITUTE(_xlfn.TEXTBEFORE(_xlpm.authors,"&"),",","")), 0 ), IF( _xlpm.hasEllipsis, "etal", IF( NOT(_xlpm.hasAmp), "", IF( _xlpm.commasBeforeAmp>2, "etal", SUBSTITUTE(TRIM(_xlfn.TEXTBEFORE(_xlfn.TEXTAFTER(_xlpm.authors,"& "),",")),"-","") ) ) ) )} -> etal | G23: =_xlfn.TEXTBEFORE(_xlfn.TEXTAFTER(A23, "("), ")") -> 1983 | H23: =E23 & IF(F23<>"", "_" & F23, "_") & IF(G23<>"", "_" & G23, "_") & IF(B23<>"", "_" & B23, "") -> Baron_etal_1983 | I23: =_xlfn.LET( _xlpm.doi,IF(C23<>"",C23,_xlfn.TEXTAFTER(A23,"https://doi.org/")), SUBSTITUTE( SUBSTITUTE( SUBSTITUTE( SUBSTITUTE( _xlpm.doi, "/","%2F"), ":","%3A"), "<","%3C"), ">","%3E") ) -> PMID%3A6663055 | J23: =TRIM(_xlfn.TEXTJOIN("_",FALSE(),H23,(SUBSTITUTE(SUBSTITUTE(D23," ",""), "_", "")))) -> Baron_etal_1983_Table1 | K23: =I23 & "_" & SUBSTITUTE(SUBSTITUTE(SUBSTITUTE(D23,CHAR(160),"")," ",""),"_","") -> PMID%3A6663055_Table1 | L23: {=IFERROR(INDEX(AUTO_Public_TSV_FileList!$A$1:$A$1000,MATCH(TRUE(),EXACT(K23,IFERROR(_xlfn.TEXTBEFORE(AUTO_Public_TSV_FileList!$A$1:$A$1000,".tsv"),"")),0)),"notfound")} -> PMID%3A6663055_Table1.tsv | N23: table | P23: FINISHED | W23: Insectivora, Scandentia & Primates | X23: main olfactory bulb (MOB) volume | Z23: histological sections | AB23: volume | AC23: Stephan | AD23: Stephan | AE23: primary
A24: Baron, G., Stephan, H., & Frahm, H. D. (1987). Comparison of brain structure volumes in Insectivora and Primates. VI. Paleocortical components. J Hirnforsch, 28(4), 463-477. http://www.ncbi.nlm.nih.gov/pubmed/3116076 | C24: PMID:3116076 | D24: Table 1 | E24: =SUBSTITUTE(SUBSTITUTE(_xlfn.TEXTBEFORE(A24,","), "-", ""), " ", "") -> Baron | F24: {=_xlfn.LET( _xlpm.authors,_xlfn.TEXTBEFORE(A24," ("&G24&")"), _xlpm.hasAmp,ISNUMBER(SEARCH("&",_xlpm.authors)), _xlpm.hasEllipsis,ISNUMBER(SEARCH(_xlfn.UNICHAR(8230),_xlpm.authors)), _xlpm.commasBeforeAmp,IF( _xlpm.hasAmp, LEN(_xlfn.TEXTBEFORE(_xlpm.authors,"&"))-LEN(SUBSTITUTE(_xlfn.TEXTBEFORE(_xlpm.authors,"&"),",","")), 0 ), IF( _xlpm.hasEllipsis, "etal", IF( NOT(_xlpm.hasAmp), "", IF( _xlpm.commasBeforeAmp>2, "etal", SUBSTITUTE(TRIM(_xlfn.TEXTBEFORE(_xlfn.TEXTAFTER(_xlpm.authors,"& "),",")),"-","") ) ) ) )} -> etal | G24: =_xlfn.TEXTBEFORE(_xlfn.TEXTAFTER(A24, "("), ")") -> 1987 | H24: =E24 & IF(F24<>"", "_" & F24, "_") & IF(G24<>"", "_" & G24, "_") & IF(B24<>"", "_" & B24, "") -> Baron_etal_1987 | I24: =_xlfn.LET( _xlpm.doi,IF(C24<>"",C24,_xlfn.TEXTAFTER(A24,"https://doi.org/")), SUBSTITUTE( SUBSTITUTE( SUBSTITUTE( SUBSTITUTE( _xlpm.doi, "/","%2F"), ":","%3A"), "<","%3C"), ">","%3E") ) -> PMID%3A3116076 | J24: =TRIM(_xlfn.TEXTJOIN("_",FALSE(),H24,(SUBSTITUTE(SUBSTITUTE(D24," ",""), "_", "")))) -> Baron_etal_1987_Table1 | K24: =I24 & "_" & SUBSTITUTE(SUBSTITUTE(SUBSTITUTE(D24,CHAR(160),"")," ",""),"_","") -> PMID%3A3116076_Table1 | L24: {=IFERROR(INDEX(AUTO_Public_TSV_FileList!$A$1:$A$1000,MATCH(TRUE(),EXACT(K24,IFERROR(_xlfn.TEXTBEFORE(AUTO_Public_TSV_FileList!$A$1:$A$1000,".tsv"),"")),0)),"notfound")} -> PMID%3A3116076_Table1.tsv | N24: table | P24: FINISHED | W24: Insectivora, Scandentia & Primates | X24: brain-structure volume (Comparison series, Part) | Z24: histological sections | AB24: volume | AC24: Stephan | AD24: Stephan | AE24: primary
A25: Baron, G., Stephan, H., & Frahm, H. D. (1990). Comparison of brain structure volumes in Insectivora and primates. IX. Trigeminal complex. J Hirnforsch, 31(2), 193-200. https://www.ncbi.nlm.nih.gov/pubmed/2358663 | C25: PMID:2358663 | D25: Table 1 | E25: =SUBSTITUTE(SUBSTITUTE(_xlfn.TEXTBEFORE(A25,","), "-", ""), " ", "") -> Baron | F25: {=_xlfn.LET( _xlpm.authors,_xlfn.TEXTBEFORE(A25," ("&G25&")"), _xlpm.hasAmp,ISNUMBER(SEARCH("&",_xlpm.authors)), _xlpm.hasEllipsis,ISNUMBER(SEARCH(_xlfn.UNICHAR(8230),_xlpm.authors)), _xlpm.commasBeforeAmp,IF( _xlpm.hasAmp, LEN(_xlfn.TEXTBEFORE(_xlpm.authors,"&"))-LEN(SUBSTITUTE(_xlfn.TEXTBEFORE(_xlpm.authors,"&"),",","")), 0 ), IF( _xlpm.hasEllipsis, "etal", IF( NOT(_xlpm.hasAmp), "", IF( _xlpm.commasBeforeAmp>2, "etal", SUBSTITUTE(TRIM(_xlfn.TEXTBEFORE(_xlfn.TEXTAFTER(_xlpm.authors,"& "),",")),"-","") ) ) ) )} -> etal | G25: =_xlfn.TEXTBEFORE(_xlfn.TEXTAFTER(A25, "("), ")") -> 1990 | H25: =E25 & IF(F25<>"", "_" & F25, "_") & IF(G25<>"", "_" & G25, "_") & IF(B25<>"", "_" & B25, "") -> Baron_etal_1990 | I25: =_xlfn.LET( _xlpm.doi,IF(C25<>"",C25,_xlfn.TEXTAFTER(A25,"https://doi.org/")), SUBSTITUTE( SUBSTITUTE( SUBSTITUTE( SUBSTITUTE( _xlpm.doi, "/","%2F"), ":","%3A"), "<","%3C"), ">","%3E") ) -> PMID%3A2358663 | J25: =TRIM(_xlfn.TEXTJOIN("_",FALSE(),H25,(SUBSTITUTE(SUBSTITUTE(D25," ",""), "_", "")))) -> Baron_etal_1990_Table1 | K25: =I25 & "_" & SUBSTITUTE(SUBSTITUTE(SUBSTITUTE(D25,CHAR(160),"")," ",""),"_","") -> PMID%3A2358663_Table1 | L25: {=IFERROR(INDEX(AUTO_Public_TSV_FileList!$A$1:$A$1000,MATCH(TRUE(),EXACT(K25,IFERROR(_xlfn.TEXTBEFORE(AUTO_Public_TSV_FileList!$A$1:$A$1000,".tsv"),"")),0)),"notfound")} -> PMID%3A2358663_Table1.tsv | M25: Table 1 .IX. Trigeminal complex | N25: table | P25: FINISHED | W25: Insectivora, Scandentia & Primates | X25: trigeminal complex volume | Z25: histological sections | AA25: volumetry | AB25: volume | AC25: Stephan | AD25: Stephan | AE25: primary
A26: Baron, G., Stephan, H., & Frahm, H. D. (1996). Comparative Neurobiology in Chiroptera: Macromorphology, Brain Structures, Tables, and Atlases. Birkhäuser. | C26: ISBN:9783764353704 | D26: Table 10 | E26: =SUBSTITUTE(SUBSTITUTE(_xlfn.TEXTBEFORE(A26,","), "-", ""), " ", "") -> Baron | F26: {=_xlfn.LET( _xlpm.authors,_xlfn.TEXTBEFORE(A26," ("&G26&")"), _xlpm.hasAmp,ISNUMBER(SEARCH("&",_xlpm.authors)), _xlpm.hasEllipsis,ISNUMBER(SEARCH(_xlfn.UNICHAR(8230),_xlpm.authors)), _xlpm.commasBeforeAmp,IF( _xlpm.hasAmp, LEN(_xlfn.TEXTBEFORE(_xlpm.authors,"&"))-LEN(SUBSTITUTE(_xlfn.TEXTBEFORE(_xlpm.authors,"&"),",","")), 0 ), IF( _xlpm.hasEllipsis, "etal", IF( NOT(_xlpm.hasAmp), "", IF( _xlpm.commasBeforeAmp>2, "etal", SUBSTITUTE(TRIM(_xlfn.TEXTBEFORE(_xlfn.TEXTAFTER(_xlpm.authors,"& "),",")),"-","") ) ) ) )} -> etal | G26: =_xlfn.TEXTBEFORE(_xlfn.TEXTAFTER(A26, "("), ")") -> 1996 | H26: =E26 & IF(F26<>"", "_" & F26, "_") & IF(G26<>"", "_" & G26, "_") & IF(B26<>"", "_" & B26, "") -> Baron_etal_1996 | I26: =_xlfn.LET( _xlpm.doi,IF(C26<>"",C26,_xlfn.TEXTAFTER(A26,"https://doi.org/")), SUBSTITUTE( SUBSTITUTE( SUBSTITUTE( SUBSTITUTE( _xlpm.doi, "/","%2F"), ":","%3A"), "<","%3C"), ">","%3E") ) -> ISBN%3A9783764353704 | J26: =TRIM(_xlfn.TEXTJOIN("_",FALSE(),H26,(SUBSTITUTE(SUBSTITUTE(D26," ",""), "_", "")))) -> Baron_etal_1996_Table10 | K26: =I26 & "_" & SUBSTITUTE(SUBSTITUTE(SUBSTITUTE(D26,CHAR(160),"")," ",""),"_","") -> ISBN%3A9783764353704_Table10 | L26: {=IFERROR(INDEX(AUTO_Public_TSV_FileList!$A$1:$A$1000,MATCH(TRUE(),EXACT(K26,IFERROR(_xlfn.TEXTBEFORE(AUTO_Public_TSV_FileList!$A$1:$A$1000,".tsv"),"")),0)),"notfound")} -> ISBN%3A9783764353704_Table10.tsv | P26: FINISHED | AE26: primary
A27: Baron, G., Stephan, H., & Frahm, H. D. (1996). Comparative Neurobiology in Chiroptera: Macromorphology, Brain Structures, Tables, and Atlases. Birkhäuser. | C27: ISBN:9783764353704 | D27: Table 13 | E27: =SUBSTITUTE(SUBSTITUTE(_xlfn.TEXTBEFORE(A27,","), "-", ""), " ", "") -> Baron | F27: {=_xlfn.LET( _xlpm.authors,_xlfn.TEXTBEFORE(A27," ("&G27&")"), _xlpm.hasAmp,ISNUMBER(SEARCH("&",_xlpm.authors)), _xlpm.hasEllipsis,ISNUMBER(SEARCH(_xlfn.UNICHAR(8230),_xlpm.authors)), _xlpm.commasBeforeAmp,IF( _xlpm.hasAmp, LEN(_xlfn.TEXTBEFORE(_xlpm.authors,"&"))-LEN(SUBSTITUTE(_xlfn.TEXTBEFORE(_xlpm.authors,"&"),",","")), 0 ), IF( _xlpm.hasEllipsis, "etal", IF( NOT(_xlpm.hasAmp), "", IF( _xlpm.commasBeforeAmp>2, "etal", SUBSTITUTE(TRIM(_xlfn.TEXTBEFORE(_xlfn.TEXTAFTER(_xlpm.authors,"& "),",")),"-","") ) ) ) )} -> etal | G27: =_xlfn.TEXTBEFORE(_xlfn.TEXTAFTER(A27, "("), ")") -> 1996 | H27: =E27 & IF(F27<>"", "_" & F27, "_") & IF(G27<>"", "_" & G27, "_") & IF(B27<>"", "_" & B27, "") -> Baron_etal_1996 | I27: =_xlfn.LET( _xlpm.doi,IF(C27<>"",C27,_xlfn.TEXTAFTER(A27,"https://doi.org/")), SUBSTITUTE( SUBSTITUTE( SUBSTITUTE( SUBSTITUTE( _xlpm.doi, "/","%2F"), ":","%3A"), "<","%3C"), ">","%3E") ) -> ISBN%3A9783764353704 | J27: =TRIM(_xlfn.TEXTJOIN("_",FALSE(),H27,(SUBSTITUTE(SUBSTITUTE(D27," ",""), "_", "")))) -> Baron_etal_1996_Table13 | K27: =I27 & "_" & SUBSTITUTE(SUBSTITUTE(SUBSTITUTE(D27,CHAR(160),"")," ",""),"_","") -> ISBN%3A9783764353704_Table13 | L27: {=IFERROR(INDEX(AUTO_Public_TSV_FileList!$A$1:$A$1000,MATCH(TRUE(),EXACT(K27,IFERROR(_xlfn.TEXTBEFORE(AUTO_Public_TSV_FileList!$A$1:$A$1000,".tsv"),"")),0)),"notfound")} -> ISBN%3A9783764353704_Table13.tsv | M27: Volumes (in mm3) of the sensory trigeminal complex and of the tractus solitarii and funicular nuclei of the medulla oblongata | N27: table | P27: FINISHED | S27: Structure list, species count and the table's size/index role confirmed against the book's own Table 1 key (PDF pp. 264-265) and the printed column header, 2026-08-31. | T27: Inherits the whole-source merge gate already recorded for Tables 10/32: seven historical taxon concepts in MANUAL_REVIEW, and source rows that collapse to the same species must be averaged within the item before Tier-1 recency resolution. Resolving that gate once unblocks every Baron item, so build order need not wait on it. | W27: Mammals | X27: trigeminal and somatosensory brainstem nucleus volumes | Y27: trigeminal and somatosensory brainstem nucleus volumes | Z27: histological sections | AB27: volume | AC27: Stephan | AD27: Stephan | AE27: primary | AG27: Not yet transcribed. PDF pages 74-78; N = 150 printed rows. Extend Baron_etal_1996_extract_snapshots.py, which already reads this PDF's text layer for Tables 10 and 32 with an explicit literal OCR-repair table.
A28: Baron, G., Stephan, H., & Frahm, H. D. (1996). Comparative Neurobiology in Chiroptera: Macromorphology, Brain Structures, Tables, and Atlases. Birkhäuser. | C28: ISBN:9783764353704 | D28: Table 16 | E28: =SUBSTITUTE(SUBSTITUTE(_xlfn.TEXTBEFORE(A28,","), "-", ""), " ", "") -> Baron | F28: {=_xlfn.LET( _xlpm.authors,_xlfn.TEXTBEFORE(A28," ("&G28&")"), _xlpm.hasAmp,ISNUMBER(SEARCH("&",_xlpm.authors)), _xlpm.hasEllipsis,ISNUMBER(SEARCH(_xlfn.UNICHAR(8230),_xlpm.authors)), _xlpm.commasBeforeAmp,IF( _xlpm.hasAmp, LEN(_xlfn.TEXTBEFORE(_xlpm.authors,"&"))-LEN(SUBSTITUTE(_xlfn.TEXTBEFORE(_xlpm.authors,"&"),",","")), 0 ), IF( _xlpm.hasEllipsis, "etal", IF( NOT(_xlpm.hasAmp), "", IF( _xlpm.commasBeforeAmp>2, "etal", SUBSTITUTE(TRIM(_xlfn.TEXTBEFORE(_xlfn.TEXTAFTER(_xlpm.authors,"& "),",")),"-","") ) ) ) )} -> etal | G28: =_xlfn.TEXTBEFORE(_xlfn.TEXTAFTER(A28, "("), ")") -> 1996 | H28: =E28 & IF(F28<>"", "_" & F28, "_") & IF(G28<>"", "_" & G28, "_") & IF(B28<>"", "_" & B28, "") -> Baron_etal_1996 | I28: =_xlfn.LET( _xlpm.doi,IF(C28<>"",C28,_xlfn.TEXTAFTER(A28,"https://doi.org/")), SUBSTITUTE( SUBSTITUTE( SUBSTITUTE( SUBSTITUTE( _xlpm.doi, "/","%2F"), ":","%3A"), "<","%3C"), ">","%3E") ) -> ISBN%3A9783764353704 | J28: =TRIM(_xlfn.TEXTJOIN("_",FALSE(),H28,(SUBSTITUTE(SUBSTITUTE(D28," ",""), "_", "")))) -> Baron_etal_1996_Table16 | K28: =I28 & "_" & SUBSTITUTE(SUBSTITUTE(SUBSTITUTE(D28,CHAR(160),"")," ",""),"_","") -> ISBN%3A9783764353704_Table16 | L28: {=IFERROR(INDEX(AUTO_Public_TSV_FileList!$A$1:$A$1000,MATCH(TRUE(),EXACT(K28,IFERROR(_xlfn.TEXTBEFORE(AUTO_Public_TSV_FileList!$A$1:$A$1000,".tsv"),"")),0)),"notfound")} -> ISBN%3A9783764353704_Table16.tsv | M28: Volumes of some motor and relay nuclei of the medulla oblongata | N28: table | P28: FINISHED | S28: Structure list, species count and the table's size/index role confirmed against the book's own Table 1 key (PDF pp. 264-265) and the printed column header, 2026-08-31. | T28: Inherits the whole-source merge gate already recorded for Tables 10/32: seven historical taxon concepts in MANUAL_REVIEW, and source rows that collapse to the same species must be averaged within the item before Tier-1 recency resolution. Resolving that gate once unblocks every Baron item, so build order need not wait on it. | W28: Mammals | X28: medullary motor and relay nucleus volumes | Y28: medullary motor and relay nucleus volumes | Z28: histological sections | AB28: volume | AC28: Stephan | AD28: Stephan | AE28: primary | AG28: Not yet transcribed. PDF pages 86-90; N = 150 printed rows. Extend Baron_etal_1996_extract_snapshots.py, which already reads this PDF's text layer for Tables 10 and 32 with an explicit literal OCR-repair table.
A29: Baron, G., Stephan, H., & Frahm, H. D. (1996). Comparative Neurobiology in Chiroptera: Macromorphology, Brain Structures, Tables, and Atlases. Birkhäuser. | C29: ISBN:9783764353704 | D29: Table 19 | E29: =SUBSTITUTE(SUBSTITUTE(_xlfn.TEXTBEFORE(A29,","), "-", ""), " ", "") -> Baron | F29: {=_xlfn.LET( _xlpm.authors,_xlfn.TEXTBEFORE(A29," ("&G29&")"), _xlpm.hasAmp,ISNUMBER(SEARCH("&",_xlpm.authors)), _xlpm.hasEllipsis,ISNUMBER(SEARCH(_xlfn.UNICHAR(8230),_xlpm.authors)), _xlpm.commasBeforeAmp,IF( _xlpm.hasAmp, LEN(_xlfn.TEXTBEFORE(_xlpm.authors,"&"))-LEN(SUBSTITUTE(_xlfn.TEXTBEFORE(_xlpm.authors,"&"),",","")), 0 ), IF( _xlpm.hasEllipsis, "etal", IF( NOT(_xlpm.hasAmp), "", IF( _xlpm.commasBeforeAmp>2, "etal", SUBSTITUTE(TRIM(_xlfn.TEXTBEFORE(_xlfn.TEXTAFTER(_xlpm.authors,"& "),",")),"-","") ) ) ) )} -> etal | G29: =_xlfn.TEXTBEFORE(_xlfn.TEXTAFTER(A29, "("), ")") -> 1996 | H29: =E29 & IF(F29<>"", "_" & F29, "_") & IF(G29<>"", "_" & G29, "_") & IF(B29<>"", "_" & B29, "") -> Baron_etal_1996 | I29: =_xlfn.LET( _xlpm.doi,IF(C29<>"",C29,_xlfn.TEXTAFTER(A29,"https://doi.org/")), SUBSTITUTE( SUBSTITUTE( SUBSTITUTE( SUBSTITUTE( _xlpm.doi, "/","%2F"), ":","%3A"), "<","%3C"), ">","%3E") ) -> ISBN%3A9783764353704 | J29: =TRIM(_xlfn.TEXTJOIN("_",FALSE(),H29,(SUBSTITUTE(SUBSTITUTE(D29," ",""), "_", "")))) -> Baron_etal_1996_Table19 | K29: =I29 & "_" & SUBSTITUTE(SUBSTITUTE(SUBSTITUTE(D29,CHAR(160),"")," ",""),"_","") -> ISBN%3A9783764353704_Table19 | L29: {=IFERROR(INDEX(AUTO_Public_TSV_FileList!$A$1:$A$1000,MATCH(TRUE(),EXACT(K29,IFERROR(_xlfn.TEXTBEFORE(AUTO_Public_TSV_FileList!$A$1:$A$1000,".tsv"),"")),0)),"notfound")} -> ISBN%3A9783764353704_Table19.tsv | M29: Volumes of the vestibular nuclei of the medulla oblongata | N29: table | P29: FINISHED | S29: Structure list, species count and the table's size/index role confirmed against the book's own Table 1 key (PDF pp. 264-265) and the printed column header, 2026-08-31. | T29: Inherits the whole-source merge gate already recorded for Tables 10/32: seven historical taxon concepts in MANUAL_REVIEW, and source rows that collapse to the same species must be averaged within the item before Tier-1 recency resolution. Resolving that gate once unblocks every Baron item, so build order need not wait on it. | W29: Mammals | X29: vestibular nucleus volumes | Y29: vestibular nucleus volumes | Z29: histological sections | AB29: volume | AC29: Stephan | AD29: Stephan | AE29: primary | AG29: Not yet transcribed. PDF pages 98-102; N = 150 printed rows. Extend Baron_etal_1996_extract_snapshots.py, which already reads this PDF's text layer for Tables 10 and 32 with an explicit literal OCR-repair table.
